{"type": "snapshot", "data": {"event_type": "depth_snapshot", "exchange": "binance", "symbol": "BTCUSDT", "event_time": 1786680055005, "received_time": 1786680055201, "last_update_id": 4671965, "bids": [{"price": 63284.85, "quantity": 23.29825}, {"price": 63284.84, "quantity": 0.00408}, {"price": 63284.83, "quantity": 0.00064}, {"price": 63284.81, "quantity": 0.00326}, {"price": 63284.8, "quantity": 0.22112}, {"price": 63284.69, "quantity": 0.00892}, {"price": 63284.06, "quantity": 0.00036}, {"price": 63284.01, "quantity": 0.00072}, {"price": 63284.0, "quantity": 1.43404}, {"price": 63283.99, "quantity": 0.56079}, {"price": 63283.93, "quantity": 0.00072}, {"price": 63283.92, "quantity": 0.1207}, {"price": 63283.59, "quantity": 0.016}, {"price": 63283.53, "quantity": 0.001}, {"price": 63283.41, "quantity": 0.00902}, {"price": 63283.2, "quantity": 0.001}, {"price": 63283.19, "quantity": 0.96935}, {"price": 63283.17, "quantity": 0.00032}, {"price": 63283.16, "quantity": 0.6317}, {"price": 63283.03, "quantity": 0.00092}, {"price": 63283.02, "quantity": 0.2008}, {"price": 63278.34, "quantity": 0.00316}, {"price": 63275.13, "quantity": 0.00031}, {"price": 63263.64, "quantity": 0.00158}, {"price": 63262.45, "quantity": 0.00526}, {"price": 63258.31, "quantity": 0.00031}, {"price": 63250.74, "quantity": 0.00735}, {"price": 63250.0, "quantity": 0.00158}, {"price": 63247.22, "quantity": 0.00048}, {"price": 63246.69, "quantity": 9e-05}, {"price": 63231.96, "quantity": 0.00158}, {"price": 63227.69, "quantity": 0.00079}, {"price": 63222.51, "quantity": 0.00031}, {"price": 63216.82, "quantity": 0.00158}, {"price": 63210.03, "quantity": 0.00048}, {"price": 63200.28, "quantity": 0.00158}, {"price": 63200.0, "quantity": 0.00086}, {"price": 63198.74, "quantity": 8e-05}, {"price": 63190.0, "quantity": 0.00025}, {"price": 63187.76, "quantity": 0.00798}, {"price": 63175.92, "quantity": 9e-05}, {"price": 63167.43, "quantity": 0.00166}, {"price": 63163.24, "quantity": 0.00162}, {"price": 63159.52, "quantity": 0.01424}, {"price": 63156.63, "quantity": 0.00158}, {"price": 63151.43, "quantity": 0.00026}, {"price": 63122.57, "quantity": 0.00047}, {"price": 63104.69, "quantity": 0.00528}, {"price": 63102.88, "quantity": 0.00079}, {"price": 63095.06, "quantity": 0.00036}, {"price": 63094.14, "quantity": 0.00795}, {"price": 63091.91, "quantity": 0.00466}, {"price": 63073.3, "quantity": 0.00525}, {"price": 63061.79, "quantity": 0.00039}, {"price": 63058.38, "quantity": 0.00158}, {"price": 63050.0, "quantity": 0.00495}, {"price": 63037.44, "quantity": 0.00079}, {"price": 63018.62, "quantity": 0.00095}, {"price": 63014.04, "quantity": 0.0027}, {"price": 63004.94, "quantity": 0.00162}, {"price": 63004.44, "quantity": 0.00255}, {"price": 63000.0, "quantity": 0.00205}, {"price": 62997.95, "quantity": 0.00158}, {"price": 62994.19, "quantity": 0.00238}, {"price": 62994.16, "quantity": 0.00047}, {"price": 62994.12, "quantity": 0.00011}, {"price": 62979.06, "quantity": 0.0027}, {"price": 62970.08, "quantity": 0.00047}, {"price": 62958.88, "quantity": 0.00047}, {"price": 62957.21, "quantity": 0.00127}, {"price": 62956.67, "quantity": 0.00024}, {"price": 62947.32, "quantity": 0.00529}, {"price": 62900.0, "quantity": 0.00078}, {"price": 62899.95, "quantity": 0.00158}, {"price": 62892.94, "quantity": 0.00127}, {"price": 62875.25, "quantity": 9e-05}, {"price": 62870.24, "quantity": 0.00802}, {"price": 62852.3, "quantity": 0.002}, {"price": 62846.63, "quantity": 0.00163}, {"price": 62839.26, "quantity": 0.00159}, {"price": 62838.81, "quantity": 0.00054}, {"price": 62833.33, "quantity": 0.0001}, {"price": 62829.81, "quantity": 0.01405}, {"price": 62828.66, "quantity": 0.00127}, {"price": 62827.65, "quantity": 0.00108}, {"price": 62824.06, "quantity": 0.00013}, {"price": 62822.3, "quantity": 0.001}, {"price": 62813.9, "quantity": 0.003}, {"price": 62805.88, "quantity": 0.00084}, {"price": 62800.0, "quantity": 0.00086}, {"price": 62790.35, "quantity": 0.0053}, {"price": 62789.38, "quantity": 0.00026}, {"price": 62782.82, "quantity": 0.01433}, {"price": 62774.57, "quantity": 0.00037}, {"price": 62764.39, "quantity": 0.00127}, {"price": 62761.13, "quantity": 0.0019}, {"price": 62748.76, "quantity": 9e-05}, {"price": 62741.51, "quantity": 0.00159}, {"price": 62736.67, "quantity": 0.07969}, {"price": 62705.12, "quantity": 0.00079}, {"price": 62700.11, "quantity": 0.00127}, {"price": 62690.91, "quantity": 0.00039}, {"price": 62688.33, "quantity": 0.00163}, {"price": 62680.58, "quantity": 0.00159}, {"price": 62677.63, "quantity": 0.00466}, {"price": 62676.9, "quantity": 0.00031}, {"price": 62674.81, "quantity": 0.00175}, {"price": 62655.86, "quantity": 0.00104}, {"price": 62635.84, "quantity": 0.00127}, {"price": 62632.4, "quantity": 0.00095}, {"price": 62600.0, "quantity": 0.00047}, {"price": 62583.07, "quantity": 0.00159}, {"price": 62574.58, "quantity": 9e-05}, {"price": 62571.57, "quantity": 0.00127}, {"price": 62565.9, "quantity": 0.00934}, {"price": 62552.71, "quantity": 0.00806}, {"price": 62530.03, "quantity": 0.00163}, {"price": 62521.89, "quantity": 0.0016}, {"price": 62507.29, "quantity": 0.00127}, {"price": 62454.08, "quantity": 0.00037}, {"price": 62444.33, "quantity": 0.00084}, {"price": 62443.02, "quantity": 0.00128}, {"price": 62439.29, "quantity": 0.00256}, {"price": 62427.33, "quantity": 0.00026}, {"price": 62424.63, "quantity": 0.0016}, {"price": 62408.37, "quantity": 0.01442}, {"price": 62400.0, "quantity": 0.00088}, {"price": 62378.74, "quantity": 0.00128}, {"price": 62374.18, "quantity": 0.0004}, {"price": 62371.72, "quantity": 0.00164}, {"price": 62338.45, "quantity": 0.00011}, {"price": 62322.21, "quantity": 0.0004}, {"price": 62314.47, "quantity": 0.00128}, {"price": 62309.86, "quantity": 0.0008}, {"price": 62273.91, "quantity": 0.0001}, {"price": 62266.19, "quantity": 0.0016}, {"price": 62263.35, "quantity": 0.00466}, {"price": 62253.69, "quantity": 0.001}, {"price": 62250.19, "quantity": 0.00128}, {"price": 62246.18, "quantity": 0.00096}, {"price": 62235.18, "quantity": 0.0081}, {"price": 62213.42, "quantity": 0.00164}, {"price": 62200.0, "quantity": 0.00048}, {"price": 62185.92, "quantity": 0.00128}, {"price": 62121.64, "quantity": 0.00128}, {"price": 62117.43, "quantity": 0.00096}, {"price": 62107.75, "quantity": 0.00161}, {"price": 62082.78, "quantity": 0.00085}, {"price": 62057.37, "quantity": 0.00128}, {"price": 62055.11, "quantity": 0.00165}, {"price": 62043.8, "quantity": 0.00031}, {"price": 62036.15, "quantity": 0.0145}, {"price": 62034.84, "quantity": 0.02857}, {"price": 62027.78, "quantity": 0.02838}, {"price": 62027.77, "quantity": 0.00337}, {"price": 62014.34, "quantity": 0.00134}, {"price": 62000.0, "quantity": 0.00088}, {"price": 61993.09, "quantity": 0.00129}, {"price": 61973.24, "quantity": 0.0001}, {"price": 61955.68, "quantity": 0.0004}, {"price": 61949.32, "quantity": 0.00161}, {"price": 61928.82, "quantity": 0.00129}, {"price": 61917.1, "quantity": 0.0008}, {"price": 61905.11, "quantity": 0.00094}, {"price": 61896.81, "quantity": 0.00165}, {"price": 61893.3, "quantity": 9e-05}, {"price": 61864.54, "quantity": 0.00129}, {"price": 61859.95, "quantity": 0.00096}, {"price": 61849.08, "quantity": 0.00466}, {"price": 61800.27, "quantity": 0.00129}, {"price": 61790.88, "quantity": 0.00161}, {"price": 61768.2, "quantity": 0.00014}, {"price": 61751.8, "quantity": 0.002}, {"price": 61750.9, "quantity": 0.0004}, {"price": 61738.51, "quantity": 0.00166}, {"price": 61735.99, "quantity": 0.00129}, {"price": 61721.23, "quantity": 0.00085}, {"price": 61703.24, "quantity": 0.00026}, {"price": 61703.23, "quantity": 0.00027}, {"price": 61682.77, "quantity": 0.00011}, {"price": 61671.72, "quantity": 0.00129}, {"price": 61666.67, "quantity": 0.00039}, {"price": 61666.16, "quantity": 0.01459}, {"price": 61629.94, "quantity": 0.00948}, {"price": 61607.44, "quantity": 0.00129}, {"price": 61603.56, "quantity": 0.00031}, {"price": 61600.0, "quantity": 0.0004}, {"price": 61591.31, "quantity": 0.0004}, {"price": 61543.17, "quantity": 0.00129}, {"price": 61526.8, "quantity": 0.00081}, {"price": 61478.89, "quantity": 0.0013}, {"price": 61473.73, "quantity": 0.00227}, {"price": 61473.72, "quantity": 0.00194}, {"price": 61455.18, "quantity": 0.001}, {"price": 61434.8, "quantity": 0.00466}, {"price": 61415.46, "quantity": 0.00138}, {"price": 61414.62, "quantity": 0.0013}, {"price": 61410.7, "quantity": 0.00031}, {"price": 61355.31, "quantity": 0.00464}, {"price": 61350.34, "quantity": 0.0013}, {"price": 61318.89, "quantity": 0.04423}, {"price": 61298.37, "quantity": 0.01468}, {"price": 61286.07, "quantity": 0.0013}, {"price": 61229.08, "quantity": 0.0004}, {"price": 61221.79, "quantity": 0.0013}, {"price": 61202.31, "quantity": 0.00465}, {"price": 61201.92, "quantity": 0.00465}, {"price": 61200.0, "quantity": 0.0004}, {"price": 61166.67, "quantity": 0.0001}, {"price": 61157.52, "quantity": 0.0013}, {"price": 61147.9, "quantity": 0.001}, {"price": 61142.63, "quantity": 0.001}, {"price": 61138.97, "quantity": 0.00081}, {"price": 61133.84, "quantity": 0.0004}, {"price": 61127.33, "quantity": 0.00014}, {"price": 61106.72, "quantity": 0.00098}, {"price": 61103.39, "quantity": 0.00036}, {"price": 61099.0, "quantity": 0.00016}, {"price": 61093.24, "quantity": 0.0013}, {"price": 61049.51, "quantity": 9e-05}, {"price": 61048.92, "quantity": 0.00466}, {"price": 61038.73, "quantity": 0.00049}, {"price": 61028.97, "quantity": 0.00131}, {"price": 61027.1, "quantity": 0.00011}, {"price": 61020.52, "quantity": 0.00466}, {"price": 61000.0, "quantity": 0.00032}, {"price": 60996.11, "quantity": 0.00081}, {"price": 60979.14, "quantity": 0.00027}, {"price": 60971.35, "quantity": 0.00109}, {"price": 60967.67, "quantity": 0.00016}, {"price": 60964.69, "quantity": 0.00131}, {"price": 60932.77, "quantity": 0.01477}, {"price": 60907.89, "quantity": 0.00976}, {"price": 60900.42, "quantity": 0.00131}, {"price": 60896.3, "quantity": 0.00468}, {"price": 60868.98, "quantity": 0.00041}, {"price": 60842.16, "quantity": 0.001}, {"price": 60836.14, "quantity": 0.00131}, {"price": 60833.33, "quantity": 0.00132}, {"price": 60833.28, "quantity": 0.00788}, {"price": 60830.02, "quantity": 0.00098}, {"price": 60800.0, "quantity": 0.00041}, {"price": 60777.6, "quantity": 0.00031}, {"price": 60771.87, "quantity": 0.00131}, {"price": 60768.83, "quantity": 0.02916}, {"price": 60753.59, "quantity": 0.00082}, {"price": 60744.05, "quantity": 0.00469}, {"price": 60707.98, "quantity": 0.00963}, {"price": 60707.59, "quantity": 0.00131}, {"price": 60643.32, "quantity": 0.00131}, {"price": 60631.51, "quantity": 0.002}, {"price": 60617.09, "quantity": 0.00027}, {"price": 60610.0, "quantity": 0.08249}, {"price": 60606.24, "quantity": 0.00466}, {"price": 60588.39, "quantity": 0.00036}, {"price": 60579.04, "quantity": 0.00132}, {"price": 60569.35, "quantity": 0.01485}, {"price": 60537.95, "quantity": 0.001}, {"price": 60530.68, "quantity": 0.00137}, {"price": 60522.95, "quantity": 0.00041}, {"price": 60514.77, "quantity": 0.00132}, {"price": 60511.0, "quantity": 0.00041}, {"price": 60508.17, "quantity": 0.00132}, {"price": 60470.47, "quantity": 0.01488}, {"price": 60462.55, "quantity": 0.00016}, {"price": 60450.5, "quantity": 0.00132}, {"price": 60400.0, "quantity": 0.00041}, {"price": 60371.43, "quantity": 0.00011}, {"price": 60370.63, "quantity": 0.00082}, {"price": 60317.99, "quantity": 0.00076}, {"price": 60313.13, "quantity": 0.00098}, {"price": 60255.04, "quantity": 0.00027}, {"price": 60235.26, "quantity": 0.001}, {"price": 60217.22, "quantity": 9e-05}, {"price": 60208.11, "quantity": 0.01494}, {"price": 60191.96, "quantity": 0.00466}, {"price": 60186.31, "quantity": 0.00099}, {"price": 60155.12, "quantity": 0.00041}, {"price": 60144.5, "quantity": 0.00031}, {"price": 60100.46, "quantity": 0.00067}, {"price": 60077.73, "quantity": 0.00036}, {"price": 60071.51, "quantity": 0.00074}, {"price": 60059.48, "quantity": 0.00074}, {"price": 60058.57, "quantity": 0.00074}, {"price": 60031.52, "quantity": 0.001}, {"price": 60000.0, "quantity": 0.0008}, {"price": 59996.5, "quantity": 0.002}, {"price": 59990.09, "quantity": 0.00083}, {"price": 59982.5, "quantity": 0.001}, {"price": 59973.1, "quantity": 0.001}, {"price": 59924.7, "quantity": 0.002}, {"price": 59918.16, "quantity": 0.00041}, {"price": 59910.2, "quantity": 0.003}, {"price": 59908.4, "quantity": 0.002}, {"price": 59893.0, "quantity": 0.00027}, {"price": 59877.99, "quantity": 0.00062}, {"price": 59849.01, "quantity": 0.01503}, {"price": 59812.0, "quantity": 0.003}, {"price": 59802.95, "quantity": 0.00184}, {"price": 59801.34, "quantity": 0.00041}, {"price": 59799.81, "quantity": 0.00977}, {"price": 59780.74, "quantity": 0.00031}, {"price": 59777.68, "quantity": 0.00466}, {"price": 59717.1, "quantity": 0.003}, {"price": 59715.76, "quantity": 0.00012}, {"price": 59712.4, "quantity": 0.004}, {"price": 59611.95, "quantity": 0.00083}, {"price": 59571.37, "quantity": 0.00036}, {"price": 59542.62, "quantity": 0.00134}, {"price": 59542.61, "quantity": 0.001}, {"price": 59502.81, "quantity": 0.02978}, {"price": 59500.0, "quantity": 0.00146}, {"price": 59453.02, "quantity": 0.00033}, {"price": 59449.63, "quantity": 0.00042}, {"price": 59431.05, "quantity": 0.03224}, {"price": 59396.28, "quantity": 9e-05}, {"price": 59319.42, "quantity": 0.00042}, {"price": 59217.97, "quantity": 0.00054}, {"price": 59100.0, "quantity": 0.00042}, {"price": 59077.82, "quantity": 0.00086}, {"price": 59069.28, "quantity": 0.00037}, {"price": 59047.03, "quantity": 0.00141}, {"price": 58905.23, "quantity": 0.00992}, {"price": 58793.39, "quantity": 0.00114}, {"price": 58785.06, "quantity": 0.02614}, {"price": 58781.62, "quantity": 0.00114}, {"price": 58780.73, "quantity": 0.00114}, {"price": 58726.66, "quantity": 0.00042}, {"price": 58638.59, "quantity": 0.00034}, {"price": 58586.53, "quantity": 9e-05}, {"price": 58577.06, "quantity": 0.00136}, {"price": 58571.43, "quantity": 0.00037}, {"price": 58348.43, "quantity": 0.00039}, {"price": 58333.33, "quantity": 0.00039}, {"price": 58236.79, "quantity": 0.03043}, {"price": 58166.67, "quantity": 0.00136}, {"price": 58139.82, "quantity": 0.00042}, {"price": 58139.07, "quantity": 0.00314}, {"price": 58077.76, "quantity": 0.00037}, {"price": 58037.89, "quantity": 0.01024}, {"price": 57824.17, "quantity": 0.00034}, {"price": 57793.52, "quantity": 0.00088}, {"price": 57787.82, "quantity": 9e-05}, {"price": 57706.68, "quantity": 0.00247}, {"price": 57558.84, "quantity": 0.00043}, {"price": 57515.27, "quantity": 0.00176}, {"price": 57503.75, "quantity": 0.00176}, {"price": 57502.89, "quantity": 0.00176}, {"price": 57491.66, "quantity": 0.00025}, {"price": 57156.01, "quantity": 0.01023}, {"price": 57009.74, "quantity": 0.00035}, {"price": 57000.0, "quantity": 9e-05}, {"price": 56983.68, "quantity": 0.00043}, {"price": 56970.77, "quantity": 0.0311}, {"price": 56833.33, "quantity": 0.0014}, {"price": 56666.67, "quantity": 0.00039}, {"price": 56414.26, "quantity": 0.00044}, {"price": 55850.53, "quantity": 0.00044}, {"price": 55500.0, "quantity": 0.00144}, {"price": 55349.57, "quantity": 0.7408}, {"price": 55292.43, "quantity": 0.00045}, {"price": 55278.45, "quantity": 0.00018}, {"price": 55269.44, "quantity": 1.3578}, {"price": 55200.0, "quantity": 0.05471}, {"price": 55167.88, "quantity": 0.01078}, {"price": 55136.35, "quantity": 0.00181}, {"price": 55000.0, "quantity": 0.00827}, {"price": 54993.96, "quantity": 0.00018}, {"price": 54786.95, "quantity": 0.01641}, {"price": 54739.91, "quantity": 0.00045}, {"price": 54710.93, "quantity": 0.00018}, {"price": 54429.36, "quantity": 0.00018}, {"price": 54421.76, "quantity": 0.0002}, {"price": 54291.84, "quantity": 0.0002}, {"price": 54207.9, "quantity": 0.0002}, {"price": 54192.91, "quantity": 0.00046}, {"price": 54149.23, "quantity": 0.00018}, {"price": 54000.0, "quantity": 0.00768}, {"price": 53870.55, "quantity": 0.00018}, {"price": 53651.38, "quantity": 0.00046}, {"price": 53597.61, "quantity": 0.01294}, {"price": 53593.3, "quantity": 0.00018}, {"price": 53317.48, "quantity": 0.00018}, {"price": 53115.26, "quantity": 0.00047}, {"price": 53043.08, "quantity": 0.00018}, {"price": 53000.0, "quantity": 0.01768}, {"price": 52996.63, "quantity": 0.01697}, {"price": 52770.09, "quantity": 0.00018}, {"price": 52584.49, "quantity": 0.00047}, {"price": 52498.5, "quantity": 0.00019}, {"price": 52379.53, "quantity": 0.0019}, {"price": 52297.88, "quantity": 0.01137}, {"price": 52228.31, "quantity": 0.00019}, {"price": 52059.03, "quantity": 0.00048}, {"price": 52000.0, "quantity": 0.00768}, {"price": 51959.52, "quantity": 0.00019}, {"price": 51875.22, "quantity": 0.001}, {"price": 51875.21, "quantity": 0.001}, {"price": 51692.11, "quantity": 0.00019}, {"price": 51538.82, "quantity": 0.00048}, {"price": 51426.07, "quantity": 0.00019}, {"price": 51264.81, "quantity": 0.01754}, {"price": 51161.4, "quantity": 0.00019}, {"price": 51023.81, "quantity": 0.00048}, {"price": 51000.0, "quantity": 0.00768}, {"price": 50898.1, "quantity": 0.00019}, {"price": 50813.8, "quantity": 0.00011}, {"price": 50636.14, "quantity": 0.00019}, {"price": 50513.94, "quantity": 0.00049}, {"price": 50500.0, "quantity": 0.0099}, {"price": 50375.54, "quantity": 0.00019}, {"price": 50116.28, "quantity": 0.00019}, {"price": 50009.17, "quantity": 0.00049}, {"price": 50000.0, "quantity": 0.11262}, {"price": 49858.35, "quantity": 0.0002}, {"price": 49760.55, "quantity": 0.002}, {"price": 49601.76, "quantity": 0.0002}, {"price": 49509.45, "quantity": 0.0005}, {"price": 49427.87, "quantity": 0.01203}, {"price": 49346.48, "quantity": 0.0002}, {"price": 49092.51, "quantity": 0.0002}, {"price": 49014.72, "quantity": 0.00051}, {"price": 49000.0, "quantity": 0.13}, {"price": 48839.85, "quantity": 0.0002}, {"price": 48588.5, "quantity": 0.0002}, {"price": 48524.93, "quantity": 0.00051}, {"price": 48338.43, "quantity": 0.0002}, {"price": 48089.66, "quantity": 0.0002}, {"price": 48040.03, "quantity": 0.00052}, {"price": 47559.98, "quantity": 0.00052}, {"price": 47322.0, "quantity": 0.05915}, {"price": 47084.73, "quantity": 0.00053}, {"price": 46726.0, "quantity": 0.02715}, {"price": 46614.23, "quantity": 0.00053}, {"price": 46302.32, "quantity": 0.01294}, {"price": 46148.43, "quantity": 0.00054}, {"price": 45687.28, "quantity": 0.00054}, {"price": 45421.0, "quantity": 0.01856}, {"price": 45309.0, "quantity": 0.01372}, {"price": 45230.74, "quantity": 0.00055}, {"price": 44966.11, "quantity": 0.001}, {"price": 44778.76, "quantity": 0.00055}, {"price": 44582.98, "quantity": 0.00056}, {"price": 44493.4, "quantity": 0.00056}, {"price": 44331.3, "quantity": 0.00056}, {"price": 43888.31, "quantity": 0.00056}, {"price": 43747.0, "quantity": 0.39278}, {"price": 43449.75, "quantity": 0.00057}, {"price": 43015.57, "quantity": 0.00058}, {"price": 42585.73, "quantity": 0.00058}, {"price": 42160.18, "quantity": 0.00059}, {"price": 42026.0, "quantity": 0.41314}, {"price": 41738.89, "quantity": 0.00059}, {"price": 41321.81, "quantity": 0.0006}, {"price": 41010.0, "quantity": 0.00269}, {"price": 40908.89, "quantity": 0.00061}, {"price": 40500.1, "quantity": 0.00061}, {"price": 40095.4, "quantity": 0.00062}, {"price": 40002.0, "quantity": 0.12177}, {"price": 40000.0, "quantity": 0.01294}, {"price": 39694.74, "quantity": 0.00062}, {"price": 39298.08, "quantity": 0.00063}, {"price": 38905.39, "quantity": 0.00064}, {"price": 38516.62, "quantity": 0.00064}, {"price": 38131.73, "quantity": 0.00065}, {"price": 37750.69, "quantity": 0.00066}, {"price": 37373.46, "quantity": 0.00066}, {"price": 37000.0, "quantity": 0.00067}, {"price": 32482.0, "quantity": 0.03466}], "asks": [{"price": 63284.86, "quantity": 3.35168}, {"price": 63284.87, "quantity": 0.00352}, {"price": 63284.88, "quantity": 0.00064}, {"price": 63285.18, "quantity": 0.00036}, {"price": 63285.25, "quantity": 0.00072}, {"price": 63285.26, "quantity": 0.38804}, {"price": 63285.38, "quantity": 0.001}, {"price": 63285.99, "quantity": 0.00072}, {"price": 63286.0, "quantity": 0.19159}, {"price": 63286.11, "quantity": 0.00072}, {"price": 63286.12, "quantity": 0.55164}, {"price": 63286.13, "quantity": 0.1794}, {"price": 63286.4, "quantity": 0.00032}, {"price": 63286.95, "quantity": 0.00072}, {"price": 63286.96, "quantity": 0.26662}, {"price": 63287.01, "quantity": 0.00838}, {"price": 63287.4, "quantity": 0.23896}, {"price": 63287.86, "quantity": 0.00036}, {"price": 63288.0, "quantity": 0.08902}, {"price": 63288.05, "quantity": 0.7598}, {"price": 63288.36, "quantity": 0.00036}, {"price": 63341.66, "quantity": 0.00315}, {"price": 63358.67, "quantity": 0.00157}, {"price": 63362.44, "quantity": 0.005}, {"price": 63365.61, "quantity": 0.00079}, {"price": 63380.1, "quantity": 0.00031}, {"price": 63388.67, "quantity": 8e-05}, {"price": 63389.7, "quantity": 0.00031}, {"price": 63398.97, "quantity": 0.00157}, {"price": 63404.12, "quantity": 0.00031}, {"price": 63422.79, "quantity": 0.00031}, {"price": 63428.14, "quantity": 0.00031}, {"price": 63430.69, "quantity": 0.00157}, {"price": 63440.73, "quantity": 0.00031}, {"price": 63462.27, "quantity": 0.00031}, {"price": 63464.0, "quantity": 0.00031}, {"price": 63470.38, "quantity": 0.00157}, {"price": 63473.52, "quantity": 0.00031}, {"price": 63477.81, "quantity": 0.00078}, {"price": 63478.3, "quantity": 0.00031}, {"price": 63487.82, "quantity": 0.00031}, {"price": 63488.81, "quantity": 0.00031}, {"price": 63497.52, "quantity": 0.01396}, {"price": 63499.18, "quantity": 0.00014}, {"price": 63502.13, "quantity": 0.00157}, {"price": 63503.7, "quantity": 0.0192}, {"price": 63511.64, "quantity": 0.00031}, {"price": 63516.24, "quantity": 1.08717}, {"price": 63517.97, "quantity": 0.00031}, {"price": 63530.58, "quantity": 0.00031}, {"price": 63537.25, "quantity": 0.00157}, {"price": 63538.02, "quantity": 0.00031}, {"price": 63546.19, "quantity": 0.00031}, {"price": 63569.03, "quantity": 0.00157}, {"price": 63572.64, "quantity": 0.00157}, {"price": 63579.16, "quantity": 0.00525}, {"price": 63585.37, "quantity": 0.00031}, {"price": 63595.47, "quantity": 0.00031}, {"price": 63600.0, "quantity": 0.00491}, {"price": 63601.3, "quantity": 0.002}, {"price": 63608.85, "quantity": 0.0027}, {"price": 63615.76, "quantity": 0.00036}, {"price": 63616.79, "quantity": 0.00031}, {"price": 63617.37, "quantity": 0.0108}, {"price": 63617.4, "quantity": 0.004}, {"price": 63618.82, "quantity": 0.00035}, {"price": 63619.13, "quantity": 0.00031}, {"price": 63619.2, "quantity": 0.003}, {"price": 63619.83, "quantity": 0.00035}, {"price": 63621.33, "quantity": 0.00031}, {"price": 63626.3, "quantity": 0.0027}, {"price": 63626.6, "quantity": 0.001}, {"price": 63627.03, "quantity": 0.00031}, {"price": 63629.71, "quantity": 0.00031}, {"price": 63633.06, "quantity": 0.00036}, {"price": 63636.01, "quantity": 0.00136}, {"price": 63636.08, "quantity": 0.00255}, {"price": 63636.9, "quantity": 0.0047}, {"price": 63637.42, "quantity": 0.00031}, {"price": 63638.53, "quantity": 0.00031}, {"price": 63639.69, "quantity": 0.00039}, {"price": 63640.24, "quantity": 0.00112}, {"price": 63642.91, "quantity": 0.00031}, {"price": 63643.68, "quantity": 0.00036}, {"price": 63644.64, "quantity": 0.015}, {"price": 63645.06, "quantity": 0.00157}, {"price": 63645.58, "quantity": 0.00031}, {"price": 63645.78, "quantity": 0.0027}, {"price": 63649.79, "quantity": 0.00011}, {"price": 63650.01, "quantity": 0.00105}, {"price": 63650.1, "quantity": 0.002}, {"price": 63651.7, "quantity": 0.00126}, {"price": 63653.85, "quantity": 0.00037}, {"price": 63662.73, "quantity": 0.00041}, {"price": 63662.9, "quantity": 0.04965}, {"price": 63663.32, "quantity": 0.00031}, {"price": 63663.94, "quantity": 0.00037}, {"price": 63666.8, "quantity": 0.003}, {"price": 63667.45, "quantity": 0.0067}, {"price": 63668.24, "quantity": 0.00078}, {"price": 63671.1, "quantity": 0.004}, {"price": 63671.19, "quantity": 0.00031}, {"price": 63671.23, "quantity": 0.00038}, {"price": 63676.9, "quantity": 0.00157}, {"price": 63677.86, "quantity": 0.01389}, {"price": 63681.1, "quantity": 0.002}, {"price": 63684.63, "quantity": 0.00031}, {"price": 63688.22, "quantity": 0.0108}, {"price": 63694.75, "quantity": 0.00037}, {"price": 63696.75, "quantity": 0.00031}, {"price": 63700.64, "quantity": 0.01093}, {"price": 63703.42, "quantity": 0.00031}, {"price": 63705.63, "quantity": 0.00525}, {"price": 63709.59, "quantity": 0.00037}, {"price": 63709.88, "quantity": 0.00042}, {"price": 63710.31, "quantity": 0.00014}, {"price": 63713.47, "quantity": 0.01107}, {"price": 63716.61, "quantity": 0.00126}, {"price": 63717.63, "quantity": 0.00031}, {"price": 63719.28, "quantity": 0.00037}, {"price": 63720.11, "quantity": 0.00157}, {"price": 63721.7, "quantity": 0.01121}, {"price": 63722.07, "quantity": 0.00031}, {"price": 63725.04, "quantity": 0.01135}, {"price": 63726.68, "quantity": 0.00795}, {"price": 63727.26, "quantity": 0.00037}, {"price": 63727.67, "quantity": 0.00031}, {"price": 63733.79, "quantity": 0.00041}, {"price": 63734.86, "quantity": 0.00916}, {"price": 63735.17, "quantity": 0.00395}, {"price": 63736.05, "quantity": 0.00036}, {"price": 63737.54, "quantity": 0.00015}, {"price": 63738.11, "quantity": 0.00524}, {"price": 63744.81, "quantity": 0.00034}, {"price": 63747.25, "quantity": 0.01039}, {"price": 63750.0, "quantity": 0.00157}, {"price": 63751.99, "quantity": 0.00156}, {"price": 63756.4, "quantity": 0.00594}, {"price": 63758.0, "quantity": 0.00196}, {"price": 63761.94, "quantity": 0.00161}, {"price": 63763.94, "quantity": 0.00297}, {"price": 63764.99, "quantity": 0.00157}, {"price": 63765.09, "quantity": 0.00915}, {"price": 63768.17, "quantity": 0.00156}, {"price": 63768.58, "quantity": 0.14978}, {"price": 63777.04, "quantity": 0.00042}, {"price": 63777.26, "quantity": 0.00018}, {"price": 63779.41, "quantity": 0.141}, {"price": 63781.54, "quantity": 0.00126}, {"price": 63783.55, "quantity": 0.00041}, {"price": 63787.78, "quantity": 0.00156}, {"price": 63790.26, "quantity": 0.00042}, {"price": 63791.07, "quantity": 0.00652}, {"price": 63798.45, "quantity": 0.00078}, {"price": 63800.0, "quantity": 0.00046}, {"price": 63802.32, "quantity": 0.00924}, {"price": 63810.14, "quantity": 0.00039}, {"price": 63819.7, "quantity": 0.00156}, {"price": 63821.51, "quantity": 0.00157}, {"price": 63822.68, "quantity": 0.00027}, {"price": 63822.82, "quantity": 0.00797}, {"price": 63823.94, "quantity": 0.00015}, {"price": 63829.25, "quantity": 0.00196}, {"price": 63829.72, "quantity": 0.00031}, {"price": 63832.4, "quantity": 0.00255}, {"price": 63832.73, "quantity": 0.00031}, {"price": 63833.54, "quantity": 0.00031}, {"price": 63835.68, "quantity": 0.00302}, {"price": 63837.97, "quantity": 0.00932}, {"price": 63840.76, "quantity": 0.00031}, {"price": 63846.45, "quantity": 0.00126}, {"price": 63850.0, "quantity": 0.00314}, {"price": 63850.67, "quantity": 0.00037}, {"price": 63851.63, "quantity": 0.00156}, {"price": 63858.68, "quantity": 0.00078}, {"price": 63863.15, "quantity": 0.00941}, {"price": 63867.22, "quantity": 0.01485}, {"price": 63875.0, "quantity": 0.00489}, {"price": 63875.52, "quantity": 0.00026}, {"price": 63889.15, "quantity": 0.00156}, {"price": 63889.65, "quantity": 0.01686}, {"price": 63890.52, "quantity": 0.00082}, {"price": 63894.72, "quantity": 0.00042}, {"price": 63894.74, "quantity": 0.00717}, {"price": 63897.45, "quantity": 0.00522}, {"price": 63906.01, "quantity": 0.00078}, {"price": 63911.37, "quantity": 0.00126}, {"price": 63919.43, "quantity": 0.00111}, {"price": 63919.72, "quantity": 0.01408}, {"price": 63921.11, "quantity": 0.00156}, {"price": 63921.44, "quantity": 0.00014}, {"price": 63931.19, "quantity": 0.00043}, {"price": 63938.37, "quantity": 0.00969}, {"price": 63948.06, "quantity": 0.00044}, {"price": 63961.68, "quantity": 0.00664}, {"price": 63968.96, "quantity": 0.00043}, {"price": 63976.28, "quantity": 0.00126}, {"price": 63982.92, "quantity": 0.00968}, {"price": 63989.73, "quantity": 0.00698}, {"price": 64000.0, "quantity": 0.00241}, {"price": 64011.32, "quantity": 0.00027}, {"price": 64013.58, "quantity": 0.00043}, {"price": 64015.12, "quantity": 0.00208}, {"price": 64018.01, "quantity": 0.00031}, {"price": 64020.01, "quantity": 0.15}, {"price": 64025.9, "quantity": 0.00977}, {"price": 64041.21, "quantity": 0.00126}, {"price": 64048.54, "quantity": 0.00188}, {"price": 64049.11, "quantity": 0.00078}, {"price": 64054.63, "quantity": 0.0006}, {"price": 64057.2, "quantity": 0.00521}, {"price": 64063.7, "quantity": 0.00975}, {"price": 64072.02, "quantity": 0.00044}, {"price": 64077.93, "quantity": 9e-05}, {"price": 64106.12, "quantity": 0.00126}, {"price": 64106.81, "quantity": 0.00031}, {"price": 64116.11, "quantity": 0.00984}, {"price": 64125.96, "quantity": 0.00047}, {"price": 64132.57, "quantity": 0.00014}, {"price": 64140.34, "quantity": 0.00797}, {"price": 64149.04, "quantity": 0.00125}, {"price": 64154.44, "quantity": 0.0788}, {"price": 64155.7, "quantity": 0.00157}, {"price": 64157.49, "quantity": 0.00045}, {"price": 64160.17, "quantity": 0.00993}, {"price": 64162.26, "quantity": 0.00014}, {"price": 64168.73, "quantity": 0.00031}, {"price": 64174.77, "quantity": 0.00031}, {"price": 64177.29, "quantity": 0.00094}, {"price": 64187.64, "quantity": 0.00039}, {"price": 64199.96, "quantity": 0.00027}, {"price": 64200.0, "quantity": 0.00046}, {"price": 64205.74, "quantity": 0.01}, {"price": 64209.12, "quantity": 0.02942}, {"price": 64211.66, "quantity": 0.0624}, {"price": 64217.34, "quantity": 0.0052}, {"price": 64235.95, "quantity": 0.00125}, {"price": 64237.52, "quantity": 0.00023}, {"price": 64237.56, "quantity": 0.00025}, {"price": 64252.07, "quantity": 0.00082}, {"price": 64255.46, "quantity": 0.00998}, {"price": 64263.46, "quantity": 0.00028}, {"price": 64279.65, "quantity": 0.05045}, {"price": 64281.1, "quantity": 0.00098}, {"price": 64281.24, "quantity": 0.00015}, {"price": 64282.04, "quantity": 0.00039}, {"price": 64283.3, "quantity": 0.01542}, {"price": 64286.64, "quantity": 0.00034}, {"price": 64292.61, "quantity": 0.00125}, {"price": 64294.03, "quantity": 0.00749}, {"price": 64299.18, "quantity": 0.01007}, {"price": 64299.8, "quantity": 0.00045}, {"price": 64303.23, "quantity": 0.01399}, {"price": 64305.46, "quantity": 0.00011}, {"price": 64311.39, "quantity": 0.00077}, {"price": 64317.44, "quantity": 0.00043}, {"price": 64324.19, "quantity": 0.00043}, {"price": 64334.42, "quantity": 0.0194}, {"price": 64334.75, "quantity": 0.00466}, {"price": 64338.97, "quantity": 0.01016}, {"price": 64339.57, "quantity": 0.00062}, {"price": 64365.82, "quantity": 0.01036}, {"price": 64370.4, "quantity": 0.00378}, {"price": 64378.59, "quantity": 9e-05}, {"price": 64382.55, "quantity": 0.01047}, {"price": 64388.6, "quantity": 0.00027}, {"price": 64400.0, "quantity": 0.00085}, {"price": 64403.24, "quantity": 0.01057}, {"price": 64416.4, "quantity": 0.00053}, {"price": 64419.07, "quantity": 0.00043}, {"price": 64422.95, "quantity": 0.01067}, {"price": 64435.67, "quantity": 0.01067}, {"price": 64443.05, "quantity": 0.00045}, {"price": 64443.25, "quantity": 0.01077}, {"price": 64448.29, "quantity": 0.01087}, {"price": 64449.95, "quantity": 0.00103}, {"price": 64453.34, "quantity": 0.01098}, {"price": 64457.87, "quantity": 0.00797}, {"price": 64460.57, "quantity": 0.01109}, {"price": 64461.6, "quantity": 0.00015}, {"price": 64466.66, "quantity": 0.0001}, {"price": 64467.15, "quantity": 0.0112}, {"price": 64470.29, "quantity": 0.00015}, {"price": 64473.22, "quantity": 0.01131}, {"price": 64475.94, "quantity": 0.001}, {"price": 64480.68, "quantity": 0.0092}, {"price": 64500.0, "quantity": 0.0001}, {"price": 64520.74, "quantity": 0.00044}, {"price": 64527.97, "quantity": 0.05339}, {"price": 64528.57, "quantity": 0.02942}, {"price": 64547.74, "quantity": 0.00045}, {"price": 64564.16, "quantity": 0.00079}, {"price": 64566.88, "quantity": 0.17539}, {"price": 64567.37, "quantity": 0.00038}, {"price": 64576.2, "quantity": 0.01579}, {"price": 64613.62, "quantity": 0.00081}, {"price": 64622.57, "quantity": 0.00044}, {"price": 64679.26, "quantity": 9e-05}, {"price": 64685.03, "quantity": 0.0006}, {"price": 64689.05, "quantity": 0.01391}, {"price": 64700.0, "quantity": 0.00485}, {"price": 64700.28, "quantity": 0.00057}, {"price": 64710.95, "quantity": 0.02783}, {"price": 64713.49, "quantity": 0.00053}, {"price": 64714.18, "quantity": 0.0025}, {"price": 64719.35, "quantity": 0.00077}, {"price": 64723.91, "quantity": 0.00058}, {"price": 64729.62, "quantity": 0.01965}, {"price": 64736.96, "quantity": 0.00015}, {"price": 64737.56, "quantity": 0.00045}, {"price": 64738.4, "quantity": 0.00048}, {"price": 64749.03, "quantity": 0.00466}, {"price": 64750.0, "quantity": 0.00894}, {"price": 64752.41, "quantity": 0.00031}, {"price": 64755.3, "quantity": 0.00124}, {"price": 64759.99, "quantity": 0.00094}, {"price": 64761.2, "quantity": 0.0047}, {"price": 64767.1, "quantity": 0.00058}, {"price": 64769.03, "quantity": 0.00106}, {"price": 64775.4, "quantity": 0.00797}, {"price": 64784.36, "quantity": 0.00015}, {"price": 64790.45, "quantity": 0.00013}, {"price": 64800.0, "quantity": 0.00038}, {"price": 64820.22, "quantity": 0.00124}, {"price": 64825.5, "quantity": 0.00061}, {"price": 64833.08, "quantity": 0.00018}, {"price": 64833.33, "quantity": 0.00093}, {"price": 64848.02, "quantity": 0.02942}, {"price": 64857.15, "quantity": 0.001}, {"price": 64884.78, "quantity": 0.00102}, {"price": 64885.13, "quantity": 0.00124}, {"price": 64897.33, "quantity": 0.00058}, {"price": 64903.17, "quantity": 0.00048}, {"price": 64908.68, "quantity": 0.00056}, {"price": 64917.69, "quantity": 0.00015}, {"price": 64918.47, "quantity": 0.00058}, {"price": 64925.7, "quantity": 0.00055}, {"price": 64930.87, "quantity": 0.00076}, {"price": 64934.92, "quantity": 0.00015}, {"price": 64949.35, "quantity": 0.00076}, {"price": 64950.05, "quantity": 0.00124}, {"price": 64953.11, "quantity": 0.00124}, {"price": 64956.88, "quantity": 0.0003}, {"price": 64971.88, "quantity": 0.00015}, {"price": 64973.31, "quantity": 0.00248}, {"price": 64975.0, "quantity": 0.00482}, {"price": 64975.17, "quantity": 0.00081}, {"price": 64979.93, "quantity": 9e-05}, {"price": 64985.47, "quantity": 0.00015}, {"price": 64987.23, "quantity": 0.00084}, {"price": 64993.87, "quantity": 0.00152}, {"price": 65000.0, "quantity": 0.00933}, {"price": 65002.44, "quantity": 0.00058}, {"price": 65027.14, "quantity": 0.00033}, {"price": 65047.44, "quantity": 0.00053}, {"price": 65060.6, "quantity": 0.00048}, {"price": 65074.7, "quantity": 0.00098}, {"price": 65077.19, "quantity": 0.01382}, {"price": 65090.65, "quantity": 0.00058}, {"price": 65101.12, "quantity": 0.00058}, {"price": 65106.85, "quantity": 0.00108}, {"price": 65116.04, "quantity": 0.00054}, {"price": 65128.94, "quantity": 0.00035}, {"price": 65129.89, "quantity": 0.00076}, {"price": 65144.31, "quantity": 0.00047}, {"price": 65163.31, "quantity": 0.00466}, {"price": 65180.28, "quantity": 0.06096}, {"price": 65200.0, "quantity": 0.00038}, {"price": 65209.73, "quantity": 0.00123}, {"price": 65231.1, "quantity": 0.0004}, {"price": 65247.07, "quantity": 0.00057}, {"price": 65250.0, "quantity": 0.01372}, {"price": 65266.12, "quantity": 0.03976}, {"price": 65266.8, "quantity": 0.00035}, {"price": 65270.9, "quantity": 0.00252}, {"price": 65271.29, "quantity": 0.00205}, {"price": 65274.64, "quantity": 0.00123}, {"price": 65280.6, "quantity": 9e-05}, {"price": 65283.33, "quantity": 0.0026}, {"price": 65286.83, "quantity": 0.00205}, {"price": 65286.98, "quantity": 0.00245}, {"price": 65287.39, "quantity": 0.00031}, {"price": 65296.31, "quantity": 0.00015}, {"price": 65297.89, "quantity": 0.00268}, {"price": 65298.13, "quantity": 0.00154}, {"price": 65305.15, "quantity": 0.00187}, {"price": 65305.48, "quantity": 0.00015}, {"price": 65309.92, "quantity": 0.0021}, {"price": 65315.49, "quantity": 0.00029}, {"price": 65316.69, "quantity": 0.00314}, {"price": 65319.6, "quantity": 0.00102}, {"price": 65321.76, "quantity": 0.00276}, {"price": 65323.82, "quantity": 0.0021}, {"price": 65328.18, "quantity": 0.00015}, {"price": 65329.85, "quantity": 0.00153}, {"price": 65333.06, "quantity": 0.00034}, {"price": 65333.59, "quantity": 0.00038}, {"price": 65335.96, "quantity": 0.00124}, {"price": 65338.98, "quantity": 0.0021}, {"price": 65339.56, "quantity": 0.00123}, {"price": 65341.59, "quantity": 0.00303}, {"price": 65345.51, "quantity": 0.00285}, {"price": 65345.93, "quantity": 0.03352}, {"price": 65362.96, "quantity": 0.00052}, {"price": 65364.35, "quantity": 0.00312}, {"price": 65368.42, "quantity": 0.05343}, {"price": 65371.81, "quantity": 0.00127}, {"price": 65372.35, "quantity": 0.00666}, {"price": 65373.3, "quantity": 0.00303}, {"price": 65374.08, "quantity": 0.00332}, {"price": 65377.92, "quantity": 0.00015}, {"price": 65390.38, "quantity": 0.00315}, {"price": 65397.03, "quantity": 0.00332}, {"price": 65398.68, "quantity": 0.00342}, {"price": 65398.74, "quantity": 0.00035}, {"price": 65399.35, "quantity": 0.00014}, {"price": 65404.47, "quantity": 0.00123}, {"price": 65404.88, "quantity": 0.00046}, {"price": 65417.63, "quantity": 0.00031}, {"price": 65425.79, "quantity": 0.00015}, {"price": 65437.19, "quantity": 0.00037}, {"price": 65439.64, "quantity": 0.00345}, {"price": 65441.53, "quantity": 0.00015}, {"price": 65441.54, "quantity": 0.00015}, {"price": 65454.98, "quantity": 0.00345}, {"price": 65457.52, "quantity": 0.00345}, {"price": 65459.93, "quantity": 0.00906}, {"price": 65467.65, "quantity": 0.01374}, {"price": 65469.39, "quantity": 0.00123}, {"price": 65493.82, "quantity": 0.00022}, {"price": 65499.3, "quantity": 0.001}, {"price": 65500.0, "quantity": 0.00912}, {"price": 65505.27, "quantity": 0.00051}, {"price": 65516.8, "quantity": 0.00155}, {"price": 65524.64, "quantity": 0.00078}, {"price": 65532.46, "quantity": 0.00375}, {"price": 65534.31, "quantity": 0.00123}, {"price": 65538.45, "quantity": 0.00069}, {"price": 65540.63, "quantity": 0.00088}, {"price": 65543.03, "quantity": 0.00076}, {"price": 65544.63, "quantity": 0.00077}, {"price": 65554.13, "quantity": 0.00015}, {"price": 65562.83, "quantity": 0.00047}, {"price": 65572.22, "quantity": 0.13767}, {"price": 65577.59, "quantity": 0.00466}, {"price": 65577.84, "quantity": 0.00015}, {"price": 65581.27, "quantity": 9e-05}, {"price": 65586.26, "quantity": 0.00038}, {"price": 65587.05, "quantity": 0.001}, {"price": 65590.48, "quantity": 0.00048}, {"price": 65595.94, "quantity": 0.00049}, {"price": 65599.22, "quantity": 0.00123}, {"price": 65628.89, "quantity": 0.00015}, {"price": 65629.77, "quantity": 0.00153}, {"price": 65639.13, "quantity": 0.00076}, {"price": 65664.15, "quantity": 0.00123}, {"price": 65678.59, "quantity": 0.00204}, {"price": 65680.48, "quantity": 0.00024}, {"price": 65720.1, "quantity": 0.00038}, {"price": 65720.19, "quantity": 0.00013}, {"price": 65729.64, "quantity": 0.00291}, {"price": 65739.44, "quantity": 0.00044}, {"price": 65750.0, "quantity": 0.00894}, {"price": 65751.47, "quantity": 0.00018}, {"price": 65754.43, "quantity": 0.00101}, {"price": 65763.1, "quantity": 0.00078}, {"price": 65767.18, "quantity": 0.00084}, {"price": 65773.89, "quantity": 0.00152}, {"price": 65796.97, "quantity": 0.04711}, {"price": 65832.89, "quantity": 0.17539}, {"price": 65840.16, "quantity": 0.0006}, {"price": 65860.46, "quantity": 0.01366}, {"price": 65867.51, "quantity": 0.00076}, {"price": 65868.29, "quantity": 0.00098}, {"price": 65880.57, "quantity": 0.00406}, {"price": 65881.94, "quantity": 9e-05}, {"price": 65886.08, "quantity": 0.00315}, {"price": 65933.33, "quantity": 0.0001}, {"price": 65936.47, "quantity": 0.00015}, {"price": 65940.2, "quantity": 0.00039}, {"price": 65941.06, "quantity": 0.00078}, {"price": 65943.2, "quantity": 0.00035}, {"price": 65945.73, "quantity": 0.00015}, {"price": 65949.24, "quantity": 0.00406}, {"price": 65958.8, "quantity": 0.00075}, {"price": 65968.41, "quantity": 0.0003}, {"price": 65968.66, "quantity": 0.00015}, {"price": 65974.14, "quantity": 0.00243}, {"price": 65977.64, "quantity": 0.00048}, {"price": 65991.87, "quantity": 0.00466}, {"price": 65992.69, "quantity": 0.00315}, {"price": 65993.99, "quantity": 0.00052}, {"price": 65994.36, "quantity": 0.00047}, {"price": 66000.0, "quantity": 0.00907}, {"price": 66000.82, "quantity": 0.00406}, {"price": 66007.05, "quantity": 0.00104}, {"price": 66018.88, "quantity": 0.00015}, {"price": 66032.06, "quantity": 0.00061}, {"price": 66037.97, "quantity": 0.00026}, {"price": 66040.77, "quantity": 0.006}, {"price": 66040.85, "quantity": 0.00039}, {"price": 66042.43, "quantity": 0.00314}, {"price": 66046.05, "quantity": 0.01}, {"price": 66056.9, "quantity": 0.01}, {"price": 66064.19, "quantity": 0.00153}, {"price": 66067.05, "quantity": 0.00314}, {"price": 66067.22, "quantity": 0.00015}, {"price": 66068.27, "quantity": 0.00032}, {"price": 66081.67, "quantity": 0.00018}, {"price": 66089.47, "quantity": 0.00015}, {"price": 66090.63, "quantity": 0.00314}, {"price": 66096.16, "quantity": 0.0013}, {"price": 66105.26, "quantity": 0.05283}, {"price": 66108.9, "quantity": 0.00037}, {"price": 66112.69, "quantity": 0.00378}, {"price": 66141.45, "quantity": 0.001}, {"price": 66142.6, "quantity": 0.00042}, {"price": 66154.85, "quantity": 0.00051}, {"price": 66166.67, "quantity": 0.00041}, {"price": 66180.71, "quantity": 0.00047}, {"price": 66182.61, "quantity": 9e-05}, {"price": 66189.25, "quantity": 0.001}, {"price": 66190.39, "quantity": 0.00152}, {"price": 66190.58, "quantity": 0.00015}, {"price": 66198.57, "quantity": 0.00782}, {"price": 66209.31, "quantity": 0.00095}, {"price": 66210.98, "quantity": 0.00087}, {"price": 66214.32, "quantity": 0.0154}, {"price": 66220.76, "quantity": 0.00015}, {"price": 66232.41, "quantity": 0.00065}, {"price": 66232.58, "quantity": 0.00026}, {"price": 66240.32, "quantity": 0.0006}, {"price": 66243.05, "quantity": 0.00075}, {"price": 66243.32, "quantity": 0.00043}, {"price": 66243.33, "quantity": 0.00043}, {"price": 66245.25, "quantity": 0.00044}, {"price": 66248.26, "quantity": 0.00037}, {"price": 66250.0, "quantity": 0.00894}, {"price": 66251.57, "quantity": 0.01}, {"price": 66252.01, "quantity": 0.00153}, {"price": 66255.62, "quantity": 0.01358}, {"price": 66266.12, "quantity": 0.00045}, {"price": 66272.31, "quantity": 0.00015}, {"price": 66281.36, "quantity": 0.00101}, {"price": 66331.91, "quantity": 0.0005}, {"price": 66346.64, "quantity": 0.00041}, {"price": 66356.74, "quantity": 0.0032}, {"price": 66370.49, "quantity": 0.00104}, {"price": 66371.4, "quantity": 0.01}, {"price": 66371.65, "quantity": 0.00059}, {"price": 66377.21, "quantity": 0.00075}, {"price": 66406.15, "quantity": 0.00466}, {"price": 66427.19, "quantity": 0.00026}, {"price": 66439.84, "quantity": 0.00153}, {"price": 66446.23, "quantity": 0.01}, {"price": 66447.88, "quantity": 0.00032}, {"price": 66449.1, "quantity": 0.005}, {"price": 66454.06, "quantity": 0.00879}, {"price": 66475.3, "quantity": 0.002}, {"price": 66483.28, "quantity": 9e-05}, {"price": 66494.27, "quantity": 0.15316}, {"price": 66500.0, "quantity": 0.0095}, {"price": 66500.1, "quantity": 0.003}, {"price": 66505.0, "quantity": 0.002}, {"price": 66507.1, "quantity": 0.002}, {"price": 66507.6, "quantity": 0.004}, {"price": 66508.6, "quantity": 0.003}, {"price": 66513.27, "quantity": 0.00152}, {"price": 66517.5, "quantity": 0.003}, {"price": 66523.07, "quantity": 0.00782}, {"price": 66526.7, "quantity": 0.003}, {"price": 66529.7, "quantity": 0.003}, {"price": 66535.02, "quantity": 0.0024}, {"price": 66536.79, "quantity": 0.00311}, {"price": 66538.9, "quantity": 0.0154}, {"price": 66543.9, "quantity": 0.001}, {"price": 66547.06, "quantity": 0.00083}, {"price": 66548.97, "quantity": 0.00034}, {"price": 66553.85, "quantity": 0.0015}, {"price": 66575.26, "quantity": 0.00065}, {"price": 66576.63, "quantity": 0.00015}, {"price": 66585.98, "quantity": 0.00015}, {"price": 66607.98, "quantity": 0.00234}, {"price": 66609.13, "quantity": 0.00015}, {"price": 66627.66, "quantity": 0.00153}, {"price": 66640.07, "quantity": 0.001}, {"price": 66640.9, "quantity": 0.01}, {"price": 66650.18, "quantity": 0.00038}, {"price": 66653.15, "quantity": 0.0135}, {"price": 66657.36, "quantity": 0.00158}, {"price": 66659.84, "quantity": 0.00015}, {"price": 66661.89, "quantity": 0.00098}, {"price": 66666.67, "quantity": 0.00039}, {"price": 66678.03, "quantity": 0.00374}, {"price": 66696.75, "quantity": 0.01}, {"price": 66698.18, "quantity": 0.001}, {"price": 66708.65, "quantity": 0.00014}, {"price": 66724.93, "quantity": 0.00048}, {"price": 66725.08, "quantity": 0.00104}, {"price": 66731.44, "quantity": 0.00051}, {"price": 66737.41, "quantity": 0.00014}, {"price": 66750.18, "quantity": 0.00035}, {"price": 66761.22, "quantity": 0.00047}, {"price": 66769.2, "quantity": 0.001}, {"price": 66783.6, "quantity": 0.001}, {"price": 66783.62, "quantity": 0.00076}, {"price": 66783.95, "quantity": 9e-05}, {"price": 66798.26, "quantity": 0.00074}, {"price": 66801.45, "quantity": 0.00155}, {"price": 66815.48, "quantity": 0.00153}, {"price": 66820.43, "quantity": 0.00466}, {"price": 66827.03, "quantity": 0.00014}, {"price": 66832.37, "quantity": 0.00355}, {"price": 66835.57, "quantity": 0.01}, {"price": 66836.15, "quantity": 0.0015}, {"price": 66842.11, "quantity": 0.05225}, {"price": 66850.18, "quantity": 0.0004}, {"price": 66863.68, "quantity": 0.00014}, {"price": 66869.01, "quantity": 0.00111}, {"price": 66872.96, "quantity": 0.02895}, {"price": 66875.0, "quantity": 0.00107}, {"price": 66898.16, "quantity": 0.00048}, {"price": 66898.93, "quantity": 0.0005}, {"price": 66909.19, "quantity": 0.00111}, {"price": 66912.32, "quantity": 0.00111}, {"price": 66915.73, "quantity": 0.00014}, {"price": 66916.94, "quantity": 0.00037}, {"price": 66945.34, "quantity": 0.00111}, {"price": 66950.18, "quantity": 0.00043}, {"price": 66971.34, "quantity": 0.00111}, {"price": 67000.0, "quantity": 0.01107}, {"price": 67003.05, "quantity": 0.001}, {"price": 67003.3, "quantity": 0.00153}, {"price": 67030.23, "quantity": 0.01}, {"price": 67050.18, "quantity": 0.00028}, {"price": 67053.07, "quantity": 0.01342}, {"price": 67055.4, "quantity": 0.001}, {"price": 67098.01, "quantity": 0.00092}, {"price": 67098.91, "quantity": 0.17539}, {"price": 67101.15, "quantity": 0.05245}, {"price": 67142.16, "quantity": 0.00308}, {"price": 67150.18, "quantity": 0.0003}, {"price": 67159.03, "quantity": 0.0015}, {"price": 67201.67, "quantity": 0.00197}, {"price": 67203.55, "quantity": 0.00078}, {"price": 67216.79, "quantity": 0.00014}, {"price": 67221.99, "quantity": 0.00074}, {"price": 67224.9, "quantity": 0.01}, {"price": 67226.23, "quantity": 0.00014}, {"price": 67234.71, "quantity": 0.00466}, {"price": 67243.37, "quantity": 0.00371}, {"price": 67249.6, "quantity": 0.00014}, {"price": 67250.18, "quantity": 0.0003}, {"price": 67250.48, "quantity": 0.00308}, {"price": 67280.61, "quantity": 0.00308}, {"price": 67295.33, "quantity": 0.00154}, {"price": 67300.8, "quantity": 0.00014}, {"price": 67323.1, "quantity": 0.00325}, {"price": 67326.91, "quantity": 0.00082}, {"price": 67329.28, "quantity": 0.00042}, {"price": 67329.29, "quantity": 0.00042}, {"price": 67333.78, "quantity": 0.00148}, {"price": 67350.08, "quantity": 0.00014}, {"price": 67350.18, "quantity": 0.00031}, {"price": 67372.19, "quantity": 0.00307}, {"price": 67378.22, "quantity": 0.00307}, {"price": 67385.35, "quantity": 0.00014}, {"price": 67400.0, "quantity": 0.0001}, {"price": 67412.32, "quantity": 0.00031}, {"price": 67415.92, "quantity": 0.00307}, {"price": 67431.31, "quantity": 0.00029}, {"price": 67450.18, "quantity": 0.0003}, {"price": 67455.39, "quantity": 0.01334}, {"price": 67455.96, "quantity": 0.00307}, {"price": 67463.28, "quantity": 0.00866}, {"price": 67481.91, "quantity": 0.00148}, {"price": 67492.98, "quantity": 0.00307}, {"price": 67506.6, "quantity": 0.00014}, {"price": 67550.18, "quantity": 0.00028}, {"price": 67559.15, "quantity": 0.00014}, {"price": 67578.95, "quantity": 0.05168}, {"price": 67592.37, "quantity": 0.00036}, {"price": 67648.98, "quantity": 0.00466}, {"price": 67650.18, "quantity": 0.0003}, {"price": 67666.73, "quantity": 0.00306}, {"price": 67727.24, "quantity": 0.00048}, {"price": 67750.18, "quantity": 0.0003}, {"price": 67804.79, "quantity": 0.00148}, {"price": 67808.72, "quantity": 0.00368}, {"price": 67809.29, "quantity": 0.001}, {"price": 67833.33, "quantity": 0.0001}, {"price": 67850.18, "quantity": 0.0003}, {"price": 67924.49, "quantity": 0.00093}, {"price": 67950.18, "quantity": 0.00028}, {"price": 68000.0, "quantity": 0.00768}, {"price": 68033.29, "quantity": 0.00014}, {"price": 68039.79, "quantity": 0.00016}, {"price": 68043.05, "quantity": 0.00028}, {"price": 68050.18, "quantity": 0.0003}, {"price": 68063.26, "quantity": 0.00466}, {"price": 68067.92, "quantity": 0.00075}, {"price": 68106.76, "quantity": 0.00081}, {"price": 68113.71, "quantity": 0.00146}, {"price": 68138.58, "quantity": 0.00055}, {"price": 68150.18, "quantity": 0.0003}, {"price": 68250.18, "quantity": 0.0003}, {"price": 68274.61, "quantity": 0.00036}, {"price": 68289.46, "quantity": 0.0033}, {"price": 68294.73, "quantity": 0.26674}, {"price": 68294.94, "quantity": 0.34954}, {"price": 68295.15, "quantity": 0.03287}, {"price": 68295.36, "quantity": 0.31045}, {"price": 68295.57, "quantity": 0.04042}, {"price": 68315.79, "quantity": 0.05113}, {"price": 68333.33, "quantity": 0.00039}, {"price": 68341.0, "quantity": 0.00012}, {"price": 68350.18, "quantity": 0.0003}, {"price": 68364.93, "quantity": 0.17539}, {"price": 68374.06, "quantity": 0.00365}, {"price": 68415.23, "quantity": 0.00042}, {"price": 68450.18, "quantity": 0.00032}, {"price": 68452.04, "quantity": 0.00151}, {"price": 68487.84, "quantity": 0.00853}, {"price": 68500.0, "quantity": 0.00341}, {"price": 68550.18, "quantity": 0.00031}, {"price": 68650.18, "quantity": 0.0003}, {"price": 68750.18, "quantity": 0.0003}, {"price": 68850.18, "quantity": 0.0003}, {"price": 68866.66, "quantity": 9e-05}, {"price": 68886.61, "quantity": 0.0008}, {"price": 68893.64, "quantity": 0.00145}, {"price": 68920.4, "quantity": 0.001}, {"price": 68939.4, "quantity": 0.00362}, {"price": 68950.18, "quantity": 0.00026}, {"price": 68963.75, "quantity": 0.00036}, {"price": 69000.0, "quantity": 0.00768}, {"price": 69050.18, "quantity": 0.00029}, {"price": 69052.63, "quantity": 0.05058}, {"price": 69086.61, "quantity": 0.00033}, {"price": 69092.09, "quantity": 0.00056}, {"price": 69191.98, "quantity": 0.00029}, {"price": 69255.82, "quantity": 0.00335}, {"price": 69352.22, "quantity": 0.00074}, {"price": 69500.0, "quantity": 0.0003}, {"price": 69501.0, "quantity": 0.0001}, {"price": 69504.75, "quantity": 0.00359}, {"price": 69527.95, "quantity": 0.0084}, {"price": 69630.95, "quantity": 0.17539}, {"price": 69659.84, "quantity": 0.00035}, {"price": 69666.46, "quantity": 0.00079}, {"price": 69673.56, "quantity": 0.00143}, {"price": 69789.47, "quantity": 0.05005}, {"price": 70000.0, "quantity": 0.01835}, {"price": 70002.05, "quantity": 0.001}, {"price": 70031.52, "quantity": 0.001}, {"price": 70047.84, "quantity": 0.00011}, {"price": 70070.09, "quantity": 0.00356}, {"price": 70264.76, "quantity": 0.09425}, {"price": 70333.33, "quantity": 9e-05}, {"price": 70362.95, "quantity": 0.00035}, {"price": 70446.3, "quantity": 0.00078}, {"price": 70453.49, "quantity": 0.00141}, {"price": 70526.32, "quantity": 0.04952}, {"price": 70583.85, "quantity": 0.00828}, {"price": 70635.43, "quantity": 0.00353}, {"price": 70636.52, "quantity": 0.00072}, {"price": 71073.16, "quantity": 0.00035}, {"price": 71226.15, "quantity": 0.00078}, {"price": 71233.42, "quantity": 0.0014}, {"price": 71263.16, "quantity": 0.04901}, {"price": 71655.8, "quantity": 0.00816}, {"price": 71666.67, "quantity": 0.00039}, {"price": 71790.54, "quantity": 0.00034}, {"price": 71800.0, "quantity": 9e-05}, {"price": 72000.0, "quantity": 0.04851}, {"price": 72006.0, "quantity": 0.00077}, {"price": 72013.35, "quantity": 0.00138}, {"price": 72070.66, "quantity": 0.00033}, {"price": 72442.34, "quantity": 0.01484}, {"price": 72515.17, "quantity": 0.00034}, {"price": 72744.02, "quantity": 0.00803}, {"price": 73247.1, "quantity": 0.00034}, {"price": 73266.66, "quantity": 9e-05}, {"price": 73333.33, "quantity": 0.00039}, {"price": 73986.42, "quantity": 0.00033}, {"price": 74712.46, "quantity": 0.11484}, {"price": 74729.29, "quantity": 0.08325}, {"price": 74733.21, "quantity": 0.00033}, {"price": 74733.33, "quantity": 9e-05}, {"price": 74755.29, "quantity": 0.06153}, {"price": 74938.04, "quantity": 0.4}, {"price": 75000.0, "quantity": 0.00039}, {"price": 75002.0, "quantity": 0.0001}, {"price": 75003.0, "quantity": 0.0001}, {"price": 75004.0, "quantity": 0.0001}, {"price": 75005.0, "quantity": 0.0001}, {"price": 75006.0, "quantity": 0.0001}, {"price": 75487.53, "quantity": 0.00033}, {"price": 75500.0, "quantity": 0.0001}, {"price": 76200.0, "quantity": 8e-05}, {"price": 76249.47, "quantity": 0.00032}, {"price": 76317.61, "quantity": 0.00131}, {"price": 76819.43, "quantity": 0.00727}, {"price": 77019.1, "quantity": 0.00032}, {"price": 77666.66, "quantity": 8e-05}, {"price": 77765.89, "quantity": 0.35}, {"price": 77796.5, "quantity": 0.00032}, {"price": 78501.0, "quantity": 0.0001}, {"price": 78581.74, "quantity": 0.00031}, {"price": 78804.18, "quantity": 0.001}, {"price": 79133.33, "quantity": 8e-05}, {"price": 79374.91, "quantity": 0.00031}, {"price": 79594.19, "quantity": 0.001}, {"price": 79992.16, "quantity": 0.001}, {"price": 80040.0, "quantity": 0.0009}, {"price": 80176.08, "quantity": 0.00031}, {"price": 80373.5, "quantity": 0.0009}, {"price": 80392.12, "quantity": 0.001}, {"price": 80600.0, "quantity": 8e-05}, {"price": 80707.0, "quantity": 0.0009}, {"price": 80794.08, "quantity": 0.001}, {"price": 80985.34, "quantity": 0.0003}, {"price": 81040.5, "quantity": 0.0009}, {"price": 81198.05, "quantity": 0.001}, {"price": 81300.71, "quantity": 0.25}, {"price": 81604.04, "quantity": 0.001}, {"price": 81802.77, "quantity": 0.0003}, {"price": 82012.06, "quantity": 0.001}, {"price": 82066.66, "quantity": 8e-05}, {"price": 82204.97, "quantity": 0.01112}, {"price": 82370.81, "quantity": 0.00047}, {"price": 82422.12, "quantity": 0.001}, {"price": 82628.45, "quantity": 0.0003}, {"price": 83462.47, "quantity": 0.00029}, {"price": 83533.33, "quantity": 8e-05}, {"price": 84304.9, "quantity": 0.00029}, {"price": 85000.0, "quantity": 7e-05}, {"price": 85155.84, "quantity": 0.00029}, {"price": 85762.44, "quantity": 0.00014}, {"price": 86015.36, "quantity": 0.00029}, {"price": 86883.56, "quantity": 0.00028}, {"price": 87760.53, "quantity": 0.00028}, {"price": 88646.34, "quantity": 0.00028}, {"price": 89541.1, "quantity": 0.00027}, {"price": 90444.89, "quantity": 0.00027}, {"price": 91357.8, "quantity": 0.00027}, {"price": 92279.92, "quantity": 0.00027}, {"price": 93211.35, "quantity": 0.00026}, {"price": 94152.19, "quantity": 0.00026}, {"price": 95102.52, "quantity": 0.00026}, {"price": 95840.01, "quantity": 0.92247}, {"price": 96062.44, "quantity": 0.00026}, {"price": 96231.3, "quantity": 0.01294}, {"price": 97032.05, "quantity": 0.00025}, {"price": 98011.45, "quantity": 0.00025}, {"price": 99000.73, "quantity": 0.00025}, {"price": 100000.0, "quantity": 0.00025}, {"price": 104438.52, "quantity": 8e-05}, {"price": 111393.3, "quantity": 0.01294}, {"price": 63326.99, "quantity": 0.00157}], "snapshot_time": 1786680055005, "source": "reconciled"}}
{"type": "delta", "data": {"event_type": "depth_update", "exchange": "binance", "symbol": "BTCUSDT", "event_time": 1786680056013, "received_time": 1786680056190, "first_update_id": 4671966, "final_update_id": 4672005, "bids": [{"price": 63284.85, "quantity": 0.0}, {"price": 63284.84, "quantity": 0.0}, {"price": 63284.83, "quantity": 0.0}, {"price": 63284.81, "quantity": 0.0}, {"price": 63284.8, "quantity": 0.0}, {"price": 63284.69, "quantity": 0.0}, {"price": 63284.06, "quantity": 0.0}, {"price": 63284.01, "quantity": 0.0}, {"price": 63284.0, "quantity": 0.0}, {"price": 63283.99, "quantity": 0.0}, {"price": 63283.93, "quantity": 0.0}, {"price": 63283.92, "quantity": 0.0}, {"price": 63283.59, "quantity": 0.0}, {"price": 63283.53, "quantity": 0.0}, {"price": 63283.41, "quantity": 0.0}, {"price": 63283.2, "quantity": 0.0}, {"price": 63283.19, "quantity": 0.0}, {"price": 63283.17, "quantity": 0.0}, {"price": 63283.16, "quantity": 0.0}, {"price": 63283.03, "quantity": 0.0}, {"price": 63283.02, "quantity": 0.0}, {"price": 63278.34, "quantity": 0.0}, {"price": 63276.0, "quantity": 16.32647}, {"price": 63275.99, "quantity": 0.00136}, {"price": 63275.98, "quantity": 0.00064}, {"price": 63275.95, "quantity": 0.02734}, {"price": 63275.9, "quantity": 0.00288}, {"price": 63275.89, "quantity": 0.08452}, {"price": 63275.86, "quantity": 0.00051}, {"price": 63275.85, "quantity": 0.00072}, {"price": 63275.84, "quantity": 0.09915}, {"price": 63275.83, "quantity": 0.05195}, {"price": 63275.82, "quantity": 0.00072}, {"price": 63275.81, "quantity": 0.26546}, {"price": 63275.64, "quantity": 0.01676}, {"price": 63275.63, "quantity": 0.00072}, {"price": 63275.62, "quantity": 0.63487}, {"price": 63275.6, "quantity": 0.008}, {"price": 63275.59, "quantity": 0.0008}, {"price": 63275.58, "quantity": 0.00902}, {"price": 63275.57, "quantity": 0.00036}, {"price": 63275.4, "quantity": 0.00036}], "asks": [{"price": 63276.01, "quantity": 2.8749}, {"price": 63276.54, "quantity": 0.00072}, {"price": 63276.55, "quantity": 0.08377}, {"price": 63276.8, "quantity": 0.00032}, {"price": 63277.04, "quantity": 0.00948}, {"price": 63277.07, "quantity": 0.00036}, {"price": 63277.27, "quantity": 0.00072}, {"price": 63277.28, "quantity": 0.17732}, {"price": 63277.71, "quantity": 0.00036}, {"price": 63278.08, "quantity": 0.00072}, {"price": 63278.09, "quantity": 0.2676}, {"price": 63278.54, "quantity": 0.00072}, {"price": 63278.55, "quantity": 0.23619}, {"price": 63278.63, "quantity": 0.00036}, {"price": 63278.64, "quantity": 0.1826}, {"price": 63279.34, "quantity": 0.00072}, {"price": 63279.7, "quantity": 0.00064}, {"price": 63279.8, "quantity": 0.00036}, {"price": 63284.86, "quantity": 0.0}, {"price": 63284.87, "quantity": 0.0}, {"price": 63284.88, "quantity": 0.0}, {"price": 63285.18, "quantity": 0.0}, {"price": 63285.25, "quantity": 0.0}, {"price": 63285.26, "quantity": 0.0}, {"price": 63285.99, "quantity": 0.0}, {"price": 63286.0, "quantity": 0.0}, {"price": 63286.11, "quantity": 0.0}, {"price": 63286.12, "quantity": 0.0}, {"price": 63286.13, "quantity": 0.0}, {"price": 63286.4, "quantity": 0.0}, {"price": 63286.95, "quantity": 0.0}, {"price": 63286.96, "quantity": 0.0}, {"price": 63287.01, "quantity": 0.0}, {"price": 63287.4, "quantity": 0.0}, {"price": 63287.86, "quantity": 0.0}, {"price": 63288.0, "quantity": 0.0}, {"price": 63288.05, "quantity": 0.0}, {"price": 63288.36, "quantity": 0.0}]}}
{"type": "delta", "data": {"event_type": "depth_update", "exchange": "binance", "symbol": "BTCUSDT", "event_time": 1786680057020, "received_time": 1786680057196, "first_update_id": 4672006, "final_update_id": 4672009, "bids": [{"price": 63198.74, "quantity": 0.0}, {"price": 63165.07, "quantity": 8e-05}], "asks": [{"price": 63354.9, "quantity": 8e-05}, {"price": 63388.67, "quantity": 0.0}]}}
{"type": "delta", "data": {"event_type": "depth_update", "exchange": "binance", "symbol": "BTCUSDT", "event_time": 1786680058003, "received_time": 1786680058179, "first_update_id": 4672010, "final_update_id": 4672010, "bids": [], "asks": [{"price": 63592.4, "quantity": 0.006}]}}
{"type": "delta", "data": {"event_type": "depth_update", "exchange": "binance", "symbol": "BTCUSDT", "event_time": 1786680059025, "received_time": 1786680059202, "first_update_id": 4672011, "final_update_id": 4672012, "bids": [], "asks": [{"price": 63276.01, "quantity": 2.87411}, {"price": 63285.38, "quantity": 0.0}]}}
{"type": "delta", "data": {"event_type": "depth_update", "exchange": "binance", "symbol": "BTCUSDT", "event_time": 1786680060011, "received_time": 1786680060189, "first_update_id": 4672013, "final_update_id": 4672015, "bids": [{"price": 63274.68, "quantity": 0.001}, {"price": 62010.49, "quantity": 0.15806}], "asks": [{"price": 63276.53, "quantity": 0.001}]}}
{"type": "delta", "data": {"event_type": "depth_update", "exchange": "binance", "symbol": "BTCUSDT", "event_time": 1786680061037, "received_time": 1786680061212, "first_update_id": 4672016, "final_update_id": 4672069, "bids": [{"price": 60000.0, "quantity": 0.00041}, {"price": 58333.33, "quantity": 0.0}, {"price": 56666.67, "quantity": 0.0}, {"price": 55000.0, "quantity": 0.00788}], "asks": [{"price": 63297.5, "quantity": 0.0}, {"price": 63297.51, "quantity": 0.00011}]}}
{"type": "delta", "data": {"event_type": "depth_update", "exchange": "binance", "symbol": "BTCUSDT", "event_time": 1786680062008, "received_time": 1786680062185, "first_update_id": 4672070, "final_update_id": 4672074, "bids": [{"price": 61666.67, "quantity": 0.0}], "asks": [{"price": 63276.01, "quantity": 2.8735}, {"price": 64035.32, "quantity": 0.0006}, {"price": 65000.0, "quantity": 0.00894}, {"price": 66666.67, "quantity": 0.0}]}}
{"type": "delta", "data": {"event_type": "depth_update", "exchange": "binance", "symbol": "BTCUSDT", "event_time": 1786680063014, "received_time": 1786680063201, "first_update_id": 4672075, "final_update_id": 4672076, "bids": [], "asks": [{"price": 68333.33, "quantity": 0.0}, {"price": 70000.0, "quantity": 0.01796}]}}
{"type": "delta", "data": {"event_type": "depth_update", "exchange": "binance", "symbol": "BTCUSDT", "event_time": 1786680064047, "received_time": 1786680064223, "first_update_id": 4672077, "final_update_id": 4672080, "bids": [], "asks": [{"price": 63276.01, "quantity": 2.8613}, {"price": 71666.67, "quantity": 0.0}]}}
{"type": "delta", "data": {"event_type": "depth_update", "exchange": "binance", "symbol": "BTCUSDT", "event_time": 1786680065019, "received_time": 1786680065200, "first_update_id": 4672081, "final_update_id": 4672081, "bids": [], "asks": [{"price": 73333.33, "quantity": 0.0}]}}
{"type": "delta", "data": {"event_type": "depth_update", "exchange": "binance", "symbol": "BTCUSDT", "event_time": 1786680066012, "received_time": 1786680066190, "first_update_id": 4672082, "final_update_id": 4672085, "bids": [{"price": 63244.36, "quantity": 0.00316}, {"price": 55000.0, "quantity": 0.00827}], "asks": [{"price": 63341.66, "quantity": 0.0}, {"price": 75000.0, "quantity": 0.0}]}}
{"type": "delta", "data": {"event_type": "depth_update", "exchange": "binance", "symbol": "BTCUSDT", "event_time": 1786680067030, "received_time": 1786680067220, "first_update_id": 4672086, "final_update_id": 4672089, "bids": [{"price": 58333.33, "quantity": 0.00039}, {"price": 56666.67, "quantity": 0.00039}], "asks": [{"price": 63276.01, "quantity": 2.86091}, {"price": 63307.65, "quantity": 0.00315}]}}
{"type": "delta", "data": {"event_type": "depth_update", "exchange": "binance", "symbol": "BTCUSDT", "event_time": 1786680068038, "received_time": 1786680068216, "first_update_id": 4672090, "final_update_id": 4672091, "bids": [{"price": 61666.67, "quantity": 0.00039}, {"price": 60000.0, "quantity": 0.0008}], "asks": []}}
{"type": "delta", "data": {"event_type": "depth_update", "exchange": "binance", "symbol": "BTCUSDT", "event_time": 1786680070012, "received_time": 1786680070190, "first_update_id": 4672092, "final_update_id": 4672092, "bids": [{"price": 63274.68, "quantity": 0.0}], "asks": []}}
{"type": "delta", "data": {"event_type": "depth_update", "exchange": "binance", "symbol": "BTCUSDT", "event_time": 1786680071009, "received_time": 1786680071186, "first_update_id": 4672093, "final_update_id": 4672147, "bids": [{"price": 63274.68, "quantity": 0.001}], "asks": [{"price": 63276.53, "quantity": 0.001}, {"price": 63297.5, "quantity": 0.0}, {"price": 63297.51, "quantity": 0.00011}, {"price": 63333.33, "quantity": 0.00039}, {"price": 65000.0, "quantity": 0.00933}]}}
{"type": "delta", "data": {"event_type": "depth_update", "exchange": "binance", "symbol": "BTCUSDT", "event_time": 1786680072010, "received_time": 1786680072187, "first_update_id": 4672148, "final_update_id": 4672148, "bids": [], "asks": [{"price": 66666.67, "quantity": 0.00039}]}}
{"type": "delta", "data": {"event_type": "depth_update", "exchange": "binance", "symbol": "BTCUSDT", "event_time": 1786680073004, "received_time": 1786680073181, "first_update_id": 4672149, "final_update_id": 4672190, "bids": [{"price": 63284.85, "quantity": 34.70219}, {"price": 63284.84, "quantity": 0.64012}, {"price": 63284.83, "quantity": 0.00064}, {"price": 63284.82, "quantity": 0.0694}, {"price": 63284.8, "quantity": 0.03407}, {"price": 63284.69, "quantity": 0.00888}, {"price": 63284.66, "quantity": 0.00114}, {"price": 63284.58, "quantity": 0.00032}, {"price": 63284.54, "quantity": 0.05047}, {"price": 63284.06, "quantity": 0.00036}, {"price": 63283.99, "quantity": 0.00051}, {"price": 63283.76, "quantity": 0.00072}, {"price": 63283.75, "quantity": 2.07338}, {"price": 63283.74, "quantity": 1.56796}, {"price": 63283.73, "quantity": 0.00032}, {"price": 63283.6, "quantity": 0.0316}, {"price": 63283.59, "quantity": 0.016}, {"price": 63283.41, "quantity": 0.00936}, {"price": 63283.39, "quantity": 0.08731}, {"price": 63276.0, "quantity": 0.0}, {"price": 63275.99, "quantity": 0.0}, {"price": 63275.98, "quantity": 0.0}, {"price": 63275.95, "quantity": 0.0}, {"price": 63275.9, "quantity": 0.0}, {"price": 63275.89, "quantity": 0.0}, {"price": 63275.86, "quantity": 0.0}, {"price": 63275.85, "quantity": 0.0}, {"price": 63275.84, "quantity": 0.0}, {"price": 63275.83, "quantity": 0.0}, {"price": 63275.82, "quantity": 0.0}, {"price": 63275.81, "quantity": 0.0}, {"price": 63275.64, "quantity": 0.0}, {"price": 63275.63, "quantity": 0.0}, {"price": 63275.62, "quantity": 0.0}, {"price": 63275.6, "quantity": 0.0}, {"price": 63275.59, "quantity": 0.0}, {"price": 63275.58, "quantity": 0.0}, {"price": 63275.57, "quantity": 0.0}, {"price": 63275.4, "quantity": 0.0}], "asks": [{"price": 63276.01, "quantity": 0.0}, {"price": 63276.53, "quantity": 0.0}, {"price": 63276.54, "quantity": 0.0}, {"price": 63276.55, "quantity": 0.0}, {"price": 63276.8, "quantity": 0.0}, {"price": 63277.04, "quantity": 0.0}, {"price": 63277.07, "quantity": 0.0}, {"price": 63277.27, "quantity": 0.0}, {"price": 63277.28, "quantity": 0.0}, {"price": 63277.71, "quantity": 0.0}, {"price": 63278.08, "quantity": 0.0}, {"price": 63278.09, "quantity": 0.0}, {"price": 63278.54, "quantity": 0.0}, {"price": 63278.55, "quantity": 0.0}, {"price": 63278.63, "quantity": 0.0}, {"price": 63278.64, "quantity": 0.0}, {"price": 63279.34, "quantity": 0.0}, {"price": 63279.7, "quantity": 0.0}, {"price": 63279.8, "quantity": 0.0}, {"price": 63284.86, "quantity": 1.22456}, {"price": 63284.87, "quantity": 0.00459}, {"price": 63284.88, "quantity": 0.07606}, {"price": 63285.04, "quantity": 0.00072}, {"price": 63285.05, "quantity": 0.34122}, {"price": 63285.18, "quantity": 0.00036}, {"price": 63285.19, "quantity": 0.00072}, {"price": 63285.2, "quantity": 2.00071}, {"price": 63286.0, "quantity": 0.0887}, {"price": 63286.12, "quantity": 0.00072}, {"price": 63286.13, "quantity": 0.15523}, {"price": 63286.4, "quantity": 0.00032}, {"price": 63286.59, "quantity": 0.00036}, {"price": 63286.76, "quantity": 0.00032}, {"price": 63286.97, "quantity": 0.00072}, {"price": 63286.98, "quantity": 0.26534}, {"price": 63287.0, "quantity": 0.00032}, {"price": 63287.4, "quantity": 0.20671}, {"price": 63287.54, "quantity": 0.00032}, {"price": 63287.86, "quantity": 0.00036}, {"price": 63592.4, "quantity": 0.0}, {"price": 68333.33, "quantity": 0.00039}]}}
{"type": "delta", "data": {"event_type": "depth_update", "exchange": "binance", "symbol": "BTCUSDT", "event_time": 1786680074005, "received_time": 1786680074183, "first_update_id": 4672191, "final_update_id": 4672192, "bids": [{"price": 63284.85, "quantity": 34.69429}], "asks": [{"price": 70000.0, "quantity": 0.01835}]}}
{"type": "delta", "data": {"event_type": "depth_update", "exchange": "binance", "symbol": "BTCUSDT", "event_time": 1786680075007, "received_time": 1786680075184, "first_update_id": 4672193, "final_update_id": 4672193, "bids": [], "asks": [{"price": 71666.67, "quantity": 0.00039}]}}
{"type": "delta", "data": {"event_type": "depth_update", "exchange": "binance", "symbol": "BTCUSDT", "event_time": 1786680076008, "received_time": 1786680076187, "first_update_id": 4672194, "final_update_id": 4672195, "bids": [], "asks": [{"price": 73333.33, "quantity": 0.00039}, {"price": 75000.0, "quantity": 0.00039}]}}
{"type": "delta", "data": {"event_type": "depth_update", "exchange": "binance", "symbol": "BTCUSDT", "event_time": 1786680078010, "received_time": 1786680078187, "first_update_id": 4672196, "final_update_id": 4672197, "bids": [{"price": 62034.84, "quantity": 0.0}, {"price": 60768.83, "quantity": 0.0}], "asks": []}}
{"type": "delta", "data": {"event_type": "depth_update", "exchange": "binance", "symbol": "BTCUSDT", "event_time": 1786680079046, "received_time": 1786680079230, "first_update_id": 4672198, "final_update_id": 4672200, "bids": [{"price": 59502.81, "quantity": 0.0}, {"price": 58236.79, "quantity": 0.0}, {"price": 56970.77, "quantity": 0.0}], "asks": []}}
{"type": "delta", "data": {"event_type": "depth_update", "exchange": "binance", "symbol": "BTCUSDT", "event_time": 1786680080007, "received_time": 1786680080184, "first_update_id": 4672201, "final_update_id": 4672203, "bids": [], "asks": [{"price": 64566.88, "quantity": 0.0}, {"price": 65832.89, "quantity": 0.0}, {"price": 67098.91, "quantity": 0.0}]}}
{"type": "delta", "data": {"event_type": "depth_update", "exchange": "binance", "symbol": "BTCUSDT", "event_time": 1786680081012, "received_time": 1786680081206, "first_update_id": 4672204, "final_update_id": 4672256, "bids": [{"price": 62019.15, "quantity": 0.02857}], "asks": [{"price": 63297.5, "quantity": 0.0}, {"price": 63297.51, "quantity": 0.00011}, {"price": 68364.93, "quantity": 0.0}, {"price": 69630.95, "quantity": 0.0}]}}
{"type": "delta", "data": {"event_type": "depth_update", "exchange": "binance", "symbol": "BTCUSDT", "event_time": 1786680082008, "received_time": 1786680082193, "first_update_id": 4672257, "final_update_id": 4672262, "bids": [{"price": 63284.85, "quantity": 34.69398}, {"price": 63283.53, "quantity": 0.001}, {"price": 63274.68, "quantity": 0.0}, {"price": 60753.46, "quantity": 0.02917}, {"price": 59487.76, "quantity": 0.02979}], "asks": [{"price": 63285.38, "quantity": 0.001}]}}
{"type": "delta", "data": {"event_type": "depth_update", "exchange": "binance", "symbol": "BTCUSDT", "event_time": 1786680083048, "received_time": 1786680083226, "first_update_id": 4672263, "final_update_id": 4672266, "bids": [{"price": 58222.06, "quantity": 0.03044}, {"price": 56956.37, "quantity": 0.03111}], "asks": [{"price": 64550.55, "quantity": 0.17539}, {"price": 66507.6, "quantity": 0.0}]}}
{"type": "delta", "data": {"event_type": "depth_update", "exchange": "binance", "symbol": "BTCUSDT", "event_time": 1786680084013, "received_time": 1786680084190, "first_update_id": 4672267, "final_update_id": 4672270, "bids": [{"price": 63284.85, "quantity": 34.69298}], "asks": [{"price": 65816.24, "quantity": 0.17539}, {"price": 67081.94, "quantity": 0.17539}, {"price": 68347.64, "quantity": 0.17539}]}}
{"type": "delta", "data": {"event_type": "depth_update", "exchange": "binance", "symbol": "BTCUSDT", "event_time": 1786680085012, "received_time": 1786680085189, "first_update_id": 4672271, "final_update_id": 4672271, "bids": [], "asks": [{"price": 69613.33, "quantity": 0.17539}]}}
{"type": "delta", "data": {"event_type": "depth_update", "exchange": "binance", "symbol": "BTCUSDT", "event_time": 1786680086013, "received_time": 1786680086193, "first_update_id": 4672272, "final_update_id": 4672274, "bids": [], "asks": [{"price": 63284.86, "quantity": 1.22156}]}}
{"type": "delta", "data": {"event_type": "depth_update", "exchange": "binance", "symbol": "BTCUSDT", "event_time": 1786680087010, "received_time": 1786680087187, "first_update_id": 4672275, "final_update_id": 4672277, "bids": [], "asks": [{"price": 63284.86, "quantity": 1.21956}, {"price": 63365.61, "quantity": 0.0}]}}
{"type": "delta", "data": {"event_type": "depth_update", "exchange": "binance", "symbol": "BTCUSDT", "event_time": 1786680088003, "received_time": 1786680088178, "first_update_id": 4672278, "final_update_id": 4672278, "bids": [], "asks": [{"price": 63365.61, "quantity": 0.00079}]}}
{"type": "delta", "data": {"event_type": "depth_update", "exchange": "binance", "symbol": "BTCUSDT", "event_time": 1786680089003, "received_time": 1786680089183, "first_update_id": 4672279, "final_update_id": 4672307, "bids": [{"price": 63284.85, "quantity": 34.68463}, {"price": 63284.82, "quantity": 0.0}, {"price": 63284.8, "quantity": 0.0}, {"price": 63284.69, "quantity": 0.0}, {"price": 63284.66, "quantity": 0.00268}, {"price": 63284.65, "quantity": 0.00096}, {"price": 63284.58, "quantity": 0.0}, {"price": 63284.54, "quantity": 0.0}, {"price": 63283.99, "quantity": 0.0}, {"price": 63283.76, "quantity": 0.0}, {"price": 63283.74, "quantity": 0.0}, {"price": 63283.6, "quantity": 0.0}, {"price": 63283.59, "quantity": 0.0}, {"price": 63283.41, "quantity": 0.0}, {"price": 63283.4, "quantity": 0.00072}, {"price": 63283.36, "quantity": 0.00032}, {"price": 63283.32, "quantity": 0.00032}, {"price": 63283.23, "quantity": 0.00423}, {"price": 63283.2, "quantity": 0.00032}, {"price": 63283.19, "quantity": 0.00032}, {"price": 63283.18, "quantity": 0.00032}, {"price": 63282.95, "quantity": 0.00851}, {"price": 63282.93, "quantity": 0.00032}, {"price": 63282.91, "quantity": 0.00032}, {"price": 63282.86, "quantity": 0.00072}], "asks": [{"price": 63284.86, "quantity": 16.27408}, {"price": 63285.04, "quantity": 0.0}, {"price": 63285.05, "quantity": 0.0}, {"price": 63285.12, "quantity": 0.00072}, {"price": 63285.13, "quantity": 0.08604}, {"price": 63285.18, "quantity": 0.01634}, {"price": 63285.19, "quantity": 0.0}, {"price": 63285.2, "quantity": 0.0}, {"price": 63285.31, "quantity": 0.00072}, {"price": 63285.32, "quantity": 0.15751}, {"price": 63285.77, "quantity": 0.00948}, {"price": 63285.95, "quantity": 0.00036}, {"price": 63285.99, "quantity": 0.00072}, {"price": 63286.09, "quantity": 0.00036}, {"price": 63286.1, "quantity": 4.52627}, {"price": 63286.11, "quantity": 1.96096}, {"price": 63286.12, "quantity": 0.0}, {"price": 63286.18, "quantity": 0.05099}, {"price": 63286.32, "quantity": 0.06864}, {"price": 63286.4, "quantity": 0.00064}, {"price": 63286.76, "quantity": 0.0}, {"price": 63286.97, "quantity": 0.0}, {"price": 63286.98, "quantity": 0.0}, {"price": 63287.0, "quantity": 0.0}, {"price": 63287.4, "quantity": 0.0}, {"price": 63287.54, "quantity": 0.0}, {"price": 63287.86, "quantity": 0.0}]}}
{"type": "delta", "data": {"event_type": "depth_update", "exchange": "binance", "symbol": "BTCUSDT", "event_time": 1786680093007, "received_time": 1786680093209, "first_update_id": 4672308, "final_update_id": 4672359, "bids": [{"price": 63283.53, "quantity": 0.0}], "asks": [{"price": 63285.38, "quantity": 0.0}, {"price": 63297.5, "quantity": 0.0}, {"price": 63297.51, "quantity": 0.00011}]}}
{"type": "delta", "data": {"event_type": "depth_update", "exchange": "binance", "symbol": "BTCUSDT", "event_time": 1786680094031, "received_time": 1786680094415, "first_update_id": 4672360, "final_update_id": 4672361, "bids": [{"price": 63283.53, "quantity": 0.001}], "asks": [{"price": 63285.38, "quantity": 0.001}]}}
{"type": "delta", "data": {"event_type": "depth_update", "exchange": "binance", "symbol": "BTCUSDT", "event_time": 1786680100022, "received_time": 1786680100379, "first_update_id": 4672362, "final_update_id": 4672362, "bids": [], "asks": [{"price": 63284.86, "quantity": 16.27308}]}}
{"type": "delta", "data": {"event_type": "depth_update", "exchange": "binance", "symbol": "BTCUSDT", "event_time": 1786680101008, "received_time": 1786680101187, "first_update_id": 4672363, "final_update_id": 4672415, "bids": [], "asks": [{"price": 63284.86, "quantity": 16.27008}, {"price": 63297.5, "quantity": 0.0}, {"price": 63297.51, "quantity": 0.00011}]}}
{"type": "delta", "data": {"event_type": "depth_update", "exchange": "binance", "symbol": "BTCUSDT", "event_time": 1786680102014, "received_time": 1786680102193, "first_update_id": 4672416, "final_update_id": 4672416, "bids": [], "asks": [{"price": 63284.86, "quantity": 16.26908}]}}
{"type": "delta", "data": {"event_type": "depth_update", "exchange": "binance", "symbol": "BTCUSDT", "event_time": 1786680103010, "received_time": 1786680103212, "first_update_id": 4672417, "final_update_id": 4672418, "bids": [{"price": 63284.85, "quantity": 34.68432}], "asks": [{"price": 63284.86, "quantity": 16.26808}]}}
{"type": "delta", "data": {"event_type": "depth_update", "exchange": "binance", "symbol": "BTCUSDT", "event_time": 1786680104009, "received_time": 1786680104188, "first_update_id": 4672419, "final_update_id": 4672420, "bids": [{"price": 63283.53, "quantity": 0.0}], "asks": [{"price": 63285.38, "quantity": 0.0}]}}
{"type": "delta", "data": {"event_type": "depth_update", "exchange": "binance", "symbol": "BTCUSDT", "event_time": 1786680105004, "received_time": 1786680105181, "first_update_id": 4672421, "final_update_id": 4672446, "bids": [{"price": 63284.82, "quantity": 0.00072}, {"price": 63284.81, "quantity": 0.22312}, {"price": 63284.8, "quantity": 0.23072}, {"price": 63284.72, "quantity": 0.05251}, {"price": 63284.69, "quantity": 0.00927}, {"price": 63284.66, "quantity": 0.03352}, {"price": 63284.08, "quantity": 0.00072}, {"price": 63284.07, "quantity": 0.19031}, {"price": 63283.76, "quantity": 0.03232}, {"price": 63283.63, "quantity": 0.00072}, {"price": 63283.62, "quantity": 0.1207}, {"price": 63283.59, "quantity": 0.016}, {"price": 63283.53, "quantity": 0.001}, {"price": 63283.41, "quantity": 0.00884}, {"price": 63283.4, "quantity": 0.0}, {"price": 63283.39, "quantity": 0.0}, {"price": 63283.36, "quantity": 0.0}, {"price": 63283.32, "quantity": 0.0}, {"price": 63283.23, "quantity": 0.0}, {"price": 63283.2, "quantity": 0.0}, {"price": 63283.19, "quantity": 0.0}, {"price": 63283.18, "quantity": 0.0}, {"price": 63282.95, "quantity": 0.0}, {"price": 63282.93, "quantity": 0.0}, {"price": 63282.91, "quantity": 0.0}, {"price": 63282.86, "quantity": 0.0}], "asks": [{"price": 63285.12, "quantity": 0.0}, {"price": 63285.13, "quantity": 0.0}, {"price": 63285.31, "quantity": 0.0}, {"price": 63285.32, "quantity": 0.0}, {"price": 63285.38, "quantity": 0.001}, {"price": 63285.65, "quantity": 0.00032}, {"price": 63285.77, "quantity": 0.0}, {"price": 63285.95, "quantity": 0.0}, {"price": 63286.09, "quantity": 0.0}, {"price": 63286.1, "quantity": 0.0}, {"price": 63286.11, "quantity": 0.0}, {"price": 63286.12, "quantity": 0.00072}, {"price": 63286.18, "quantity": 0.0}, {"price": 63286.32, "quantity": 0.0}, {"price": 63286.76, "quantity": 0.00032}, {"price": 63286.79, "quantity": 0.00072}, {"price": 63286.8, "quantity": 0.57528}, {"price": 63286.97, "quantity": 0.00036}, {"price": 63286.98, "quantity": 0.26534}, {"price": 63287.39, "quantity": 0.76439}, {"price": 63287.4, "quantity": 0.20704}, {"price": 63287.54, "quantity": 0.00032}, {"price": 63287.86, "quantity": 0.00036}]}}
{"type": "delta", "data": {"event_type": "depth_update", "exchange": "binance", "symbol": "BTCUSDT", "event_time": 1786680112009, "received_time": 1786680112187, "first_update_id": 4672447, "final_update_id": 4672497, "bids": [], "asks": [{"price": 63284.86, "quantity": 16.26611}, {"price": 63297.5, "quantity": 0.0}, {"price": 63297.51, "quantity": 0.00011}]}}
{"type": "delta", "data": {"event_type": "depth_update", "exchange": "binance", "symbol": "BTCUSDT", "event_time": 1786680113013, "received_time": 1786680113191, "first_update_id": 4672498, "final_update_id": 4672498, "bids": [], "asks": [{"price": 66543.9, "quantity": 0.0}]}}
{"type": "delta", "data": {"event_type": "depth_update", "exchange": "binance", "symbol": "BTCUSDT", "event_time": 1786680115008, "received_time": 1786680115192, "first_update_id": 4672499, "final_update_id": 4672502, "bids": [{"price": 63283.53, "quantity": 0.0}], "asks": [{"price": 63284.86, "quantity": 16.26411}, {"price": 63285.38, "quantity": 0.0}]}}
{"type": "delta", "data": {"event_type": "depth_update", "exchange": "binance", "symbol": "BTCUSDT", "event_time": 1786680116005, "received_time": 1786680116197, "first_update_id": 4672503, "final_update_id": 4672506, "bids": [{"price": 63283.53, "quantity": 0.001}], "asks": [{"price": 63284.86, "quantity": 16.26211}, {"price": 63285.38, "quantity": 0.001}]}}
{"type": "delta", "data": {"event_type": "depth_update", "exchange": "binance", "symbol": "BTCUSDT", "event_time": 1786680117059, "received_time": 1786680117249, "first_update_id": 4672507, "final_update_id": 4672507, "bids": [], "asks": [{"price": 63284.86, "quantity": 16.26111}]}}
{"type": "delta", "data": {"event_type": "depth_update", "exchange": "binance", "symbol": "BTCUSDT", "event_time": 1786680118006, "received_time": 1786680118183, "first_update_id": 4672508, "final_update_id": 4672512, "bids": [{"price": 62019.15, "quantity": 0.0}, {"price": 60753.46, "quantity": 0.0}, {"price": 59487.76, "quantity": 0.0}], "asks": [{"price": 63365.61, "quantity": 0.0}, {"price": 63375.74, "quantity": 0.00078}]}}
{"type": "delta", "data": {"event_type": "depth_update", "exchange": "binance", "symbol": "BTCUSDT", "event_time": 1786680119041, "received_time": 1786680119219, "first_update_id": 4672513, "final_update_id": 4672514, "bids": [{"price": 58222.06, "quantity": 0.0}], "asks": [{"price": 64550.55, "quantity": 0.0}]}}
{"type": "delta", "data": {"event_type": "depth_update", "exchange": "binance", "symbol": "BTCUSDT", "event_time": 1786680120012, "received_time": 1786680120190, "first_update_id": 4672515, "final_update_id": 4672516, "bids": [], "asks": [{"price": 65816.24, "quantity": 0.0}, {"price": 67081.94, "quantity": 0.0}]}}
{"type": "delta", "data": {"event_type": "depth_update", "exchange": "binance", "symbol": "BTCUSDT", "event_time": 1786680121011, "received_time": 1786680121191, "first_update_id": 4672517, "final_update_id": 4672613, "bids": [{"price": 63298.93, "quantity": 42.96708}, {"price": 63298.92, "quantity": 0.00025}, {"price": 63298.91, "quantity": 0.00136}, {"price": 63298.9, "quantity": 0.20136}, {"price": 63298.88, "quantity": 0.04032}, {"price": 63298.86, "quantity": 0.00072}, {"price": 63298.85, "quantity": 0.30108}, {"price": 63298.79, "quantity": 0.00032}, {"price": 63298.75, "quantity": 0.03115}, {"price": 63298.58, "quantity": 0.00032}, {"price": 63298.12, "quantity": 0.00064}, {"price": 63298.01, "quantity": 0.00072}, {"price": 63298.0, "quantity": 3.81022}, {"price": 63297.99, "quantity": 0.2716}, {"price": 63297.98, "quantity": 0.00032}, {"price": 63297.91, "quantity": 0.00036}, {"price": 63297.9, "quantity": 3.78907}, {"price": 63297.89, "quantity": 1.7338}, {"price": 63297.58, "quantity": 0.15051}, {"price": 63297.35, "quantity": 0.00859}, {"price": 63284.85, "quantity": 0.0}, {"price": 63284.84, "quantity": 0.0}, {"price": 63284.83, "quantity": 0.0}, {"price": 63284.82, "quantity": 0.0}, {"price": 63284.81, "quantity": 0.0}, {"price": 63284.8, "quantity": 0.0}, {"price": 63284.72, "quantity": 0.0}, {"price": 63284.69, "quantity": 0.0}, {"price": 63284.66, "quantity": 0.0}, {"price": 63284.65, "quantity": 0.0}, {"price": 63284.08, "quantity": 0.0}, {"price": 63284.07, "quantity": 0.0}, {"price": 63284.06, "quantity": 0.0}, {"price": 63283.76, "quantity": 0.0}, {"price": 63283.75, "quantity": 0.0}, {"price": 63283.73, "quantity": 0.0}, {"price": 63283.63, "quantity": 0.0}, {"price": 63283.62, "quantity": 0.0}, {"price": 63283.59, "quantity": 0.0}, {"price": 63283.41, "quantity": 0.0}, {"price": 62019.16, "quantity": 0.03173}, {"price": 62010.49, "quantity": 0.0}, {"price": 60753.47, "quantity": 0.02917}], "asks": [{"price": 63284.86, "quantity": 0.0}, {"price": 63284.87, "quantity": 0.0}, {"price": 63284.88, "quantity": 0.0}, {"price": 63285.18, "quantity": 0.0}, {"price": 63285.38, "quantity": 0.0}, {"price": 63285.65, "quantity": 0.0}, {"price": 63285.99, "quantity": 0.0}, {"price": 63286.0, "quantity": 0.0}, {"price": 63286.12, "quantity": 0.0}, {"price": 63286.13, "quantity": 0.0}, {"price": 63286.4, "quantity": 0.0}, {"price": 63286.59, "quantity": 0.0}, {"price": 63286.76, "quantity": 0.0}, {"price": 63286.79, "quantity": 0.0}, {"price": 63286.8, "quantity": 0.0}, {"price": 63286.97, "quantity": 0.0}, {"price": 63286.98, "quantity": 0.0}, {"price": 63287.39, "quantity": 0.0}, {"price": 63287.4, "quantity": 0.0}, {"price": 63287.54, "quantity": 0.0}, {"price": 63287.86, "quantity": 0.0}, {"price": 63297.5, "quantity": 0.0}, {"price": 63297.51, "quantity": 0.0}, {"price": 63298.94, "quantity": 0.86882}, {"price": 63298.95, "quantity": 0.0017}, {"price": 63298.96, "quantity": 0.00064}, {"price": 63299.11, "quantity": 0.00032}, {"price": 63299.2, "quantity": 0.00032}, {"price": 63299.99, "quantity": 0.00072}, {"price": 63300.0, "quantity": 0.12836}, {"price": 63300.13, "quantity": 0.00072}, {"price": 63300.14, "quantity": 0.08956}, {"price": 63300.51, "quantity": 0.00032}, {"price": 63300.55, "quantity": 0.00036}, {"price": 63300.75, "quantity": 0.00036}, {"price": 63300.76, "quantity": 0.3057}, {"price": 63300.85, "quantity": 0.00072}, {"price": 63300.86, "quantity": 4.00067}, {"price": 63300.94, "quantity": 0.00032}, {"price": 63301.03, "quantity": 0.00032}, {"price": 63301.08, "quantity": 0.00106}, {"price": 63301.09, "quantity": 0.2609}, {"price": 63301.32, "quantity": 0.00032}, {"price": 68347.64, "quantity": 0.0}, {"price": 69613.33, "quantity": 0.0}]}}
{"type": "delta", "data": {"event_type": "depth_update", "exchange": "binance", "symbol": "BTCUSDT", "event_time": 1786680122008, "received_time": 1786680122186, "first_update_id": 4672614, "final_update_id": 4672616, "bids": [{"price": 63298.93, "quantity": 42.96685}, {"price": 59487.77, "quantity": 0.02979}, {"price": 58222.07, "quantity": 0.03044}], "asks": []}}
{"type": "delta", "data": {"event_type": "depth_update", "exchange": "binance", "symbol": "BTCUSDT", "event_time": 1786680123028, "received_time": 1786680123206, "first_update_id": 4672617, "final_update_id": 4672621, "bids": [{"price": 63298.93, "quantity": 42.95104}], "asks": [{"price": 64550.56, "quantity": 0.17539}, {"price": 65816.25, "quantity": 0.17539}, {"price": 67081.95, "quantity": 0.17539}, {"price": 68347.65, "quantity": 0.17539}]}}
{"type": "delta", "data": {"event_type": "depth_update", "exchange": "binance", "symbol": "BTCUSDT", "event_time": 1786680124007, "received_time": 1786680124185, "first_update_id": 4672622, "final_update_id": 4672626, "bids": [{"price": 63298.93, "quantity": 42.95037}], "asks": [{"price": 63601.3, "quantity": 0.0}, {"price": 63615.5, "quantity": 0.003}, {"price": 69613.35, "quantity": 0.17539}]}}
{"type": "delta", "data": {"event_type": "depth_update", "exchange": "binance", "symbol": "BTCUSDT", "event_time": 1786680126010, "received_time": 1786680126189, "first_update_id": 4672627, "final_update_id": 4672630, "bids": [{"price": 63298.93, "quantity": 42.94599}, {"price": 63297.61, "quantity": 0.001}, {"price": 63283.53, "quantity": 0.0}], "asks": [{"price": 63298.94, "quantity": 0.85687}]}}
{"type": "delta", "data": {"event_type": "depth_update", "exchange": "binance", "symbol": "BTCUSDT", "event_time": 1786680127016, "received_time": 1786680127193, "first_update_id": 4672631, "final_update_id": 4672631, "bids": [], "asks": [{"price": 63299.46, "quantity": 0.001}]}}
{"type": "delta", "data": {"event_type": "depth_update", "exchange": "binance", "symbol": "BTCUSDT", "event_time": 1786680128027, "received_time": 1786680128205, "first_update_id": 4672632, "final_update_id": 4672633, "bids": [{"price": 63244.36, "quantity": 0.0}], "asks": [{"price": 63307.65, "quantity": 0.0}]}}
{"type": "delta", "data": {"event_type": "depth_update", "exchange": "binance", "symbol": "BTCUSDT", "event_time": 1786680129020, "received_time": 1786680129202, "first_update_id": 4672634, "final_update_id": 4672635, "bids": [{"price": 63267.28, "quantity": 0.00316}], "asks": [{"price": 63330.59, "quantity": 0.00315}]}}
{"type": "delta", "data": {"event_type": "depth_update", "exchange": "binance", "symbol": "BTCUSDT", "event_time": 1786680130006, "received_time": 1786680130275, "first_update_id": 4672636, "final_update_id": 4672637, "bids": [], "asks": [{"price": 63298.94, "quantity": 0.85487}]}}
{"type": "delta", "data": {"event_type": "depth_update", "exchange": "binance", "symbol": "BTCUSDT", "event_time": 1786680131009, "received_time": 1786680131213, "first_update_id": 4672638, "final_update_id": 4672689, "bids": [{"price": 63298.93, "quantity": 42.94599}, {"price": 63298.92, "quantity": 0.00036}], "asks": [{"price": 63298.94, "quantity": 0.85287}]}}
{"type": "delta", "data": {"event_type": "depth_update", "exchange": "binance", "symbol": "BTCUSDT", "event_time": 1786680132009, "received_time": 1786680132354, "first_update_id": 4672690, "final_update_id": 4672690, "bids": [], "asks": [{"price": 63298.94, "quantity": 0.85187}]}}
{"type": "delta", "data": {"event_type": "depth_update", "exchange": "binance", "symbol": "BTCUSDT", "event_time": 1786680137009, "received_time": 1786680137190, "first_update_id": 4672691, "final_update_id": 4672694, "bids": [{"price": 63298.93, "quantity": 42.94521}, {"price": 63297.61, "quantity": 0.001}], "asks": [{"price": 63299.46, "quantity": 0.0}]}}
{"type": "delta", "data": {"event_type": "depth_update", "exchange": "binance", "symbol": "BTCUSDT", "event_time": 1786680138046, "received_time": 1786680138308, "first_update_id": 4672695, "final_update_id": 4672730, "bids": [{"price": 63300.85, "quantity": 44.03079}, {"price": 63300.84, "quantity": 0.00136}, {"price": 63300.83, "quantity": 0.00064}, {"price": 63300.81, "quantity": 0.00072}, {"price": 63300.8, "quantity": 0.06183}, {"price": 63300.76, "quantity": 0.00036}, {"price": 63300.75, "quantity": 0.37988}, {"price": 63300.14, "quantity": 0.00103}, {"price": 63300.13, "quantity": 3.33992}, {"price": 63300.01, "quantity": 0.00072}, {"price": 63300.0, "quantity": 0.61738}, {"price": 63299.99, "quantity": 2.64752}, {"price": 63299.58, "quantity": 0.1529}, {"price": 63299.49, "quantity": 0.016}, {"price": 63299.29, "quantity": 0.00036}, {"price": 63299.2, "quantity": 0.00064}, {"price": 63298.95, "quantity": 1.88023}, {"price": 63298.94, "quantity": 4.70408}, {"price": 63298.92, "quantity": 0.00011}, {"price": 63298.91, "quantity": 0.0}, {"price": 63298.9, "quantity": 0.0}, {"price": 63298.88, "quantity": 0.0}, {"price": 63298.86, "quantity": 0.0}, {"price": 63298.85, "quantity": 0.0}, {"price": 63298.75, "quantity": 0.0}, {"price": 63298.58, "quantity": 0.0}, {"price": 63298.12, "quantity": 0.0}, {"price": 63298.01, "quantity": 0.0}, {"price": 63298.0, "quantity": 0.0}, {"price": 63297.99, "quantity": 0.0}, {"price": 63297.98, "quantity": 0.0}, {"price": 63297.91, "quantity": 0.0}, {"price": 63297.9, "quantity": 0.0}, {"price": 63297.89, "quantity": 0.0}, {"price": 63297.58, "quantity": 0.0}, {"price": 63297.35, "quantity": 0.0}], "asks": [{"price": 63298.94, "quantity": 0.0}, {"price": 63298.95, "quantity": 0.0}, {"price": 63298.96, "quantity": 0.0}, {"price": 63299.11, "quantity": 0.0}, {"price": 63299.2, "quantity": 0.0}, {"price": 63299.99, "quantity": 0.0}, {"price": 63300.0, "quantity": 0.0}, {"price": 63300.13, "quantity": 0.0}, {"price": 63300.14, "quantity": 0.0}, {"price": 63300.51, "quantity": 0.0}, {"price": 63300.55, "quantity": 0.0}, {"price": 63300.75, "quantity": 0.0}, {"price": 63300.76, "quantity": 0.0}, {"price": 63300.85, "quantity": 0.0}, {"price": 63300.87, "quantity": 0.00242}, {"price": 63300.88, "quantity": 0.00064}, {"price": 63300.94, "quantity": 0.0}, {"price": 63301.03, "quantity": 0.0}, {"price": 63301.32, "quantity": 0.0}, {"price": 63301.99, "quantity": 0.00072}, {"price": 63302.0, "quantity": 0.08799}, {"price": 63302.16, "quantity": 0.00072}, {"price": 63302.17, "quantity": 0.08808}, {"price": 63302.31, "quantity": 0.00128}, {"price": 63302.4, "quantity": 0.00068}, {"price": 63302.45, "quantity": 0.00036}, {"price": 63303.0, "quantity": 0.00072}, {"price": 63303.01, "quantity": 0.26056}, {"price": 63303.43, "quantity": 0.00072}, {"price": 63303.44, "quantity": 0.13211}, {"price": 63303.94, "quantity": 0.00096}, {"price": 63303.99, "quantity": 0.00036}, {"price": 63304.0, "quantity": 0.08799}, {"price": 63304.26, "quantity": 0.00036}]}}
{"type": "delta", "data": {"event_type": "depth_update", "exchange": "binance", "symbol": "BTCUSDT", "event_time": 1786680139024, "received_time": 1786680139417, "first_update_id": 4672731, "final_update_id": 4672731, "bids": [], "asks": [{"price": 63615.5, "quantity": 0.0}]}}
{"type": "delta", "data": {"event_type": "depth_update", "exchange": "binance", "symbol": "BTCUSDT", "event_time": 1786680143015, "received_time": 1786680143272, "first_update_id": 4672732, "final_update_id": 4672782, "bids": [{"price": 63300.85, "quantity": 44.03079}, {"price": 63300.84, "quantity": 0.00147}, {"price": 63298.92, "quantity": 0.0}], "asks": [{"price": 66465.9, "quantity": 0.002}]}}
{"type": "delta", "data": {"event_type": "depth_update", "exchange": "binance", "symbol": "BTCUSDT", "event_time": 1786680144020, "received_time": 1786680144200, "first_update_id": 4672783, "final_update_id": 4672785, "bids": [{"price": 63300.85, "quantity": 44.0298}], "asks": [{"price": 63300.86, "quantity": 3.98386}]}}
{"type": "delta", "data": {"event_type": "depth_update", "exchange": "binance", "symbol": "BTCUSDT", "event_time": 1786680145011, "received_time": 1786680145205, "first_update_id": 4672786, "final_update_id": 4672791, "bids": [{"price": 44310.6, "quantity": 0.00017}], "asks": [{"price": 63300.86, "quantity": 3.96079}, {"price": 63677.86, "quantity": 0.0}, {"price": 63688.22, "quantity": 0.0}]}}
{"type": "delta", "data": {"event_type": "depth_update", "exchange": "binance", "symbol": "BTCUSDT", "event_time": 1786680146010, "received_time": 1786680146191, "first_update_id": 4672792, "final_update_id": 4672796, "bids": [{"price": 63293.84, "quantity": 0.01391}, {"price": 44310.6, "quantity": 0.0}], "asks": [{"price": 63300.86, "quantity": 3.95779}]}}
{"type": "delta", "data": {"event_type": "depth_update", "exchange": "binance", "symbol": "BTCUSDT", "event_time": 1786680147004, "received_time": 1786680147183, "first_update_id": 4672797, "final_update_id": 4672799, "bids": [], "asks": [{"price": 63300.86, "quantity": 3.95581}, {"price": 63693.7, "quantity": 0.01383}]}}
{"type": "delta", "data": {"event_type": "depth_update", "exchange": "binance", "symbol": "BTCUSDT", "event_time": 1786680148003, "received_time": 1786680148182, "first_update_id": 4672800, "final_update_id": 4672802, "bids": [{"price": 63299.53, "quantity": 0.001}, {"price": 63297.61, "quantity": 0.0}], "asks": [{"price": 63301.38, "quantity": 0.001}]}}
{"type": "delta", "data": {"event_type": "depth_update", "exchange": "binance", "symbol": "BTCUSDT", "event_time": 1786680154070, "received_time": 1786680154252, "first_update_id": 4672803, "final_update_id": 4672898, "bids": [{"price": 63329.99, "quantity": 50.80747}, {"price": 63329.98, "quantity": 0.0}, {"price": 63329.97, "quantity": 0.00015}, {"price": 63329.95, "quantity": 0.20175}, {"price": 63329.94, "quantity": 0.05616}, {"price": 63329.93, "quantity": 0.15751}, {"price": 63329.91, "quantity": 0.00072}, {"price": 63329.9, "quantity": 0.20102}, {"price": 63329.71, "quantity": 0.05059}, {"price": 63329.18, "quantity": 0.00072}, {"price": 63329.17, "quantity": 3.90386}, {"price": 63329.16, "quantity": 5.63884}, {"price": 63329.15, "quantity": 11.2514}, {"price": 63329.05, "quantity": 0.00888}, {"price": 63328.72, "quantity": 0.17727}, {"price": 63328.47, "quantity": 0.00036}, {"price": 63328.07, "quantity": 0.016}, {"price": 63328.01, "quantity": 0.00032}, {"price": 63328.0, "quantity": 0.93164}, {"price": 63300.85, "quantity": 0.0}, {"price": 63300.84, "quantity": 0.0}, {"price": 63300.83, "quantity": 0.0}, {"price": 63300.81, "quantity": 0.0}, {"price": 63300.8, "quantity": 0.0}, {"price": 63300.76, "quantity": 0.0}, {"price": 63300.75, "quantity": 0.0}, {"price": 63300.14, "quantity": 0.0}, {"price": 63300.13, "quantity": 0.0}, {"price": 63300.01, "quantity": 0.0}, {"price": 63300.0, "quantity": 0.0}, {"price": 63299.99, "quantity": 0.0}, {"price": 63299.58, "quantity": 0.0}, {"price": 63299.49, "quantity": 0.0}, {"price": 63299.29, "quantity": 0.0}, {"price": 63299.2, "quantity": 0.0}, {"price": 63298.95, "quantity": 0.0}, {"price": 63298.94, "quantity": 0.0}, {"price": 63298.93, "quantity": 0.0}, {"price": 63298.79, "quantity": 0.0}, {"price": 63218.95, "quantity": 8e-05}, {"price": 63165.07, "quantity": 0.0}, {"price": 44310.6, "quantity": 0.0}], "asks": [{"price": 63300.86, "quantity": 0.0}, {"price": 63300.87, "quantity": 0.0}, {"price": 63300.88, "quantity": 0.0}, {"price": 63301.08, "quantity": 0.0}, {"price": 63301.09, "quantity": 0.0}, {"price": 63301.38, "quantity": 0.0}, {"price": 63301.99, "quantity": 0.0}, {"price": 63302.0, "quantity": 0.0}, {"price": 63302.16, "quantity": 0.0}, {"price": 63302.17, "quantity": 0.0}, {"price": 63302.31, "quantity": 0.0}, {"price": 63302.4, "quantity": 0.0}, {"price": 63302.45, "quantity": 0.0}, {"price": 63303.0, "quantity": 0.0}, {"price": 63303.01, "quantity": 0.0}, {"price": 63303.43, "quantity": 0.0}, {"price": 63303.44, "quantity": 0.0}, {"price": 63303.94, "quantity": 0.0}, {"price": 63303.99, "quantity": 0.0}, {"price": 63304.0, "quantity": 0.0}, {"price": 63304.26, "quantity": 0.0}, {"price": 63326.99, "quantity": 0.0}, {"price": 63330.0, "quantity": 0.63094}, {"price": 63330.01, "quantity": 0.00242}, {"price": 63330.02, "quantity": 0.00064}, {"price": 63330.19, "quantity": 0.00032}, {"price": 63330.37, "quantity": 0.00036}, {"price": 63331.2, "quantity": 0.00032}, {"price": 63331.33, "quantity": 0.00032}, {"price": 63331.99, "quantity": 0.00072}, {"price": 63332.0, "quantity": 0.08799}, {"price": 63332.18, "quantity": 0.00072}, {"price": 63332.19, "quantity": 0.256}, {"price": 63332.27, "quantity": 0.00036}, {"price": 63332.88, "quantity": 0.00036}, {"price": 63332.98, "quantity": 0.00072}, {"price": 63332.99, "quantity": 0.07194}, {"price": 63333.0, "quantity": 0.14152}, {"price": 63333.36, "quantity": 0.00032}, {"price": 63333.54, "quantity": 0.00944}, {"price": 63333.91, "quantity": 0.00032}, {"price": 63333.94, "quantity": 0.00092}, {"price": 63354.9, "quantity": 0.0}, {"price": 63408.94, "quantity": 8e-05}]}}
{"type": "delta", "data": {"event_type": "depth_update", "exchange": "binance", "symbol": "BTCUSDT", "event_time": 1786680155031, "received_time": 1786680155213, "first_update_id": 4672899, "final_update_id": 4672900, "bids": [{"price": 63329.99, "quantity": 50.80701}], "asks": []}}
{"type": "delta", "data": {"event_type": "depth_update", "exchange": "binance", "symbol": "BTCUSDT", "event_time": 1786680157015, "received_time": 1786680157194, "first_update_id": 4672901, "final_update_id": 4672903, "bids": [{"price": 62019.16, "quantity": 0.00316}, {"price": 56956.37, "quantity": 0.0}], "asks": [{"price": 63330.0, "quantity": 0.63044}]}}
{"type": "delta", "data": {"event_type": "depth_update", "exchange": "binance", "symbol": "BTCUSDT", "event_time": 1786680158017, "received_time": 1786680158208, "first_update_id": 4672904, "final_update_id": 4672906, "bids": [{"price": 60753.47, "quantity": 0.0}, {"price": 59487.77, "quantity": 0.0}, {"price": 58222.07, "quantity": 0.0}], "asks": []}}
{"type": "delta", "data": {"event_type": "depth_update", "exchange": "binance", "symbol": "BTCUSDT", "event_time": 1786680159003, "received_time": 1786680159181, "first_update_id": 4672907, "final_update_id": 4672918, "bids": [{"price": 63328.67, "quantity": 0.001}, {"price": 63299.53, "quantity": 0.0}], "asks": [{"price": 63330.0, "quantity": 0.62944}, {"price": 63330.52, "quantity": 0.001}, {"price": 63617.4, "quantity": 0.0}, {"price": 63619.2, "quantity": 0.0}, {"price": 63626.6, "quantity": 0.0}, {"price": 63636.9, "quantity": 0.0027}, {"price": 63646.7, "quantity": 0.003}, {"price": 64550.56, "quantity": 0.0}, {"price": 65816.25, "quantity": 0.0}, {"price": 67081.95, "quantity": 0.0}]}}
{"type": "delta", "data": {"event_type": "depth_update", "exchange": "binance", "symbol": "BTCUSDT", "event_time": 1786680160003, "received_time": 1786680160182, "first_update_id": 4672919, "final_update_id": 4672925, "bids": [{"price": 62063.39, "quantity": 0.02855}], "asks": [{"price": 63330.0, "quantity": 0.62744}, {"price": 63375.74, "quantity": 0.0}, {"price": 63412.73, "quantity": 0.00078}, {"price": 68347.65, "quantity": 0.0}, {"price": 69613.35, "quantity": 0.0}]}}
{"type": "delta", "data": {"event_type": "depth_update", "exchange": "binance", "symbol": "BTCUSDT", "event_time": 1786680161010, "received_time": 1786680161190, "first_update_id": 4672926, "final_update_id": 4672979, "bids": [{"price": 63329.99, "quantity": 50.80701}, {"price": 63329.98, "quantity": 0.0}, {"price": 60796.79, "quantity": 0.02915}, {"price": 59530.19, "quantity": 0.02977}], "asks": [{"price": 63330.0, "quantity": 0.62544}]}}
{"type": "delta", "data": {"event_type": "depth_update", "exchange": "binance", "symbol": "BTCUSDT", "event_time": 1786680162012, "received_time": 1786680162192, "first_update_id": 4672980, "final_update_id": 4672983, "bids": [{"price": 58263.59, "quantity": 0.03041}, {"price": 56996.99, "quantity": 0.03109}], "asks": [{"price": 64596.59, "quantity": 0.17539}, {"price": 65863.19, "quantity": 0.17539}]}}
{"type": "delta", "data": {"event_type": "depth_update", "exchange": "binance", "symbol": "BTCUSDT", "event_time": 1786680163008, "received_time": 1786680163191, "first_update_id": 4672984, "final_update_id": 4672987, "bids": [{"price": 63295.32, "quantity": 0.00157}], "asks": [{"price": 63330.0, "quantity": 0.62444}, {"price": 67129.79, "quantity": 0.17539}, {"price": 68396.39, "quantity": 0.17539}]}}
{"type": "snapshot", "data": {"event_type": "depth_snapshot", "exchange": "binance", "symbol": "BTCUSDT", "event_time": 1786680202013, "received_time": 1786680202207, "last_update_id": 4673301, "bids": [{"price": 63341.99, "quantity": 28.83837}, {"price": 63341.98, "quantity": 4.741}, {"price": 63341.97, "quantity": 0.00064}, {"price": 63341.95, "quantity": 0.20102}, {"price": 63341.94, "quantity": 0.04991}, {"price": 63341.9, "quantity": 0.20136}, {"price": 63341.78, "quantity": 0.00072}, {"price": 63341.77, "quantity": 0.8396}, {"price": 63341.76, "quantity": 1.56519}, {"price": 63341.73, "quantity": 0.0088}, {"price": 63341.16, "quantity": 0.00036}, {"price": 63340.81, "quantity": 0.03232}, {"price": 63340.8, "quantity": 0.00064}, {"price": 63340.73, "quantity": 0.00072}, {"price": 63340.72, "quantity": 0.18736}, {"price": 63340.67, "quantity": 0.001}, {"price": 63340.53, "quantity": 0.00036}, {"price": 63340.45, "quantity": 0.00898}, {"price": 63340.0, "quantity": 0.96418}, {"price": 63339.99, "quantity": 0.99355}, {"price": 63339.98, "quantity": 0.00032}, {"price": 63310.32, "quantity": 0.00315}, {"price": 63295.32, "quantity": 0.00157}, {"price": 63293.84, "quantity": 0.01391}, {"price": 63275.13, "quantity": 0.00031}, {"price": 63263.64, "quantity": 0.00158}, {"price": 63262.45, "quantity": 0.00526}, {"price": 63258.31, "quantity": 0.00031}, {"price": 63250.74, "quantity": 0.00735}, {"price": 63250.0, "quantity": 0.00158}, {"price": 63247.22, "quantity": 0.00048}, {"price": 63246.69, "quantity": 9e-05}, {"price": 63231.96, "quantity": 0.00158}, {"price": 63227.69, "quantity": 0.00079}, {"price": 63222.51, "quantity": 0.00031}, {"price": 63218.95, "quantity": 8e-05}, {"price": 63216.82, "quantity": 0.00158}, {"price": 63210.03, "quantity": 0.00048}, {"price": 63200.28, "quantity": 0.00158}, {"price": 63200.0, "quantity": 0.00086}, {"price": 63190.0, "quantity": 0.00025}, {"price": 63187.76, "quantity": 0.00798}, {"price": 63175.92, "quantity": 9e-05}, {"price": 63167.43, "quantity": 0.00166}, {"price": 63163.24, "quantity": 0.00162}, {"price": 63159.52, "quantity": 0.01424}, {"price": 63156.63, "quantity": 0.00158}, {"price": 63151.43, "quantity": 0.00026}, {"price": 63122.57, "quantity": 0.00047}, {"price": 63104.69, "quantity": 0.00528}, {"price": 63102.88, "quantity": 0.00079}, {"price": 63095.06, "quantity": 0.00036}, {"price": 63094.14, "quantity": 0.00795}, {"price": 63091.91, "quantity": 0.00466}, {"price": 63073.3, "quantity": 0.00525}, {"price": 63061.79, "quantity": 0.00039}, {"price": 63058.38, "quantity": 0.00158}, {"price": 63050.0, "quantity": 0.00495}, {"price": 63037.44, "quantity": 0.00079}, {"price": 63018.62, "quantity": 0.00095}, {"price": 63014.04, "quantity": 0.0027}, {"price": 63004.94, "quantity": 0.00162}, {"price": 63004.44, "quantity": 0.00255}, {"price": 63000.0, "quantity": 0.00205}, {"price": 62997.95, "quantity": 0.00158}, {"price": 62994.19, "quantity": 0.00238}, {"price": 62994.16, "quantity": 0.00047}, {"price": 62994.12, "quantity": 0.00011}, {"price": 62979.06, "quantity": 0.0027}, {"price": 62970.08, "quantity": 0.00047}, {"price": 62958.88, "quantity": 0.00047}, {"price": 62957.21, "quantity": 0.00127}, {"price": 62956.67, "quantity": 0.00024}, {"price": 62947.32, "quantity": 0.00529}, {"price": 62900.0, "quantity": 0.00078}, {"price": 62899.95, "quantity": 0.00158}, {"price": 62892.94, "quantity": 0.00127}, {"price": 62875.25, "quantity": 9e-05}, {"price": 62870.24, "quantity": 0.00802}, {"price": 62852.3, "quantity": 0.002}, {"price": 62846.63, "quantity": 0.00163}, {"price": 62839.26, "quantity": 0.00159}, {"price": 62838.81, "quantity": 0.00054}, {"price": 62833.33, "quantity": 0.0001}, {"price": 62829.81, "quantity": 0.01405}, {"price": 62828.66, "quantity": 0.00127}, {"price": 62827.65, "quantity": 0.00108}, {"price": 62824.06, "quantity": 0.00013}, {"price": 62822.3, "quantity": 0.001}, {"price": 62813.9, "quantity": 0.003}, {"price": 62805.88, "quantity": 0.00084}, {"price": 62800.0, "quantity": 0.00086}, {"price": 62790.35, "quantity": 0.0053}, {"price": 62789.38, "quantity": 0.00026}, {"price": 62782.82, "quantity": 0.01433}, {"price": 62774.57, "quantity": 0.00037}, {"price": 62764.39, "quantity": 0.00127}, {"price": 62761.13, "quantity": 0.0019}, {"price": 62748.76, "quantity": 9e-05}, {"price": 62741.51, "quantity": 0.00159}, {"price": 62736.67, "quantity": 0.07969}, {"price": 62705.12, "quantity": 0.00079}, {"price": 62700.11, "quantity": 0.00127}, {"price": 62690.91, "quantity": 0.00039}, {"price": 62688.33, "quantity": 0.00163}, {"price": 62680.58, "quantity": 0.00159}, {"price": 62677.63, "quantity": 0.00466}, {"price": 62676.9, "quantity": 0.00031}, {"price": 62674.81, "quantity": 0.00175}, {"price": 62655.86, "quantity": 0.00104}, {"price": 62635.84, "quantity": 0.00127}, {"price": 62632.4, "quantity": 0.00095}, {"price": 62600.0, "quantity": 0.00047}, {"price": 62583.07, "quantity": 0.00159}, {"price": 62574.58, "quantity": 9e-05}, {"price": 62571.57, "quantity": 0.00127}, {"price": 62565.9, "quantity": 0.00934}, {"price": 62552.71, "quantity": 0.00806}, {"price": 62530.03, "quantity": 0.00163}, {"price": 62521.89, "quantity": 0.0016}, {"price": 62507.29, "quantity": 0.00127}, {"price": 62454.08, "quantity": 0.00037}, {"price": 62444.33, "quantity": 0.00084}, {"price": 62443.02, "quantity": 0.00128}, {"price": 62439.29, "quantity": 0.00256}, {"price": 62427.33, "quantity": 0.00026}, {"price": 62424.63, "quantity": 0.0016}, {"price": 62408.37, "quantity": 0.01442}, {"price": 62400.0, "quantity": 0.00088}, {"price": 62378.74, "quantity": 0.00128}, {"price": 62374.18, "quantity": 0.0004}, {"price": 62371.72, "quantity": 0.00164}, {"price": 62338.45, "quantity": 0.00011}, {"price": 62322.21, "quantity": 0.0004}, {"price": 62314.47, "quantity": 0.00128}, {"price": 62309.86, "quantity": 0.0008}, {"price": 62273.91, "quantity": 0.0001}, {"price": 62266.19, "quantity": 0.0016}, {"price": 62263.35, "quantity": 0.00466}, {"price": 62253.69, "quantity": 0.001}, {"price": 62250.19, "quantity": 0.00128}, {"price": 62246.18, "quantity": 0.00096}, {"price": 62235.18, "quantity": 0.0081}, {"price": 62213.42, "quantity": 0.00164}, {"price": 62200.0, "quantity": 0.00048}, {"price": 62185.92, "quantity": 0.00128}, {"price": 62121.64, "quantity": 0.00128}, {"price": 62117.43, "quantity": 0.00096}, {"price": 62107.75, "quantity": 0.00161}, {"price": 62082.78, "quantity": 0.00085}, {"price": 62075.16, "quantity": 0.02855}, {"price": 62057.37, "quantity": 0.00128}, {"price": 62055.11, "quantity": 0.00165}, {"price": 62043.8, "quantity": 0.00031}, {"price": 62036.15, "quantity": 0.0145}, {"price": 62027.78, "quantity": 0.02838}, {"price": 62027.77, "quantity": 0.00337}, {"price": 62014.34, "quantity": 0.00134}, {"price": 62000.0, "quantity": 0.00088}, {"price": 61993.09, "quantity": 0.00129}, {"price": 61973.24, "quantity": 0.0001}, {"price": 61955.68, "quantity": 0.0004}, {"price": 61949.32, "quantity": 0.00161}, {"price": 61928.82, "quantity": 0.00129}, {"price": 61917.1, "quantity": 0.0008}, {"price": 61905.11, "quantity": 0.00094}, {"price": 61896.81, "quantity": 0.00165}, {"price": 61893.3, "quantity": 9e-05}, {"price": 61864.54, "quantity": 0.00129}, {"price": 61859.95, "quantity": 0.00096}, {"price": 61849.08, "quantity": 0.00466}, {"price": 61800.27, "quantity": 0.00129}, {"price": 61790.88, "quantity": 0.00161}, {"price": 61768.2, "quantity": 0.00014}, {"price": 61751.8, "quantity": 0.002}, {"price": 61750.9, "quantity": 0.0004}, {"price": 61738.51, "quantity": 0.00166}, {"price": 61735.99, "quantity": 0.00129}, {"price": 61721.23, "quantity": 0.00085}, {"price": 61703.24, "quantity": 0.00026}, {"price": 61703.23, "quantity": 0.00027}, {"price": 61682.77, "quantity": 0.00011}, {"price": 61671.72, "quantity": 0.00129}, {"price": 61666.67, "quantity": 0.00039}, {"price": 61666.16, "quantity": 0.01459}, {"price": 61629.94, "quantity": 0.00948}, {"price": 61607.44, "quantity": 0.00129}, {"price": 61603.56, "quantity": 0.00031}, {"price": 61600.0, "quantity": 0.0004}, {"price": 61591.31, "quantity": 0.0004}, {"price": 61543.17, "quantity": 0.00129}, {"price": 61526.8, "quantity": 0.00081}, {"price": 61478.89, "quantity": 0.0013}, {"price": 61473.73, "quantity": 0.00227}, {"price": 61473.72, "quantity": 0.00194}, {"price": 61455.18, "quantity": 0.001}, {"price": 61434.8, "quantity": 0.00466}, {"price": 61415.46, "quantity": 0.00138}, {"price": 61414.62, "quantity": 0.0013}, {"price": 61410.7, "quantity": 0.00031}, {"price": 61355.31, "quantity": 0.00464}, {"price": 61350.34, "quantity": 0.0013}, {"price": 61318.89, "quantity": 0.04423}, {"price": 61298.37, "quantity": 0.01468}, {"price": 61286.07, "quantity": 0.0013}, {"price": 61229.08, "quantity": 0.0004}, {"price": 61221.79, "quantity": 0.0013}, {"price": 61202.31, "quantity": 0.00465}, {"price": 61201.92, "quantity": 0.00465}, {"price": 61200.0, "quantity": 0.0004}, {"price": 61166.67, "quantity": 0.0001}, {"price": 61157.52, "quantity": 0.0013}, {"price": 61147.9, "quantity": 0.001}, {"price": 61142.63, "quantity": 0.001}, {"price": 61138.97, "quantity": 0.00081}, {"price": 61133.84, "quantity": 0.0004}, {"price": 61127.33, "quantity": 0.00014}, {"price": 61106.72, "quantity": 0.00098}, {"price": 61103.39, "quantity": 0.00036}, {"price": 61099.0, "quantity": 0.00016}, {"price": 61093.24, "quantity": 0.0013}, {"price": 61049.51, "quantity": 9e-05}, {"price": 61048.92, "quantity": 0.00466}, {"price": 61038.73, "quantity": 0.00049}, {"price": 61028.97, "quantity": 0.00131}, {"price": 61027.1, "quantity": 0.00011}, {"price": 61020.52, "quantity": 0.00466}, {"price": 61000.0, "quantity": 0.00032}, {"price": 60996.11, "quantity": 0.00081}, {"price": 60979.14, "quantity": 0.00027}, {"price": 60971.35, "quantity": 0.00109}, {"price": 60967.67, "quantity": 0.00016}, {"price": 60964.69, "quantity": 0.00131}, {"price": 60932.77, "quantity": 0.01477}, {"price": 60907.89, "quantity": 0.00976}, {"price": 60900.42, "quantity": 0.00131}, {"price": 60896.3, "quantity": 0.00468}, {"price": 60868.98, "quantity": 0.00041}, {"price": 60842.16, "quantity": 0.001}, {"price": 60836.14, "quantity": 0.00131}, {"price": 60833.33, "quantity": 0.00132}, {"price": 60833.28, "quantity": 0.00788}, {"price": 60830.02, "quantity": 0.00098}, {"price": 60808.32, "quantity": 0.02914}, {"price": 60800.0, "quantity": 0.00041}, {"price": 60777.6, "quantity": 0.00031}, {"price": 60771.87, "quantity": 0.00131}, {"price": 60753.59, "quantity": 0.00082}, {"price": 60744.05, "quantity": 0.00469}, {"price": 60707.98, "quantity": 0.00963}, {"price": 60707.59, "quantity": 0.00131}, {"price": 60643.32, "quantity": 0.00131}, {"price": 60631.51, "quantity": 0.002}, {"price": 60617.09, "quantity": 0.00027}, {"price": 60610.0, "quantity": 0.08249}, {"price": 60606.24, "quantity": 0.00466}, {"price": 60588.39, "quantity": 0.00036}, {"price": 60579.04, "quantity": 0.00132}, {"price": 60569.35, "quantity": 0.01485}, {"price": 60537.95, "quantity": 0.001}, {"price": 60530.68, "quantity": 0.00137}, {"price": 60522.95, "quantity": 0.00041}, {"price": 60514.77, "quantity": 0.00132}, {"price": 60511.0, "quantity": 0.00041}, {"price": 60508.17, "quantity": 0.00132}, {"price": 60470.47, "quantity": 0.01488}, {"price": 60462.55, "quantity": 0.00016}, {"price": 60450.5, "quantity": 0.00132}, {"price": 60400.0, "quantity": 0.00041}, {"price": 60371.43, "quantity": 0.00011}, {"price": 60370.63, "quantity": 0.00082}, {"price": 60317.99, "quantity": 0.00076}, {"price": 60313.13, "quantity": 0.00098}, {"price": 60255.04, "quantity": 0.00027}, {"price": 60235.26, "quantity": 0.001}, {"price": 60217.22, "quantity": 9e-05}, {"price": 60208.11, "quantity": 0.01494}, {"price": 60191.96, "quantity": 0.00466}, {"price": 60186.31, "quantity": 0.00099}, {"price": 60155.12, "quantity": 0.00041}, {"price": 60144.5, "quantity": 0.00031}, {"price": 60100.46, "quantity": 0.00067}, {"price": 60077.73, "quantity": 0.00036}, {"price": 60071.51, "quantity": 0.00074}, {"price": 60059.48, "quantity": 0.00074}, {"price": 60058.57, "quantity": 0.00074}, {"price": 60031.52, "quantity": 0.001}, {"price": 60000.0, "quantity": 0.0008}, {"price": 59996.5, "quantity": 0.002}, {"price": 59990.09, "quantity": 0.00083}, {"price": 59982.5, "quantity": 0.001}, {"price": 59973.1, "quantity": 0.001}, {"price": 59924.7, "quantity": 0.002}, {"price": 59918.16, "quantity": 0.00041}, {"price": 59910.2, "quantity": 0.003}, {"price": 59908.4, "quantity": 0.002}, {"price": 59893.0, "quantity": 0.00027}, {"price": 59877.99, "quantity": 0.00062}, {"price": 59849.01, "quantity": 0.01503}, {"price": 59812.0, "quantity": 0.003}, {"price": 59802.95, "quantity": 0.00184}, {"price": 59801.34, "quantity": 0.00041}, {"price": 59799.81, "quantity": 0.00977}, {"price": 59780.74, "quantity": 0.00031}, {"price": 59777.68, "quantity": 0.00466}, {"price": 59717.1, "quantity": 0.003}, {"price": 59715.76, "quantity": 0.00012}, {"price": 59712.4, "quantity": 0.004}, {"price": 59611.95, "quantity": 0.00083}, {"price": 59571.37, "quantity": 0.00036}, {"price": 59542.62, "quantity": 0.00134}, {"price": 59542.61, "quantity": 0.001}, {"price": 59500.0, "quantity": 0.00146}, {"price": 59453.02, "quantity": 0.00033}, {"price": 59449.63, "quantity": 0.00042}, {"price": 59431.05, "quantity": 0.03224}, {"price": 59396.28, "quantity": 9e-05}, {"price": 59319.42, "quantity": 0.00042}, {"price": 59217.97, "quantity": 0.00054}, {"price": 59100.0, "quantity": 0.00042}, {"price": 59077.82, "quantity": 0.00086}, {"price": 59069.28, "quantity": 0.00037}, {"price": 59047.03, "quantity": 0.00141}, {"price": 58905.23, "quantity": 0.00992}, {"price": 58793.39, "quantity": 0.00114}, {"price": 58785.06, "quantity": 0.02614}, {"price": 58781.62, "quantity": 0.00114}, {"price": 58780.73, "quantity": 0.00114}, {"price": 58726.66, "quantity": 0.00042}, {"price": 58638.59, "quantity": 0.00034}, {"price": 58586.53, "quantity": 9e-05}, {"price": 58577.06, "quantity": 0.00136}, {"price": 58571.43, "quantity": 0.00037}, {"price": 58348.43, "quantity": 0.00039}, {"price": 58333.33, "quantity": 0.00039}, {"price": 58166.67, "quantity": 0.00136}, {"price": 58139.82, "quantity": 0.00042}, {"price": 58139.07, "quantity": 0.00314}, {"price": 58077.76, "quantity": 0.00037}, {"price": 58037.89, "quantity": 0.01024}, {"price": 57824.17, "quantity": 0.00034}, {"price": 57793.52, "quantity": 0.00088}, {"price": 57787.82, "quantity": 9e-05}, {"price": 57706.68, "quantity": 0.00247}, {"price": 57558.84, "quantity": 0.00043}, {"price": 57515.27, "quantity": 0.00176}, {"price": 57503.75, "quantity": 0.00176}, {"price": 57502.89, "quantity": 0.00176}, {"price": 57491.66, "quantity": 0.00025}, {"price": 57156.01, "quantity": 0.01023}, {"price": 57009.74, "quantity": 0.00035}, {"price": 57000.0, "quantity": 9e-05}, {"price": 56983.68, "quantity": 0.00043}, {"price": 56833.33, "quantity": 0.0014}, {"price": 56666.67, "quantity": 0.00039}, {"price": 56414.26, "quantity": 0.00044}, {"price": 55850.53, "quantity": 0.00044}, {"price": 55500.0, "quantity": 0.00144}, {"price": 55349.57, "quantity": 0.7408}, {"price": 55292.43, "quantity": 0.00045}, {"price": 55278.45, "quantity": 0.00018}, {"price": 55269.44, "quantity": 1.3578}, {"price": 55200.0, "quantity": 0.05471}, {"price": 55167.88, "quantity": 0.01078}, {"price": 55136.35, "quantity": 0.00181}, {"price": 55000.0, "quantity": 0.00827}, {"price": 54993.96, "quantity": 0.00018}, {"price": 54786.95, "quantity": 0.01641}, {"price": 54739.91, "quantity": 0.00045}, {"price": 54710.93, "quantity": 0.00018}, {"price": 54429.36, "quantity": 0.00018}, {"price": 54421.76, "quantity": 0.0002}, {"price": 54291.84, "quantity": 0.0002}, {"price": 54207.9, "quantity": 0.0002}, {"price": 54192.91, "quantity": 0.00046}, {"price": 54149.23, "quantity": 0.00018}, {"price": 54000.0, "quantity": 0.00768}, {"price": 53870.55, "quantity": 0.00018}, {"price": 53651.38, "quantity": 0.00046}, {"price": 53597.61, "quantity": 0.01294}, {"price": 53593.3, "quantity": 0.00018}, {"price": 53317.48, "quantity": 0.00018}, {"price": 53115.26, "quantity": 0.00047}, {"price": 53043.08, "quantity": 0.00018}, {"price": 53000.0, "quantity": 0.01768}, {"price": 52996.63, "quantity": 0.01697}, {"price": 52770.09, "quantity": 0.00018}, {"price": 52584.49, "quantity": 0.00047}, {"price": 52498.5, "quantity": 0.00019}, {"price": 52379.53, "quantity": 0.0019}, {"price": 52297.88, "quantity": 0.01137}, {"price": 52228.31, "quantity": 0.00019}, {"price": 52059.03, "quantity": 0.00048}, {"price": 52000.0, "quantity": 0.00768}, {"price": 51959.52, "quantity": 0.00019}, {"price": 51875.22, "quantity": 0.001}, {"price": 51875.21, "quantity": 0.001}, {"price": 51692.11, "quantity": 0.00019}, {"price": 51538.82, "quantity": 0.00048}, {"price": 51426.07, "quantity": 0.00019}, {"price": 51264.81, "quantity": 0.01754}, {"price": 51161.4, "quantity": 0.00019}, {"price": 51023.81, "quantity": 0.00048}, {"price": 51000.0, "quantity": 0.00768}, {"price": 50898.1, "quantity": 0.00019}, {"price": 50813.8, "quantity": 0.00011}, {"price": 50636.14, "quantity": 0.00019}, {"price": 50513.94, "quantity": 0.00049}, {"price": 50500.0, "quantity": 0.0099}, {"price": 50375.54, "quantity": 0.00019}, {"price": 50116.28, "quantity": 0.00019}, {"price": 50009.17, "quantity": 0.00049}, {"price": 50000.0, "quantity": 0.11262}, {"price": 49858.35, "quantity": 0.0002}, {"price": 49760.55, "quantity": 0.002}, {"price": 49601.76, "quantity": 0.0002}, {"price": 49509.45, "quantity": 0.0005}, {"price": 49427.87, "quantity": 0.01203}, {"price": 49346.48, "quantity": 0.0002}, {"price": 49092.51, "quantity": 0.0002}, {"price": 49014.72, "quantity": 0.00051}, {"price": 49000.0, "quantity": 0.13}, {"price": 48839.85, "quantity": 0.0002}, {"price": 48588.5, "quantity": 0.0002}, {"price": 48524.93, "quantity": 0.00051}, {"price": 48338.43, "quantity": 0.0002}, {"price": 48089.66, "quantity": 0.0002}, {"price": 48040.03, "quantity": 0.00052}, {"price": 47559.98, "quantity": 0.00052}, {"price": 47322.0, "quantity": 0.05915}, {"price": 47084.73, "quantity": 0.00053}, {"price": 46726.0, "quantity": 0.02715}, {"price": 46614.23, "quantity": 0.00053}, {"price": 46302.32, "quantity": 0.01294}, {"price": 46148.43, "quantity": 0.00054}, {"price": 45687.28, "quantity": 0.00054}, {"price": 45421.0, "quantity": 0.01856}, {"price": 45309.0, "quantity": 0.01372}, {"price": 45230.74, "quantity": 0.00055}, {"price": 44966.11, "quantity": 0.001}, {"price": 44778.76, "quantity": 0.00055}, {"price": 44582.98, "quantity": 0.00056}, {"price": 44493.4, "quantity": 0.00056}, {"price": 44331.3, "quantity": 0.00056}, {"price": 43888.31, "quantity": 0.00056}, {"price": 43747.0, "quantity": 0.39278}, {"price": 43449.75, "quantity": 0.00057}, {"price": 43015.57, "quantity": 0.00058}, {"price": 42585.73, "quantity": 0.00058}, {"price": 42160.18, "quantity": 0.00059}, {"price": 42026.0, "quantity": 0.41314}, {"price": 41738.89, "quantity": 0.00059}, {"price": 41321.81, "quantity": 0.0006}, {"price": 41010.0, "quantity": 0.00269}, {"price": 40908.89, "quantity": 0.00061}, {"price": 40500.1, "quantity": 0.00061}, {"price": 40095.4, "quantity": 0.00062}, {"price": 40002.0, "quantity": 0.12177}, {"price": 40000.0, "quantity": 0.01294}, {"price": 39694.74, "quantity": 0.00062}, {"price": 39298.08, "quantity": 0.00063}, {"price": 38905.39, "quantity": 0.00064}, {"price": 38516.62, "quantity": 0.00064}, {"price": 38131.73, "quantity": 0.00065}, {"price": 37750.69, "quantity": 0.00066}, {"price": 37373.46, "quantity": 0.00066}, {"price": 37000.0, "quantity": 0.00067}, {"price": 32482.0, "quantity": 0.03466}, {"price": 59541.48, "quantity": 0.02976}, {"price": 58274.64, "quantity": 0.03041}, {"price": 57007.8, "quantity": 0.03108}], "asks": [{"price": 63342.0, "quantity": 4.72414}, {"price": 63342.01, "quantity": 0.0017}, {"price": 63342.02, "quantity": 0.00064}, {"price": 63342.21, "quantity": 0.00064}, {"price": 63342.42, "quantity": 0.00036}, {"price": 63342.52, "quantity": 0.001}, {"price": 63342.76, "quantity": 0.00072}, {"price": 63342.77, "quantity": 0.08523}, {"price": 63343.98, "quantity": 0.00072}, {"price": 63343.99, "quantity": 0.14252}, {"price": 63344.0, "quantity": 0.08831}, {"price": 63344.2, "quantity": 0.00072}, {"price": 63344.21, "quantity": 0.25342}, {"price": 63344.69, "quantity": 0.00336}, {"price": 63344.96, "quantity": 0.00036}, {"price": 63345.52, "quantity": 0.00032}, {"price": 63345.6, "quantity": 0.01634}, {"price": 63345.61, "quantity": 0.00036}, {"price": 63345.62, "quantity": 0.065}, {"price": 63345.93, "quantity": 0.1696}, {"price": 63346.0, "quantity": 0.08799}, {"price": 63358.67, "quantity": 0.00157}, {"price": 63362.44, "quantity": 0.005}, {"price": 63373.67, "quantity": 0.00315}, {"price": 63380.1, "quantity": 0.00031}, {"price": 63389.7, "quantity": 0.00031}, {"price": 63398.97, "quantity": 0.00157}, {"price": 63404.12, "quantity": 0.00031}, {"price": 63408.94, "quantity": 8e-05}, {"price": 63422.79, "quantity": 0.00031}, {"price": 63428.14, "quantity": 0.00031}, {"price": 63430.69, "quantity": 0.00157}, {"price": 63440.73, "quantity": 0.00031}, {"price": 63462.27, "quantity": 0.00031}, {"price": 63464.0, "quantity": 0.00031}, {"price": 63470.38, "quantity": 0.00157}, {"price": 63473.52, "quantity": 0.00031}, {"price": 63477.81, "quantity": 0.00078}, {"price": 63478.3, "quantity": 0.00031}, {"price": 63487.82, "quantity": 0.00031}, {"price": 63488.81, "quantity": 0.00031}, {"price": 63497.52, "quantity": 0.01396}, {"price": 63499.18, "quantity": 0.00014}, {"price": 63502.13, "quantity": 0.00157}, {"price": 63503.7, "quantity": 0.0192}, {"price": 63511.64, "quantity": 0.00031}, {"price": 63516.24, "quantity": 1.08717}, {"price": 63517.97, "quantity": 0.00031}, {"price": 63530.58, "quantity": 0.00031}, {"price": 63537.25, "quantity": 0.00157}, {"price": 63538.02, "quantity": 0.00031}, {"price": 63546.19, "quantity": 0.00031}, {"price": 63569.03, "quantity": 0.00157}, {"price": 63572.64, "quantity": 0.00157}, {"price": 63579.16, "quantity": 0.00525}, {"price": 63585.37, "quantity": 0.00031}, {"price": 63595.47, "quantity": 0.00031}, {"price": 63600.0, "quantity": 0.00491}, {"price": 63608.85, "quantity": 0.0027}, {"price": 63615.76, "quantity": 0.00036}, {"price": 63616.79, "quantity": 0.00031}, {"price": 63617.37, "quantity": 0.0108}, {"price": 63618.82, "quantity": 0.00035}, {"price": 63619.13, "quantity": 0.00031}, {"price": 63619.83, "quantity": 0.00035}, {"price": 63621.33, "quantity": 0.00031}, {"price": 63626.3, "quantity": 0.0027}, {"price": 63627.03, "quantity": 0.00031}, {"price": 63629.71, "quantity": 0.00031}, {"price": 63633.06, "quantity": 0.00036}, {"price": 63636.01, "quantity": 0.00136}, {"price": 63636.08, "quantity": 0.00255}, {"price": 63636.9, "quantity": 0.0027}, {"price": 63637.42, "quantity": 0.00031}, {"price": 63638.53, "quantity": 0.00031}, {"price": 63639.69, "quantity": 0.00039}, {"price": 63640.24, "quantity": 0.00112}, {"price": 63642.91, "quantity": 0.00031}, {"price": 63643.68, "quantity": 0.00036}, {"price": 63644.64, "quantity": 0.015}, {"price": 63645.06, "quantity": 0.00157}, {"price": 63645.58, "quantity": 0.00031}, {"price": 63645.78, "quantity": 0.0027}, {"price": 63649.79, "quantity": 0.00011}, {"price": 63650.01, "quantity": 0.00105}, {"price": 63651.7, "quantity": 0.00126}, {"price": 63653.85, "quantity": 0.00037}, {"price": 63658.8, "quantity": 0.001}, {"price": 63662.73, "quantity": 0.00041}, {"price": 63662.9, "quantity": 0.04965}, {"price": 63663.32, "quantity": 0.00031}, {"price": 63663.94, "quantity": 0.00037}, {"price": 63666.8, "quantity": 0.003}, {"price": 63667.45, "quantity": 0.0067}, {"price": 63668.24, "quantity": 0.00078}, {"price": 63671.1, "quantity": 0.004}, {"price": 63671.19, "quantity": 0.00031}, {"price": 63671.23, "quantity": 0.00038}, {"price": 63676.9, "quantity": 0.00157}, {"price": 63684.63, "quantity": 0.00031}, {"price": 63693.7, "quantity": 0.01383}, {"price": 63694.75, "quantity": 0.00037}, {"price": 63696.75, "quantity": 0.00031}, {"price": 63700.64, "quantity": 0.01093}, {"price": 63703.42, "quantity": 0.00031}, {"price": 63705.63, "quantity": 0.00525}, {"price": 63709.59, "quantity": 0.00037}, {"price": 63709.88, "quantity": 0.00042}, {"price": 63710.31, "quantity": 0.00014}, {"price": 63713.47, "quantity": 0.01107}, {"price": 63716.61, "quantity": 0.00126}, {"price": 63717.63, "quantity": 0.00031}, {"price": 63719.28, "quantity": 0.00037}, {"price": 63720.11, "quantity": 0.00157}, {"price": 63721.7, "quantity": 0.01121}, {"price": 63722.07, "quantity": 0.00031}, {"price": 63725.04, "quantity": 0.01135}, {"price": 63726.68, "quantity": 0.00795}, {"price": 63727.26, "quantity": 0.00037}, {"price": 63727.67, "quantity": 0.00031}, {"price": 63733.79, "quantity": 0.00041}, {"price": 63734.86, "quantity": 0.00916}, {"price": 63735.17, "quantity": 0.00395}, {"price": 63736.05, "quantity": 0.00036}, {"price": 63737.54, "quantity": 0.00015}, {"price": 63738.11, "quantity": 0.00524}, {"price": 63744.81, "quantity": 0.00034}, {"price": 63747.25, "quantity": 0.01039}, {"price": 63750.0, "quantity": 0.00157}, {"price": 63751.99, "quantity": 0.00156}, {"price": 63756.4, "quantity": 0.00594}, {"price": 63758.0, "quantity": 0.00196}, {"price": 63761.94, "quantity": 0.00161}, {"price": 63763.94, "quantity": 0.00297}, {"price": 63764.99, "quantity": 0.00157}, {"price": 63765.09, "quantity": 0.00915}, {"price": 63768.17, "quantity": 0.00156}, {"price": 63768.58, "quantity": 0.14978}, {"price": 63777.04, "quantity": 0.00042}, {"price": 63777.26, "quantity": 0.00018}, {"price": 63779.41, "quantity": 0.141}, {"price": 63781.54, "quantity": 0.00126}, {"price": 63783.55, "quantity": 0.00041}, {"price": 63787.78, "quantity": 0.00156}, {"price": 63790.26, "quantity": 0.00042}, {"price": 63791.07, "quantity": 0.00652}, {"price": 63798.45, "quantity": 0.00078}, {"price": 63800.0, "quantity": 0.00046}, {"price": 63802.32, "quantity": 0.00924}, {"price": 63810.14, "quantity": 0.00039}, {"price": 63819.7, "quantity": 0.00156}, {"price": 63821.51, "quantity": 0.00157}, {"price": 63822.68, "quantity": 0.00027}, {"price": 63822.82, "quantity": 0.00797}, {"price": 63823.94, "quantity": 0.00015}, {"price": 63829.25, "quantity": 0.00196}, {"price": 63829.72, "quantity": 0.00031}, {"price": 63832.4, "quantity": 0.00255}, {"price": 63832.73, "quantity": 0.00031}, {"price": 63833.54, "quantity": 0.00031}, {"price": 63835.68, "quantity": 0.00302}, {"price": 63837.97, "quantity": 0.00932}, {"price": 63840.76, "quantity": 0.00031}, {"price": 63846.45, "quantity": 0.00126}, {"price": 63850.0, "quantity": 0.00314}, {"price": 63850.67, "quantity": 0.00037}, {"price": 63851.63, "quantity": 0.00156}, {"price": 63858.68, "quantity": 0.00078}, {"price": 63863.15, "quantity": 0.00941}, {"price": 63867.22, "quantity": 0.01485}, {"price": 63875.0, "quantity": 0.00489}, {"price": 63875.52, "quantity": 0.00026}, {"price": 63889.15, "quantity": 0.00156}, {"price": 63889.65, "quantity": 0.01686}, {"price": 63890.52, "quantity": 0.00082}, {"price": 63894.72, "quantity": 0.00042}, {"price": 63894.74, "quantity": 0.00717}, {"price": 63897.45, "quantity": 0.00522}, {"price": 63906.01, "quantity": 0.00078}, {"price": 63911.37, "quantity": 0.00126}, {"price": 63919.43, "quantity": 0.00111}, {"price": 63919.72, "quantity": 0.01408}, {"price": 63921.11, "quantity": 0.00156}, {"price": 63921.44, "quantity": 0.00014}, {"price": 63931.19, "quantity": 0.00043}, {"price": 63938.37, "quantity": 0.00969}, {"price": 63948.06, "quantity": 0.00044}, {"price": 63961.68, "quantity": 0.00664}, {"price": 63968.96, "quantity": 0.00043}, {"price": 63976.28, "quantity": 0.00126}, {"price": 63982.92, "quantity": 0.00968}, {"price": 63989.73, "quantity": 0.00698}, {"price": 64000.0, "quantity": 0.00241}, {"price": 64011.32, "quantity": 0.00027}, {"price": 64013.58, "quantity": 0.00043}, {"price": 64015.12, "quantity": 0.00208}, {"price": 64018.01, "quantity": 0.00031}, {"price": 64020.01, "quantity": 0.15}, {"price": 64025.9, "quantity": 0.00977}, {"price": 64035.32, "quantity": 0.0006}, {"price": 64041.21, "quantity": 0.00126}, {"price": 64048.54, "quantity": 0.00188}, {"price": 64049.11, "quantity": 0.00078}, {"price": 64054.63, "quantity": 0.0006}, {"price": 64057.2, "quantity": 0.00521}, {"price": 64063.7, "quantity": 0.00975}, {"price": 64072.02, "quantity": 0.00044}, {"price": 64077.93, "quantity": 9e-05}, {"price": 64106.12, "quantity": 0.00126}, {"price": 64106.81, "quantity": 0.00031}, {"price": 64116.11, "quantity": 0.00984}, {"price": 64125.96, "quantity": 0.00047}, {"price": 64132.57, "quantity": 0.00014}, {"price": 64140.34, "quantity": 0.00797}, {"price": 64149.04, "quantity": 0.00125}, {"price": 64154.44, "quantity": 0.0788}, {"price": 64155.7, "quantity": 0.00157}, {"price": 64157.49, "quantity": 0.00045}, {"price": 64160.17, "quantity": 0.00993}, {"price": 64162.26, "quantity": 0.00014}, {"price": 64168.73, "quantity": 0.00031}, {"price": 64174.77, "quantity": 0.00031}, {"price": 64177.29, "quantity": 0.00094}, {"price": 64187.64, "quantity": 0.00039}, {"price": 64199.96, "quantity": 0.00027}, {"price": 64200.0, "quantity": 0.00046}, {"price": 64205.74, "quantity": 0.01}, {"price": 64209.12, "quantity": 0.02942}, {"price": 64211.66, "quantity": 0.0624}, {"price": 64217.34, "quantity": 0.0052}, {"price": 64235.95, "quantity": 0.00125}, {"price": 64237.52, "quantity": 0.00023}, {"price": 64237.56, "quantity": 0.00025}, {"price": 64252.07, "quantity": 0.00082}, {"price": 64255.46, "quantity": 0.00998}, {"price": 64263.46, "quantity": 0.00028}, {"price": 64279.65, "quantity": 0.05045}, {"price": 64281.1, "quantity": 0.00098}, {"price": 64281.24, "quantity": 0.00015}, {"price": 64282.04, "quantity": 0.00039}, {"price": 64283.3, "quantity": 0.01542}, {"price": 64286.64, "quantity": 0.00034}, {"price": 64292.61, "quantity": 0.00125}, {"price": 64294.03, "quantity": 0.00749}, {"price": 64299.18, "quantity": 0.01007}, {"price": 64299.8, "quantity": 0.00045}, {"price": 64303.23, "quantity": 0.01399}, {"price": 64305.46, "quantity": 0.00011}, {"price": 64311.39, "quantity": 0.00077}, {"price": 64317.44, "quantity": 0.00043}, {"price": 64324.19, "quantity": 0.00043}, {"price": 64334.42, "quantity": 0.0194}, {"price": 64334.75, "quantity": 0.00466}, {"price": 64338.97, "quantity": 0.01016}, {"price": 64339.57, "quantity": 0.00062}, {"price": 64365.82, "quantity": 0.01036}, {"price": 64370.4, "quantity": 0.00378}, {"price": 64378.59, "quantity": 9e-05}, {"price": 64382.55, "quantity": 0.01047}, {"price": 64388.6, "quantity": 0.00027}, {"price": 64400.0, "quantity": 0.00085}, {"price": 64403.24, "quantity": 0.01057}, {"price": 64416.4, "quantity": 0.00053}, {"price": 64419.07, "quantity": 0.00043}, {"price": 64422.95, "quantity": 0.01067}, {"price": 64435.67, "quantity": 0.01067}, {"price": 64443.05, "quantity": 0.00045}, {"price": 64443.25, "quantity": 0.01077}, {"price": 64448.29, "quantity": 0.01087}, {"price": 64449.95, "quantity": 0.00103}, {"price": 64453.34, "quantity": 0.01098}, {"price": 64457.87, "quantity": 0.00797}, {"price": 64460.57, "quantity": 0.01109}, {"price": 64461.6, "quantity": 0.00015}, {"price": 64466.66, "quantity": 0.0001}, {"price": 64467.15, "quantity": 0.0112}, {"price": 64470.29, "quantity": 0.00015}, {"price": 64473.22, "quantity": 0.01131}, {"price": 64475.94, "quantity": 0.001}, {"price": 64480.68, "quantity": 0.0092}, {"price": 64500.0, "quantity": 0.0001}, {"price": 64520.74, "quantity": 0.00044}, {"price": 64527.97, "quantity": 0.05339}, {"price": 64528.57, "quantity": 0.02942}, {"price": 64547.74, "quantity": 0.00045}, {"price": 64564.16, "quantity": 0.00079}, {"price": 64567.37, "quantity": 0.00038}, {"price": 64576.2, "quantity": 0.01579}, {"price": 64613.62, "quantity": 0.00081}, {"price": 64622.57, "quantity": 0.00044}, {"price": 64679.26, "quantity": 9e-05}, {"price": 64685.03, "quantity": 0.0006}, {"price": 64689.05, "quantity": 0.01391}, {"price": 64700.0, "quantity": 0.00485}, {"price": 64700.28, "quantity": 0.00057}, {"price": 64710.95, "quantity": 0.02783}, {"price": 64713.49, "quantity": 0.00053}, {"price": 64714.18, "quantity": 0.0025}, {"price": 64719.35, "quantity": 0.00077}, {"price": 64723.91, "quantity": 0.00058}, {"price": 64729.62, "quantity": 0.01965}, {"price": 64736.96, "quantity": 0.00015}, {"price": 64737.56, "quantity": 0.00045}, {"price": 64738.4, "quantity": 0.00048}, {"price": 64749.03, "quantity": 0.00466}, {"price": 64750.0, "quantity": 0.00894}, {"price": 64752.41, "quantity": 0.00031}, {"price": 64755.3, "quantity": 0.00124}, {"price": 64759.99, "quantity": 0.00094}, {"price": 64761.2, "quantity": 0.0047}, {"price": 64767.1, "quantity": 0.00058}, {"price": 64769.03, "quantity": 0.00106}, {"price": 64775.4, "quantity": 0.00797}, {"price": 64784.36, "quantity": 0.00015}, {"price": 64790.45, "quantity": 0.00013}, {"price": 64800.0, "quantity": 0.00038}, {"price": 64820.22, "quantity": 0.00124}, {"price": 64825.5, "quantity": 0.00061}, {"price": 64833.08, "quantity": 0.00018}, {"price": 64833.33, "quantity": 0.00093}, {"price": 64848.02, "quantity": 0.02942}, {"price": 64857.15, "quantity": 0.001}, {"price": 64884.78, "quantity": 0.00102}, {"price": 64885.13, "quantity": 0.00124}, {"price": 64897.33, "quantity": 0.00058}, {"price": 64903.17, "quantity": 0.00048}, {"price": 64908.68, "quantity": 0.00056}, {"price": 64917.69, "quantity": 0.00015}, {"price": 64918.47, "quantity": 0.00058}, {"price": 64925.7, "quantity": 0.00055}, {"price": 64930.87, "quantity": 0.00076}, {"price": 64934.92, "quantity": 0.00015}, {"price": 64949.35, "quantity": 0.00076}, {"price": 64950.05, "quantity": 0.00124}, {"price": 64953.11, "quantity": 0.00124}, {"price": 64956.88, "quantity": 0.0003}, {"price": 64971.88, "quantity": 0.00015}, {"price": 64973.31, "quantity": 0.00248}, {"price": 64975.0, "quantity": 0.00482}, {"price": 64975.17, "quantity": 0.00081}, {"price": 64979.93, "quantity": 9e-05}, {"price": 64985.47, "quantity": 0.00015}, {"price": 64987.23, "quantity": 0.00084}, {"price": 64993.87, "quantity": 0.00152}, {"price": 65000.0, "quantity": 0.00933}, {"price": 65002.44, "quantity": 0.00058}, {"price": 65027.14, "quantity": 0.00033}, {"price": 65047.44, "quantity": 0.00053}, {"price": 65060.6, "quantity": 0.00048}, {"price": 65074.7, "quantity": 0.00098}, {"price": 65077.19, "quantity": 0.01382}, {"price": 65090.65, "quantity": 0.00058}, {"price": 65101.12, "quantity": 0.00058}, {"price": 65106.85, "quantity": 0.00108}, {"price": 65116.04, "quantity": 0.00054}, {"price": 65128.94, "quantity": 0.00035}, {"price": 65129.89, "quantity": 0.00076}, {"price": 65144.31, "quantity": 0.00047}, {"price": 65163.31, "quantity": 0.00466}, {"price": 65180.28, "quantity": 0.06096}, {"price": 65200.0, "quantity": 0.00038}, {"price": 65209.73, "quantity": 0.00123}, {"price": 65231.1, "quantity": 0.0004}, {"price": 65247.07, "quantity": 0.00057}, {"price": 65250.0, "quantity": 0.01372}, {"price": 65266.12, "quantity": 0.03976}, {"price": 65266.8, "quantity": 0.00035}, {"price": 65270.9, "quantity": 0.00252}, {"price": 65271.29, "quantity": 0.00205}, {"price": 65274.64, "quantity": 0.00123}, {"price": 65280.6, "quantity": 9e-05}, {"price": 65283.33, "quantity": 0.0026}, {"price": 65286.83, "quantity": 0.00205}, {"price": 65286.98, "quantity": 0.00245}, {"price": 65287.39, "quantity": 0.00031}, {"price": 65296.31, "quantity": 0.00015}, {"price": 65297.89, "quantity": 0.00268}, {"price": 65298.13, "quantity": 0.00154}, {"price": 65305.15, "quantity": 0.00187}, {"price": 65305.48, "quantity": 0.00015}, {"price": 65309.92, "quantity": 0.0021}, {"price": 65315.49, "quantity": 0.00029}, {"price": 65316.69, "quantity": 0.00314}, {"price": 65319.6, "quantity": 0.00102}, {"price": 65321.76, "quantity": 0.00276}, {"price": 65323.82, "quantity": 0.0021}, {"price": 65328.18, "quantity": 0.00015}, {"price": 65329.85, "quantity": 0.00153}, {"price": 65333.06, "quantity": 0.00034}, {"price": 65333.59, "quantity": 0.00038}, {"price": 65335.96, "quantity": 0.00124}, {"price": 65338.98, "quantity": 0.0021}, {"price": 65339.56, "quantity": 0.00123}, {"price": 65341.59, "quantity": 0.00303}, {"price": 65345.51, "quantity": 0.00285}, {"price": 65345.93, "quantity": 0.03352}, {"price": 65362.96, "quantity": 0.00052}, {"price": 65364.35, "quantity": 0.00312}, {"price": 65368.42, "quantity": 0.05343}, {"price": 65371.81, "quantity": 0.00127}, {"price": 65372.35, "quantity": 0.00666}, {"price": 65373.3, "quantity": 0.00303}, {"price": 65374.08, "quantity": 0.00332}, {"price": 65377.92, "quantity": 0.00015}, {"price": 65390.38, "quantity": 0.00315}, {"price": 65397.03, "quantity": 0.00332}, {"price": 65398.68, "quantity": 0.00342}, {"price": 65398.74, "quantity": 0.00035}, {"price": 65399.35, "quantity": 0.00014}, {"price": 65404.47, "quantity": 0.00123}, {"price": 65404.88, "quantity": 0.00046}, {"price": 65417.63, "quantity": 0.00031}, {"price": 65425.79, "quantity": 0.00015}, {"price": 65437.19, "quantity": 0.00037}, {"price": 65439.64, "quantity": 0.00345}, {"price": 65441.53, "quantity": 0.00015}, {"price": 65441.54, "quantity": 0.00015}, {"price": 65454.98, "quantity": 0.00345}, {"price": 65457.52, "quantity": 0.00345}, {"price": 65459.93, "quantity": 0.00906}, {"price": 65467.65, "quantity": 0.01374}, {"price": 65469.39, "quantity": 0.00123}, {"price": 65493.82, "quantity": 0.00022}, {"price": 65499.3, "quantity": 0.001}, {"price": 65500.0, "quantity": 0.00912}, {"price": 65505.27, "quantity": 0.00051}, {"price": 65516.8, "quantity": 0.00155}, {"price": 65524.64, "quantity": 0.00078}, {"price": 65532.46, "quantity": 0.00375}, {"price": 65534.31, "quantity": 0.00123}, {"price": 65538.45, "quantity": 0.00069}, {"price": 65540.63, "quantity": 0.00088}, {"price": 65543.03, "quantity": 0.00076}, {"price": 65544.63, "quantity": 0.00077}, {"price": 65554.13, "quantity": 0.00015}, {"price": 65562.83, "quantity": 0.00047}, {"price": 65572.22, "quantity": 0.13767}, {"price": 65577.59, "quantity": 0.00466}, {"price": 65577.84, "quantity": 0.00015}, {"price": 65581.27, "quantity": 9e-05}, {"price": 65586.26, "quantity": 0.00038}, {"price": 65587.05, "quantity": 0.001}, {"price": 65590.48, "quantity": 0.00048}, {"price": 65595.94, "quantity": 0.00049}, {"price": 65599.22, "quantity": 0.00123}, {"price": 65628.89, "quantity": 0.00015}, {"price": 65629.77, "quantity": 0.00153}, {"price": 65639.13, "quantity": 0.00076}, {"price": 65664.15, "quantity": 0.00123}, {"price": 65678.59, "quantity": 0.00204}, {"price": 65680.48, "quantity": 0.00024}, {"price": 65720.1, "quantity": 0.00038}, {"price": 65720.19, "quantity": 0.00013}, {"price": 65729.64, "quantity": 0.00291}, {"price": 65739.44, "quantity": 0.00044}, {"price": 65750.0, "quantity": 0.00894}, {"price": 65751.47, "quantity": 0.00018}, {"price": 65754.43, "quantity": 0.00101}, {"price": 65763.1, "quantity": 0.00078}, {"price": 65767.18, "quantity": 0.00084}, {"price": 65773.89, "quantity": 0.00152}, {"price": 65796.97, "quantity": 0.04711}, {"price": 65840.16, "quantity": 0.0006}, {"price": 65860.46, "quantity": 0.01366}, {"price": 65867.51, "quantity": 0.00076}, {"price": 65868.29, "quantity": 0.00098}, {"price": 65880.57, "quantity": 0.00406}, {"price": 65881.94, "quantity": 9e-05}, {"price": 65886.08, "quantity": 0.00315}, {"price": 65933.33, "quantity": 0.0001}, {"price": 65936.47, "quantity": 0.00015}, {"price": 65940.2, "quantity": 0.00039}, {"price": 65941.06, "quantity": 0.00078}, {"price": 65943.2, "quantity": 0.00035}, {"price": 65945.73, "quantity": 0.00015}, {"price": 65949.24, "quantity": 0.00406}, {"price": 65958.8, "quantity": 0.00075}, {"price": 65968.41, "quantity": 0.0003}, {"price": 65968.66, "quantity": 0.00015}, {"price": 65974.14, "quantity": 0.00243}, {"price": 65977.64, "quantity": 0.00048}, {"price": 65991.87, "quantity": 0.00466}, {"price": 65992.69, "quantity": 0.00315}, {"price": 65993.99, "quantity": 0.00052}, {"price": 65994.36, "quantity": 0.00047}, {"price": 66000.0, "quantity": 0.00907}, {"price": 66000.82, "quantity": 0.00406}, {"price": 66007.05, "quantity": 0.00104}, {"price": 66018.88, "quantity": 0.00015}, {"price": 66032.06, "quantity": 0.00061}, {"price": 66037.97, "quantity": 0.00026}, {"price": 66040.77, "quantity": 0.006}, {"price": 66040.85, "quantity": 0.00039}, {"price": 66042.43, "quantity": 0.00314}, {"price": 66046.05, "quantity": 0.01}, {"price": 66056.9, "quantity": 0.01}, {"price": 66064.19, "quantity": 0.00153}, {"price": 66067.05, "quantity": 0.00314}, {"price": 66067.22, "quantity": 0.00015}, {"price": 66068.27, "quantity": 0.00032}, {"price": 66081.67, "quantity": 0.00018}, {"price": 66089.47, "quantity": 0.00015}, {"price": 66090.63, "quantity": 0.00314}, {"price": 66096.16, "quantity": 0.0013}, {"price": 66105.26, "quantity": 0.05283}, {"price": 66108.9, "quantity": 0.00037}, {"price": 66112.69, "quantity": 0.00378}, {"price": 66141.45, "quantity": 0.001}, {"price": 66142.6, "quantity": 0.00042}, {"price": 66154.85, "quantity": 0.00051}, {"price": 66166.67, "quantity": 0.00041}, {"price": 66180.71, "quantity": 0.00047}, {"price": 66182.61, "quantity": 9e-05}, {"price": 66189.25, "quantity": 0.001}, {"price": 66190.39, "quantity": 0.00152}, {"price": 66190.58, "quantity": 0.00015}, {"price": 66198.57, "quantity": 0.00782}, {"price": 66209.31, "quantity": 0.00095}, {"price": 66210.98, "quantity": 0.00087}, {"price": 66214.32, "quantity": 0.0154}, {"price": 66220.76, "quantity": 0.00015}, {"price": 66232.41, "quantity": 0.00065}, {"price": 66232.58, "quantity": 0.00026}, {"price": 66240.32, "quantity": 0.0006}, {"price": 66243.05, "quantity": 0.00075}, {"price": 66243.32, "quantity": 0.00043}, {"price": 66243.33, "quantity": 0.00043}, {"price": 66245.25, "quantity": 0.00044}, {"price": 66248.26, "quantity": 0.00037}, {"price": 66250.0, "quantity": 0.00894}, {"price": 66251.57, "quantity": 0.01}, {"price": 66252.01, "quantity": 0.00153}, {"price": 66255.62, "quantity": 0.01358}, {"price": 66266.12, "quantity": 0.00045}, {"price": 66272.31, "quantity": 0.00015}, {"price": 66281.36, "quantity": 0.00101}, {"price": 66331.91, "quantity": 0.0005}, {"price": 66346.64, "quantity": 0.00041}, {"price": 66356.74, "quantity": 0.0032}, {"price": 66370.49, "quantity": 0.00104}, {"price": 66371.4, "quantity": 0.01}, {"price": 66371.65, "quantity": 0.00059}, {"price": 66377.21, "quantity": 0.00075}, {"price": 66406.15, "quantity": 0.00466}, {"price": 66427.19, "quantity": 0.00026}, {"price": 66439.84, "quantity": 0.00153}, {"price": 66446.23, "quantity": 0.01}, {"price": 66447.88, "quantity": 0.00032}, {"price": 66449.1, "quantity": 0.005}, {"price": 66454.06, "quantity": 0.00879}, {"price": 66465.9, "quantity": 0.002}, {"price": 66475.3, "quantity": 0.002}, {"price": 66483.28, "quantity": 9e-05}, {"price": 66494.27, "quantity": 0.15316}, {"price": 66500.0, "quantity": 0.0095}, {"price": 66505.0, "quantity": 0.002}, {"price": 66507.1, "quantity": 0.002}, {"price": 66508.6, "quantity": 0.003}, {"price": 66509.1, "quantity": 0.003}, {"price": 66513.27, "quantity": 0.00152}, {"price": 66517.5, "quantity": 0.003}, {"price": 66523.07, "quantity": 0.00782}, {"price": 66526.7, "quantity": 0.003}, {"price": 66529.7, "quantity": 0.003}, {"price": 66535.02, "quantity": 0.0024}, {"price": 66536.79, "quantity": 0.00311}, {"price": 66538.9, "quantity": 0.0154}, {"price": 66547.06, "quantity": 0.00083}, {"price": 66548.97, "quantity": 0.00034}, {"price": 66553.85, "quantity": 0.0015}, {"price": 66575.26, "quantity": 0.00065}, {"price": 66576.63, "quantity": 0.00015}, {"price": 66585.98, "quantity": 0.00015}, {"price": 66607.98, "quantity": 0.00234}, {"price": 66609.13, "quantity": 0.00015}, {"price": 66627.66, "quantity": 0.00153}, {"price": 66640.07, "quantity": 0.001}, {"price": 66640.9, "quantity": 0.01}, {"price": 66650.18, "quantity": 0.00038}, {"price": 66653.15, "quantity": 0.0135}, {"price": 66657.36, "quantity": 0.00158}, {"price": 66659.84, "quantity": 0.00015}, {"price": 66661.89, "quantity": 0.00098}, {"price": 66666.67, "quantity": 0.00039}, {"price": 66678.03, "quantity": 0.00374}, {"price": 66696.75, "quantity": 0.01}, {"price": 66698.18, "quantity": 0.001}, {"price": 66708.65, "quantity": 0.00014}, {"price": 66724.93, "quantity": 0.00048}, {"price": 66725.08, "quantity": 0.00104}, {"price": 66731.44, "quantity": 0.00051}, {"price": 66737.41, "quantity": 0.00014}, {"price": 66750.18, "quantity": 0.00035}, {"price": 66761.22, "quantity": 0.00047}, {"price": 66769.2, "quantity": 0.001}, {"price": 66783.6, "quantity": 0.001}, {"price": 66783.62, "quantity": 0.00076}, {"price": 66783.95, "quantity": 9e-05}, {"price": 66798.26, "quantity": 0.00074}, {"price": 66801.45, "quantity": 0.00155}, {"price": 66815.48, "quantity": 0.00153}, {"price": 66820.43, "quantity": 0.00466}, {"price": 66827.03, "quantity": 0.00014}, {"price": 66832.37, "quantity": 0.00355}, {"price": 66835.57, "quantity": 0.01}, {"price": 66836.15, "quantity": 0.0015}, {"price": 66842.11, "quantity": 0.05225}, {"price": 66850.18, "quantity": 0.0004}, {"price": 66863.68, "quantity": 0.00014}, {"price": 66869.01, "quantity": 0.00111}, {"price": 66872.96, "quantity": 0.02895}, {"price": 66875.0, "quantity": 0.00107}, {"price": 66898.16, "quantity": 0.00048}, {"price": 66898.93, "quantity": 0.0005}, {"price": 66909.19, "quantity": 0.00111}, {"price": 66912.32, "quantity": 0.00111}, {"price": 66915.73, "quantity": 0.00014}, {"price": 66916.94, "quantity": 0.00037}, {"price": 66945.34, "quantity": 0.00111}, {"price": 66950.18, "quantity": 0.00043}, {"price": 66971.34, "quantity": 0.00111}, {"price": 67000.0, "quantity": 0.01107}, {"price": 67003.05, "quantity": 0.001}, {"price": 67003.3, "quantity": 0.00153}, {"price": 67030.23, "quantity": 0.01}, {"price": 67050.18, "quantity": 0.00028}, {"price": 67053.07, "quantity": 0.01342}, {"price": 67055.4, "quantity": 0.001}, {"price": 67098.01, "quantity": 0.00092}, {"price": 67101.15, "quantity": 0.05245}, {"price": 67142.16, "quantity": 0.00308}, {"price": 67150.18, "quantity": 0.0003}, {"price": 67159.03, "quantity": 0.0015}, {"price": 67201.67, "quantity": 0.00197}, {"price": 67203.55, "quantity": 0.00078}, {"price": 67216.79, "quantity": 0.00014}, {"price": 67221.99, "quantity": 0.00074}, {"price": 67224.9, "quantity": 0.01}, {"price": 67226.23, "quantity": 0.00014}, {"price": 67234.71, "quantity": 0.00466}, {"price": 67243.37, "quantity": 0.00371}, {"price": 67249.6, "quantity": 0.00014}, {"price": 67250.18, "quantity": 0.0003}, {"price": 67250.48, "quantity": 0.00308}, {"price": 67280.61, "quantity": 0.00308}, {"price": 67295.33, "quantity": 0.00154}, {"price": 67300.8, "quantity": 0.00014}, {"price": 67323.1, "quantity": 0.00325}, {"price": 67326.91, "quantity": 0.00082}, {"price": 67329.28, "quantity": 0.00042}, {"price": 67329.29, "quantity": 0.00042}, {"price": 67333.78, "quantity": 0.00148}, {"price": 67350.08, "quantity": 0.00014}, {"price": 67350.18, "quantity": 0.00031}, {"price": 67372.19, "quantity": 0.00307}, {"price": 67378.22, "quantity": 0.00307}, {"price": 67385.35, "quantity": 0.00014}, {"price": 67400.0, "quantity": 0.0001}, {"price": 67412.32, "quantity": 0.00031}, {"price": 67415.92, "quantity": 0.00307}, {"price": 67431.31, "quantity": 0.00029}, {"price": 67450.18, "quantity": 0.0003}, {"price": 67455.39, "quantity": 0.01334}, {"price": 67455.96, "quantity": 0.00307}, {"price": 67463.28, "quantity": 0.00866}, {"price": 67481.91, "quantity": 0.00148}, {"price": 67492.98, "quantity": 0.00307}, {"price": 67506.6, "quantity": 0.00014}, {"price": 67550.18, "quantity": 0.00028}, {"price": 67559.15, "quantity": 0.00014}, {"price": 67578.95, "quantity": 0.05168}, {"price": 67592.37, "quantity": 0.00036}, {"price": 67648.98, "quantity": 0.00466}, {"price": 67650.18, "quantity": 0.0003}, {"price": 67666.73, "quantity": 0.00306}, {"price": 67727.24, "quantity": 0.00048}, {"price": 67750.18, "quantity": 0.0003}, {"price": 67804.79, "quantity": 0.00148}, {"price": 67808.72, "quantity": 0.00368}, {"price": 67809.29, "quantity": 0.001}, {"price": 67833.33, "quantity": 0.0001}, {"price": 67850.18, "quantity": 0.0003}, {"price": 67924.49, "quantity": 0.00093}, {"price": 67950.18, "quantity": 0.00028}, {"price": 68000.0, "quantity": 0.00768}, {"price": 68033.29, "quantity": 0.00014}, {"price": 68039.79, "quantity": 0.00016}, {"price": 68043.05, "quantity": 0.00028}, {"price": 68050.18, "quantity": 0.0003}, {"price": 68063.26, "quantity": 0.00466}, {"price": 68067.92, "quantity": 0.00075}, {"price": 68106.76, "quantity": 0.00081}, {"price": 68113.71, "quantity": 0.00146}, {"price": 68138.58, "quantity": 0.00055}, {"price": 68150.18, "quantity": 0.0003}, {"price": 68250.18, "quantity": 0.0003}, {"price": 68274.61, "quantity": 0.00036}, {"price": 68289.46, "quantity": 0.0033}, {"price": 68294.73, "quantity": 0.26674}, {"price": 68294.94, "quantity": 0.34954}, {"price": 68295.15, "quantity": 0.03287}, {"price": 68295.36, "quantity": 0.31045}, {"price": 68295.57, "quantity": 0.04042}, {"price": 68315.79, "quantity": 0.05113}, {"price": 68333.33, "quantity": 0.00039}, {"price": 68341.0, "quantity": 0.00012}, {"price": 68350.18, "quantity": 0.0003}, {"price": 68374.06, "quantity": 0.00365}, {"price": 68415.23, "quantity": 0.00042}, {"price": 68450.18, "quantity": 0.00032}, {"price": 68452.04, "quantity": 0.00151}, {"price": 68487.84, "quantity": 0.00853}, {"price": 68500.0, "quantity": 0.00341}, {"price": 68550.18, "quantity": 0.00031}, {"price": 68650.18, "quantity": 0.0003}, {"price": 68750.18, "quantity": 0.0003}, {"price": 68850.18, "quantity": 0.0003}, {"price": 68866.66, "quantity": 9e-05}, {"price": 68886.61, "quantity": 0.0008}, {"price": 68893.64, "quantity": 0.00145}, {"price": 68920.4, "quantity": 0.001}, {"price": 68939.4, "quantity": 0.00362}, {"price": 68950.18, "quantity": 0.00026}, {"price": 68963.75, "quantity": 0.00036}, {"price": 69000.0, "quantity": 0.00768}, {"price": 69050.18, "quantity": 0.00029}, {"price": 69052.63, "quantity": 0.05058}, {"price": 69086.61, "quantity": 0.00033}, {"price": 69092.09, "quantity": 0.00056}, {"price": 69191.98, "quantity": 0.00029}, {"price": 69255.82, "quantity": 0.00335}, {"price": 69352.22, "quantity": 0.00074}, {"price": 69500.0, "quantity": 0.0003}, {"price": 69501.0, "quantity": 0.0001}, {"price": 69504.75, "quantity": 0.00359}, {"price": 69527.95, "quantity": 0.0084}, {"price": 69659.84, "quantity": 0.00035}, {"price": 69666.46, "quantity": 0.00079}, {"price": 69673.56, "quantity": 0.00143}, {"price": 69789.47, "quantity": 0.05005}, {"price": 70000.0, "quantity": 0.01835}, {"price": 70002.05, "quantity": 0.001}, {"price": 70031.52, "quantity": 0.001}, {"price": 70047.84, "quantity": 0.00011}, {"price": 70070.09, "quantity": 0.00356}, {"price": 70264.76, "quantity": 0.09425}, {"price": 70333.33, "quantity": 9e-05}, {"price": 70362.95, "quantity": 0.00035}, {"price": 70446.3, "quantity": 0.00078}, {"price": 70453.49, "quantity": 0.00141}, {"price": 70526.32, "quantity": 0.04952}, {"price": 70583.85, "quantity": 0.00828}, {"price": 70635.43, "quantity": 0.00353}, {"price": 70636.52, "quantity": 0.00072}, {"price": 71073.16, "quantity": 0.00035}, {"price": 71226.15, "quantity": 0.00078}, {"price": 71233.42, "quantity": 0.0014}, {"price": 71263.16, "quantity": 0.04901}, {"price": 71655.8, "quantity": 0.00816}, {"price": 71666.67, "quantity": 0.00039}, {"price": 71790.54, "quantity": 0.00034}, {"price": 71800.0, "quantity": 9e-05}, {"price": 72000.0, "quantity": 0.04851}, {"price": 72006.0, "quantity": 0.00077}, {"price": 72013.35, "quantity": 0.00138}, {"price": 72070.66, "quantity": 0.00033}, {"price": 72442.34, "quantity": 0.01484}, {"price": 72515.17, "quantity": 0.00034}, {"price": 72744.02, "quantity": 0.00803}, {"price": 73247.1, "quantity": 0.00034}, {"price": 73266.66, "quantity": 9e-05}, {"price": 73333.33, "quantity": 0.00039}, {"price": 73986.42, "quantity": 0.00033}, {"price": 74712.46, "quantity": 0.11484}, {"price": 74729.29, "quantity": 0.08325}, {"price": 74733.21, "quantity": 0.00033}, {"price": 74733.33, "quantity": 9e-05}, {"price": 74755.29, "quantity": 0.06153}, {"price": 74938.04, "quantity": 0.4}, {"price": 75000.0, "quantity": 0.00039}, {"price": 75002.0, "quantity": 0.0001}, {"price": 75003.0, "quantity": 0.0001}, {"price": 75004.0, "quantity": 0.0001}, {"price": 75005.0, "quantity": 0.0001}, {"price": 75006.0, "quantity": 0.0001}, {"price": 75487.53, "quantity": 0.00033}, {"price": 75500.0, "quantity": 0.0001}, {"price": 76200.0, "quantity": 8e-05}, {"price": 76249.47, "quantity": 0.00032}, {"price": 76317.61, "quantity": 0.00131}, {"price": 76819.43, "quantity": 0.00727}, {"price": 77019.1, "quantity": 0.00032}, {"price": 77666.66, "quantity": 8e-05}, {"price": 77765.89, "quantity": 0.35}, {"price": 77796.5, "quantity": 0.00032}, {"price": 78501.0, "quantity": 0.0001}, {"price": 78581.74, "quantity": 0.00031}, {"price": 78804.18, "quantity": 0.001}, {"price": 79133.33, "quantity": 8e-05}, {"price": 79374.91, "quantity": 0.00031}, {"price": 79594.19, "quantity": 0.001}, {"price": 79992.16, "quantity": 0.001}, {"price": 80040.0, "quantity": 0.0009}, {"price": 80176.08, "quantity": 0.00031}, {"price": 80373.5, "quantity": 0.0009}, {"price": 80392.12, "quantity": 0.001}, {"price": 80600.0, "quantity": 8e-05}, {"price": 80707.0, "quantity": 0.0009}, {"price": 80794.08, "quantity": 0.001}, {"price": 80985.34, "quantity": 0.0003}, {"price": 81040.5, "quantity": 0.0009}, {"price": 81198.05, "quantity": 0.001}, {"price": 81300.71, "quantity": 0.25}, {"price": 81604.04, "quantity": 0.001}, {"price": 81802.77, "quantity": 0.0003}, {"price": 82012.06, "quantity": 0.001}, {"price": 82066.66, "quantity": 8e-05}, {"price": 82204.97, "quantity": 0.01112}, {"price": 82370.81, "quantity": 0.00047}, {"price": 82422.12, "quantity": 0.001}, {"price": 82628.45, "quantity": 0.0003}, {"price": 83462.47, "quantity": 0.00029}, {"price": 83533.33, "quantity": 8e-05}, {"price": 84304.9, "quantity": 0.00029}, {"price": 85000.0, "quantity": 7e-05}, {"price": 85155.84, "quantity": 0.00029}, {"price": 85762.44, "quantity": 0.00014}, {"price": 86015.36, "quantity": 0.00029}, {"price": 86883.56, "quantity": 0.00028}, {"price": 87760.53, "quantity": 0.00028}, {"price": 88646.34, "quantity": 0.00028}, {"price": 89541.1, "quantity": 0.00027}, {"price": 90444.89, "quantity": 0.00027}, {"price": 91357.8, "quantity": 0.00027}, {"price": 92279.92, "quantity": 0.00027}, {"price": 93211.35, "quantity": 0.00026}, {"price": 94152.19, "quantity": 0.00026}, {"price": 95102.52, "quantity": 0.00026}, {"price": 95840.01, "quantity": 0.92247}, {"price": 96062.44, "quantity": 0.00026}, {"price": 96231.3, "quantity": 0.01294}, {"price": 97032.05, "quantity": 0.00025}, {"price": 98011.45, "quantity": 0.00025}, {"price": 99000.73, "quantity": 0.00025}, {"price": 100000.0, "quantity": 0.00025}, {"price": 104438.52, "quantity": 8e-05}, {"price": 111393.3, "quantity": 0.01294}], "snapshot_time": 1786680202013, "source": "reconciled"}}
{"type": "delta", "data": {"event_type": "depth_update", "exchange": "binance", "symbol": "BTCUSDT", "event_time": 1786680203020, "received_time": 1786680203215, "first_update_id": 4673302, "final_update_id": 4673350, "bids": [{"price": 63353.99, "quantity": 16.8266}, {"price": 63353.98, "quantity": 1.56816}, {"price": 63353.97, "quantity": 0.00064}, {"price": 63353.94, "quantity": 0.04175}, {"price": 63353.9, "quantity": 0.00064}, {"price": 63353.6, "quantity": 0.00064}, {"price": 63353.13, "quantity": 0.00931}, {"price": 63352.73, "quantity": 0.00072}, {"price": 63352.72, "quantity": 0.21884}, {"price": 63352.58, "quantity": 0.00036}, {"price": 63352.03, "quantity": 0.00072}, {"price": 63352.02, "quantity": 1.51076}, {"price": 63352.0, "quantity": 0.08944}, {"price": 63351.99, "quantity": 0.16919}, {"price": 63351.8, "quantity": 0.00072}, {"price": 63351.79, "quantity": 0.25442}, {"price": 63351.67, "quantity": 0.008}, {"price": 63351.45, "quantity": 0.25114}, {"price": 63351.31, "quantity": 0.00036}, {"price": 63351.29, "quantity": 0.00092}, {"price": 63341.99, "quantity": 0.0}, {"price": 63341.98, "quantity": 0.00011}, {"price": 63341.97, "quantity": 0.0}, {"price": 63341.95, "quantity": 0.0}, {"price": 63341.94, "quantity": 0.0}, {"price": 63341.9, "quantity": 0.0}, {"price": 63341.78, "quantity": 0.0}, {"price": 63341.77, "quantity": 0.0}, {"price": 63341.76, "quantity": 0.0}, {"price": 63341.73, "quantity": 0.0}, {"price": 63341.16, "quantity": 0.0}, {"price": 63340.81, "quantity": 0.0}, {"price": 63340.8, "quantity": 0.0}, {"price": 63340.73, "quantity": 0.0}, {"price": 63340.72, "quantity": 0.0}, {"price": 63340.67, "quantity": 0.001}, {"price": 63340.53, "quantity": 0.0}, {"price": 63340.45, "quantity": 0.0}, {"price": 63340.0, "quantity": 0.0}, {"price": 63339.99, "quantity": 0.0}, {"price": 63339.98, "quantity": 0.0}], "asks": [{"price": 63342.0, "quantity": 0.0}, {"price": 63342.01, "quantity": 0.0}, {"price": 63342.02, "quantity": 0.0}, {"price": 63342.21, "quantity": 0.0}, {"price": 63342.42, "quantity": 0.0}, {"price": 63342.52, "quantity": 0.0}, {"price": 63342.76, "quantity": 0.0}, {"price": 63342.77, "quantity": 0.0}, {"price": 63343.98, "quantity": 0.0}, {"price": 63343.99, "quantity": 0.0}, {"price": 63344.0, "quantity": 0.0}, {"price": 63344.2, "quantity": 0.0}, {"price": 63344.21, "quantity": 0.0}, {"price": 63344.69, "quantity": 0.0}, {"price": 63344.96, "quantity": 0.0}, {"price": 63345.52, "quantity": 0.0}, {"price": 63345.6, "quantity": 0.0}, {"price": 63345.61, "quantity": 0.0}, {"price": 63345.62, "quantity": 0.0}, {"price": 63345.93, "quantity": 0.0}, {"price": 63346.0, "quantity": 0.0}, {"price": 63354.0, "quantity": 8.80672}, {"price": 63354.01, "quantity": 0.0028}, {"price": 63354.02, "quantity": 0.00064}, {"price": 63354.22, "quantity": 0.00032}, {"price": 63354.43, "quantity": 0.00498}, {"price": 63354.48, "quantity": 0.00072}, {"price": 63354.49, "quantity": 0.2356}, {"price": 63354.5, "quantity": 0.75883}, {"price": 63354.7, "quantity": 0.00032}, {"price": 63354.96, "quantity": 0.00032}, {"price": 63355.04, "quantity": 0.00999}, {"price": 63355.14, "quantity": 0.01634}, {"price": 63355.65, "quantity": 0.00032}, {"price": 63355.88, "quantity": 0.00036}, {"price": 63355.89, "quantity": 0.0852}, {"price": 63355.99, "quantity": 0.00072}, {"price": 63356.0, "quantity": 0.08799}, {"price": 63356.2, "quantity": 0.00072}, {"price": 63356.21, "quantity": 0.13494}, {"price": 63356.22, "quantity": 0.25174}, {"price": 63434.72, "quantity": 0.00078}, {"price": 64608.84, "quantity": 0.17539}, {"price": 65875.68, "quantity": 0.17539}, {"price": 66521.7, "quantity": 0.002}, {"price": 67142.52, "quantity": 0.17539}]}}
{"type": "delta", "data": {"event_type": "depth_update", "exchange": "binance", "symbol": "BTCUSDT", "event_time": 1786680204025, "received_time": 1786680204221, "first_update_id": 4673351, "final_update_id": 4673357, "bids": [{"price": 63353.99, "quantity": 16.8246}], "asks": [{"price": 63658.8, "quantity": 0.0}, {"price": 63666.8, "quantity": 0.0}, {"price": 63670.8, "quantity": 0.001}, {"price": 68409.36, "quantity": 0.17539}, {"price": 69676.2, "quantity": 0.17539}]}}
{"type": "delta", "data": {"event_type": "depth_update", "exchange": "binance", "symbol": "BTCUSDT", "event_time": 1786680205028, "received_time": 1786680205222, "first_update_id": 4673358, "final_update_id": 4673361, "bids": [{"price": 63353.99, "quantity": 16.80757}], "asks": [{"price": 63354.0, "quantity": 8.80572}]}}
{"type": "delta", "data": {"event_type": "depth_update", "exchange": "binance", "symbol": "BTCUSDT", "event_time": 1786680206006, "received_time": 1786680206199, "first_update_id": 4673362, "final_update_id": 4673362, "bids": [{"price": 63353.99, "quantity": 16.79957}], "asks": []}}
{"type": "delta", "data": {"event_type": "depth_update", "exchange": "binance", "symbol": "BTCUSDT", "event_time": 1786680207033, "received_time": 1786680207227, "first_update_id": 4673363, "final_update_id": 4673363, "bids": [], "asks": [{"price": 63354.0, "quantity": 8.80375}]}}
{"type": "delta", "data": {"event_type": "depth_update", "exchange": "binance", "symbol": "BTCUSDT", "event_time": 1786680209021, "received_time": 1786680209214, "first_update_id": 4673364, "final_update_id": 4673365, "bids": [], "asks": [{"price": 63670.8, "quantity": 0.004}]}}
{"type": "delta", "data": {"event_type": "depth_update", "exchange": "binance", "symbol": "BTCUSDT", "event_time": 1786680213013, "received_time": 1786680213209, "first_update_id": 4673366, "final_update_id": 4673416, "bids": [{"price": 63353.99, "quantity": 16.79957}, {"price": 63353.98, "quantity": 1.56827}, {"price": 63341.98, "quantity": 0.0}], "asks": [{"price": 63354.0, "quantity": 8.79523}]}}
{"type": "delta", "data": {"event_type": "depth_update", "exchange": "binance", "symbol": "BTCUSDT", "event_time": 1786680214022, "received_time": 1786680214219, "first_update_id": 4673417, "final_update_id": 4673419, "bids": [{"price": 63352.67, "quantity": 0.001}, {"price": 63340.67, "quantity": 0.0}], "asks": [{"price": 63354.52, "quantity": 0.001}]}}
{"type": "delta", "data": {"event_type": "depth_update", "exchange": "binance", "symbol": "BTCUSDT", "event_time": 1786680215049, "received_time": 1786680215247, "first_update_id": 4673420, "final_update_id": 4673420, "bids": [], "asks": [{"price": 66517.5, "quantity": 0.0}]}}
{"type": "delta", "data": {"event_type": "depth_update", "exchange": "binance", "symbol": "BTCUSDT", "event_time": 1786680216015, "received_time": 1786680216210, "first_update_id": 4673421, "final_update_id": 4673421, "bids": [{"price": 63353.99, "quantity": 16.63053}], "asks": []}}
{"type": "delta", "data": {"event_type": "depth_update", "exchange": "binance", "symbol": "BTCUSDT", "event_time": 1786680218009, "received_time": 1786680218203, "first_update_id": 4673422, "final_update_id": 4673422, "bids": [], "asks": [{"price": 63354.0, "quantity": 8.79423}]}}
{"type": "delta", "data": {"event_type": "depth_update", "exchange": "binance", "symbol": "BTCUSDT", "event_time": 1786680219010, "received_time": 1786680219205, "first_update_id": 4673423, "final_update_id": 4673469, "bids": [{"price": 63363.7, "quantity": 57.2699}, {"price": 63363.69, "quantity": 0.00168}, {"price": 63363.68, "quantity": 0.00064}, {"price": 63363.66, "quantity": 0.00144}, {"price": 63363.65, "quantity": 6.71647}, {"price": 63363.64, "quantity": 11.37808}, {"price": 63363.59, "quantity": 0.00096}, {"price": 63363.21, "quantity": 0.00072}, {"price": 63363.2, "quantity": 1.56695}, {"price": 63363.19, "quantity": 2.60314}, {"price": 63363.11, "quantity": 0.00787}, {"price": 63363.09, "quantity": 0.016}, {"price": 63363.03, "quantity": 3.77308}, {"price": 63363.02, "quantity": 0.00032}, {"price": 63362.73, "quantity": 0.00036}, {"price": 63362.37, "quantity": 0.18851}, {"price": 63362.2, "quantity": 0.30103}, {"price": 63362.19, "quantity": 1.01492}, {"price": 63361.95, "quantity": 0.00644}, {"price": 63361.5, "quantity": 0.016}, {"price": 63353.99, "quantity": 0.0}, {"price": 63353.98, "quantity": 0.00011}, {"price": 63353.97, "quantity": 0.0}, {"price": 63353.94, "quantity": 0.0}, {"price": 63353.9, "quantity": 0.0}, {"price": 63353.6, "quantity": 0.0}, {"price": 63353.13, "quantity": 0.0}, {"price": 63352.73, "quantity": 0.0}, {"price": 63352.72, "quantity": 0.0}, {"price": 63352.58, "quantity": 0.0}, {"price": 63352.03, "quantity": 0.0}, {"price": 63352.02, "quantity": 0.0}, {"price": 63352.0, "quantity": 0.0}, {"price": 63351.99, "quantity": 0.0}, {"price": 63351.8, "quantity": 0.0}, {"price": 63351.79, "quantity": 0.0}, {"price": 63351.67, "quantity": 0.0}, {"price": 63351.45, "quantity": 0.0}, {"price": 63351.31, "quantity": 0.0}, {"price": 63351.29, "quantity": 0.0}, {"price": 63252.59, "quantity": 8e-05}, {"price": 63218.95, "quantity": 0.0}], "asks": [{"price": 63354.0, "quantity": 0.0}, {"price": 63354.01, "quantity": 0.0}, {"price": 63354.02, "quantity": 0.0}, {"price": 63354.22, "quantity": 0.0}, {"price": 63354.43, "quantity": 0.0}, {"price": 63354.48, "quantity": 0.0}, {"price": 63354.49, "quantity": 0.0}, {"price": 63354.5, "quantity": 0.0}, {"price": 63354.52, "quantity": 0.0}, {"price": 63354.7, "quantity": 0.0}, {"price": 63354.96, "quantity": 0.0}, {"price": 63355.04, "quantity": 0.0}, {"price": 63355.14, "quantity": 0.0}, {"price": 63355.65, "quantity": 0.0}, {"price": 63355.88, "quantity": 0.0}, {"price": 63355.89, "quantity": 0.0}, {"price": 63355.99, "quantity": 0.0}, {"price": 63356.0, "quantity": 0.0}, {"price": 63356.2, "quantity": 0.0}, {"price": 63356.21, "quantity": 0.0}, {"price": 63356.22, "quantity": 0.0}, {"price": 63358.67, "quantity": 0.0}, {"price": 63362.44, "quantity": 0.0}, {"price": 63363.71, "quantity": 0.71792}, {"price": 63363.72, "quantity": 0.00106}, {"price": 63363.99, "quantity": 0.00072}, {"price": 63364.0, "quantity": 0.08799}, {"price": 63364.4, "quantity": 0.00032}, {"price": 63364.56, "quantity": 0.00032}, {"price": 63364.68, "quantity": 0.00036}, {"price": 63364.73, "quantity": 0.00032}, {"price": 63365.14, "quantity": 0.00072}, {"price": 63365.15, "quantity": 0.05356}, {"price": 63365.5, "quantity": 0.00944}, {"price": 63365.79, "quantity": 0.00032}, {"price": 63365.9, "quantity": 0.00072}, {"price": 63365.91, "quantity": 0.2482}, {"price": 63365.99, "quantity": 0.00072}, {"price": 63366.0, "quantity": 0.08799}, {"price": 63366.29, "quantity": 0.00032}, {"price": 63366.4, "quantity": 0.00068}, {"price": 63366.79, "quantity": 0.00128}, {"price": 63367.34, "quantity": 0.00036}, {"price": 63408.94, "quantity": 0.0}]}}
{"type": "delta", "data": {"event_type": "depth_update", "exchange": "binance", "symbol": "BTCUSDT", "event_time": 1786680220011, "received_time": 1786680220301, "first_update_id": 4673470, "final_update_id": 4673475, "bids": [], "asks": [{"price": 63363.71, "quantity": 0.71614}, {"price": 63442.69, "quantity": 8e-05}, {"price": 63670.8, "quantity": 0.0}, {"price": 63680.6, "quantity": 0.002}, {"price": 66526.7, "quantity": 0.0}]}}
{"type": "delta", "data": {"event_type": "depth_update", "exchange": "binance", "symbol": "BTCUSDT", "event_time": 1786680224012, "received_time": 1786680224210, "first_update_id": 4673476, "final_update_id": 4673526, "bids": [{"price": 63363.7, "quantity": 57.2699}, {"price": 63363.69, "quantity": 0.00179}, {"price": 63353.98, "quantity": 0.0}, {"price": 63352.67, "quantity": 0.0}], "asks": []}}
{"type": "delta", "data": {"event_type": "depth_update", "exchange": "binance", "symbol": "BTCUSDT", "event_time": 1786680225013, "received_time": 1786680225207, "first_update_id": 4673527, "final_update_id": 4673529, "bids": [{"price": 63362.38, "quantity": 0.001}], "asks": [{"price": 63364.23, "quantity": 0.001}, {"price": 66475.3, "quantity": 0.0}]}}
{"type": "delta", "data": {"event_type": "depth_update", "exchange": "binance", "symbol": "BTCUSDT", "event_time": 1786680228005, "received_time": 1786680228198, "first_update_id": 4673530, "final_update_id": 4673530, "bids": [{"price": 63327.0, "quantity": 0.00157}], "asks": []}}
{"type": "delta", "data": {"event_type": "depth_update", "exchange": "binance", "symbol": "BTCUSDT", "event_time": 1786680229034, "received_time": 1786680229228, "first_update_id": 4673531, "final_update_id": 4673531, "bids": [], "asks": [{"price": 63363.71, "quantity": 0.70034}]}}
{"type": "delta", "data": {"event_type": "depth_update", "exchange": "binance", "symbol": "BTCUSDT", "event_time": 1786680230023, "received_time": 1786680230217, "first_update_id": 4673532, "final_update_id": 4673532, "bids": [], "asks": [{"price": 63363.71, "quantity": 0.69837}]}}
{"type": "delta", "data": {"event_type": "depth_update", "exchange": "binance", "symbol": "BTCUSDT", "event_time": 1786680232012, "received_time": 1786680232208, "first_update_id": 4673533, "final_update_id": 4673583, "bids": [{"price": 63363.7, "quantity": 57.26519}, {"price": 63363.69, "quantity": 0.00179}], "asks": []}}
{"type": "delta", "data": {"event_type": "depth_update", "exchange": "binance", "symbol": "BTCUSDT", "event_time": 1786680233067, "received_time": 1786680233266, "first_update_id": 4673584, "final_update_id": 4673586, "bids": [], "asks": [{"price": 63363.71, "quantity": 0.69637}, {"price": 66531.9, "quantity": 0.001}]}}
{"type": "delta", "data": {"event_type": "depth_update", "exchange": "binance", "symbol": "BTCUSDT", "event_time": 1786680234008, "received_time": 1786680234206, "first_update_id": 4673587, "final_update_id": 4673588, "bids": [], "asks": [{"price": 63363.71, "quantity": 0.69437}]}}
{"type": "delta", "data": {"event_type": "depth_update", "exchange": "binance", "symbol": "BTCUSDT", "event_time": 1786680235006, "received_time": 1786680235201, "first_update_id": 4673589, "final_update_id": 4673631, "bids": [{"price": 63369.88, "quantity": 5.45652}, {"price": 63369.87, "quantity": 0.00323}, {"price": 63369.86, "quantity": 0.00064}, {"price": 63369.6, "quantity": 0.00032}, {"price": 63369.15, "quantity": 0.00064}, {"price": 63368.62, "quantity": 0.00072}, {"price": 63368.61, "quantity": 0.19184}, {"price": 63368.6, "quantity": 0.00032}, {"price": 63368.44, "quantity": 0.00036}, {"price": 63368.39, "quantity": 0.00072}, {"price": 63368.38, "quantity": 0.08071}, {"price": 63368.19, "quantity": 0.00072}, {"price": 63368.18, "quantity": 0.48104}, {"price": 63368.13, "quantity": 0.00072}, {"price": 63368.12, "quantity": 0.37972}, {"price": 63368.0, "quantity": 0.00032}, {"price": 63367.99, "quantity": 0.00032}, {"price": 63367.72, "quantity": 0.00072}, {"price": 63367.71, "quantity": 0.25786}, {"price": 63367.57, "quantity": 0.008}, {"price": 63363.7, "quantity": 0.0}, {"price": 63363.69, "quantity": 0.00011}, {"price": 63363.68, "quantity": 0.0}, {"price": 63363.66, "quantity": 0.0}, {"price": 63363.65, "quantity": 0.0}, {"price": 63363.64, "quantity": 0.0}, {"price": 63363.59, "quantity": 0.0}, {"price": 63363.21, "quantity": 0.0}, {"price": 63363.2, "quantity": 0.0}, {"price": 63363.19, "quantity": 0.0}, {"price": 63363.11, "quantity": 0.0}, {"price": 63363.09, "quantity": 0.0}, {"price": 63363.03, "quantity": 0.0}, {"price": 63363.02, "quantity": 0.0}, {"price": 63362.73, "quantity": 0.0}, {"price": 63362.38, "quantity": 0.0}, {"price": 63362.37, "quantity": 0.0}, {"price": 63362.2, "quantity": 0.0}, {"price": 63362.19, "quantity": 0.0}, {"price": 63361.95, "quantity": 0.0}, {"price": 63361.5, "quantity": 0.0}], "asks": [{"price": 63363.71, "quantity": 0.0}, {"price": 63363.72, "quantity": 0.0}, {"price": 63363.99, "quantity": 0.0}, {"price": 63364.0, "quantity": 0.0}, {"price": 63364.23, "quantity": 0.0}, {"price": 63364.4, "quantity": 0.0}, {"price": 63364.56, "quantity": 0.0}, {"price": 63364.68, "quantity": 0.0}, {"price": 63364.73, "quantity": 0.0}, {"price": 63365.14, "quantity": 0.0}, {"price": 63365.15, "quantity": 0.0}, {"price": 63365.5, "quantity": 0.0}, {"price": 63365.79, "quantity": 0.0}, {"price": 63365.9, "quantity": 0.0}, {"price": 63365.91, "quantity": 0.0}, {"price": 63365.99, "quantity": 0.0}, {"price": 63366.0, "quantity": 0.0}, {"price": 63366.29, "quantity": 0.0}, {"price": 63366.4, "quantity": 0.0}, {"price": 63366.79, "quantity": 0.0}, {"price": 63367.34, "quantity": 0.0}, {"price": 63369.89, "quantity": 11.78275}, {"price": 63369.9, "quantity": 0.20096}, {"price": 63369.91, "quantity": 0.00064}, {"price": 63369.94, "quantity": 0.00072}, {"price": 63369.95, "quantity": 0.2}, {"price": 63369.99, "quantity": 0.00072}, {"price": 63370.0, "quantity": 0.138}, {"price": 63371.04, "quantity": 0.01634}, {"price": 63371.54, "quantity": 0.03155}, {"price": 63371.55, "quantity": 0.00032}, {"price": 63371.62, "quantity": 0.05079}, {"price": 63371.65, "quantity": 0.00032}, {"price": 63371.87, "quantity": 0.00032}, {"price": 63371.93, "quantity": 0.00944}, {"price": 63371.98, "quantity": 0.00072}, {"price": 63371.99, "quantity": 0.2951}, {"price": 63372.0, "quantity": 0.4036}, {"price": 63372.15, "quantity": 0.24912}, {"price": 63372.27, "quantity": 0.0852}, {"price": 63372.63, "quantity": 0.016}, {"price": 66465.9, "quantity": 0.0}]}}
{"type": "delta", "data": {"event_type": "depth_update", "exchange": "binance", "symbol": "BTCUSDT", "event_time": 1786680236009, "received_time": 1786680236205, "first_update_id": 4673632, "final_update_id": 4673637, "bids": [{"price": 63369.88, "quantity": 5.4159}, {"price": 63362.38, "quantity": 0.001}, {"price": 62075.16, "quantity": 0.0}], "asks": [{"price": 63369.89, "quantity": 11.78236}]}}
{"type": "delta", "data": {"event_type": "depth_update", "exchange": "binance", "symbol": "BTCUSDT", "event_time": 1786680237068, "received_time": 1786680237265, "first_update_id": 4673638, "final_update_id": 4673641, "bids": [{"price": 60808.32, "quantity": 0.0}, {"price": 59541.48, "quantity": 0.0}, {"price": 58274.64, "quantity": 0.0}, {"price": 57007.8, "quantity": 0.0}], "asks": []}}
{"type": "delta", "data": {"event_type": "depth_update", "exchange": "binance", "symbol": "BTCUSDT", "event_time": 1786680238004, "received_time": 1786680238198, "first_update_id": 4673642, "final_update_id": 4673645, "bids": [], "asks": [{"price": 64608.84, "quantity": 0.0}, {"price": 65875.68, "quantity": 0.0}, {"price": 67142.52, "quantity": 0.0}, {"price": 68409.36, "quantity": 0.0}]}}
{"type": "delta", "data": {"event_type": "depth_update", "exchange": "binance", "symbol": "BTCUSDT", "event_time": 1786680239010, "received_time": 1786680239302, "first_update_id": 4673646, "final_update_id": 4673651, "bids": [{"price": 63369.88, "quantity": 5.41299}, {"price": 62096.95, "quantity": 0.02854}, {"price": 60829.66, "quantity": 0.02913}, {"price": 59562.38, "quantity": 0.02975}], "asks": [{"price": 63369.89, "quantity": 11.78136}, {"price": 69676.2, "quantity": 0.0}]}}
{"type": "delta", "data": {"event_type": "depth_update", "exchange": "binance", "symbol": "BTCUSDT", "event_time": 1786680240007, "received_time": 1786680240201, "first_update_id": 4673652, "final_update_id": 4673655, "bids": [{"price": 58295.09, "quantity": 0.0304}, {"price": 57027.81, "quantity": 0.03107}], "asks": [{"price": 63680.6, "quantity": 0.0}, {"price": 63686.8, "quantity": 0.002}]}}
{"type": "delta", "data": {"event_type": "depth_update", "exchange": "binance", "symbol": "BTCUSDT", "event_time": 1786680241007, "received_time": 1786680241201, "first_update_id": 4673656, "final_update_id": 4673709, "bids": [{"price": 63369.88, "quantity": 5.41299}, {"price": 63369.87, "quantity": 0.00334}, {"price": 63363.69, "quantity": 0.0}, {"price": 62102.49, "quantity": 0.15783}], "asks": [{"price": 64631.51, "quantity": 0.17539}, {"price": 65898.8, "quantity": 0.17539}, {"price": 67166.08, "quantity": 0.17539}]}}
{"type": "delta", "data": {"event_type": "depth_update", "exchange": "binance", "symbol": "BTCUSDT", "event_time": 1786680242004, "received_time": 1786680242199, "first_update_id": 4673710, "final_update_id": 4673713, "bids": [{"price": 63369.88, "quantity": 5.39404}], "asks": [{"price": 68433.37, "quantity": 0.17539}, {"price": 69700.65, "quantity": 0.17539}]}}
{"type": "delta", "data": {"event_type": "depth_update", "exchange": "binance", "symbol": "BTCUSDT", "event_time": 1786680243019, "received_time": 1786680243214, "first_update_id": 4673714, "final_update_id": 4673715, "bids": [{"price": 63369.88, "quantity": 5.38549}], "asks": [{"price": 63369.89, "quantity": 11.77237}]}}
{"type": "delta", "data": {"event_type": "depth_update", "exchange": "binance", "symbol": "BTCUSDT", "event_time": 1786680244018, "received_time": 1786680244216, "first_update_id": 4673716, "final_update_id": 4673717, "bids": [], "asks": [{"price": 63369.89, "quantity": 11.77071}]}}
{"type": "delta", "data": {"event_type": "depth_update", "exchange": "binance", "symbol": "BTCUSDT", "event_time": 1786680245024, "received_time": 1786680245386, "first_update_id": 4673718, "final_update_id": 4673720, "bids": [{"price": 63369.88, "quantity": 5.38528}], "asks": [{"price": 63434.72, "quantity": 0.0}, {"price": 63448.07, "quantity": 0.00078}]}}
{"type": "delta", "data": {"event_type": "depth_update", "exchange": "binance", "symbol": "BTCUSDT", "event_time": 1786680246060, "received_time": 1786680246255, "first_update_id": 4673721, "final_update_id": 4673722, "bids": [{"price": 63368.56, "quantity": 0.001}, {"price": 63362.38, "quantity": 0.0}], "asks": []}}
{"type": "delta", "data": {"event_type": "depth_update", "exchange": "binance", "symbol": "BTCUSDT", "event_time": 1786680247005, "received_time": 1786680247199, "first_update_id": 4673723, "final_update_id": 4673723, "bids": [], "asks": [{"price": 63370.41, "quantity": 0.001}]}}
{"type": "delta", "data": {"event_type": "depth_update", "exchange": "binance", "symbol": "BTCUSDT", "event_time": 1786680248016, "received_time": 1786680248212, "first_update_id": 4673724, "final_update_id": 4673725, "bids": [{"price": 63369.88, "quantity": 5.38328}], "asks": []}}
{"type": "delta", "data": {"event_type": "depth_update", "exchange": "binance", "symbol": "BTCUSDT", "event_time": 1786680249007, "received_time": 1786680249202, "first_update_id": 4673726, "final_update_id": 4673728, "bids": [{"price": 63369.88, "quantity": 5.38028}], "asks": []}}
{"type": "delta", "data": {"event_type": "depth_update", "exchange": "binance", "symbol": "BTCUSDT", "event_time": 1786680250008, "received_time": 1786680250205, "first_update_id": 4673729, "final_update_id": 4673729, "bids": [], "asks": [{"price": 63369.89, "quantity": 11.76993}]}}
{"type": "delta", "data": {"event_type": "depth_update", "exchange": "binance", "symbol": "BTCUSDT", "event_time": 1786680251033, "received_time": 1786680251231, "first_update_id": 4673730, "final_update_id": 4673823, "bids": [{"price": 63369.88, "quantity": 0.0}, {"price": 63369.87, "quantity": 0.0}, {"price": 63369.86, "quantity": 0.0}, {"price": 63369.6, "quantity": 0.0}, {"price": 63369.15, "quantity": 0.0}, {"price": 63368.62, "quantity": 0.0}, {"price": 63368.61, "quantity": 0.0}, {"price": 63368.6, "quantity": 0.0}, {"price": 63368.56, "quantity": 0.0}, {"price": 63368.44, "quantity": 0.0}, {"price": 63368.39, "quantity": 0.0}, {"price": 63368.38, "quantity": 0.0}, {"price": 63368.19, "quantity": 0.0}, {"price": 63368.18, "quantity": 0.0}, {"price": 63368.13, "quantity": 0.0}, {"price": 63368.12, "quantity": 0.0}, {"price": 63368.0, "quantity": 0.0}, {"price": 63367.99, "quantity": 0.0}, {"price": 63367.72, "quantity": 0.0}, {"price": 63367.71, "quantity": 0.0}, {"price": 63367.57, "quantity": 0.0}, {"price": 63365.25, "quantity": 10.30544}, {"price": 63365.24, "quantity": 0.00532}, {"price": 63365.23, "quantity": 0.00064}, {"price": 63365.2, "quantity": 0.03216}, {"price": 63365.16, "quantity": 0.00032}, {"price": 63365.14, "quantity": 0.00555}, {"price": 63365.13, "quantity": 0.00032}, {"price": 63364.81, "quantity": 0.00032}, {"price": 63364.79, "quantity": 0.00136}, {"price": 63364.78, "quantity": 0.19008}, {"price": 63364.73, "quantity": 0.00342}, {"price": 63364.69, "quantity": 0.00072}, {"price": 63364.68, "quantity": 0.53219}, {"price": 63364.53, "quantity": 0.00032}, {"price": 63364.26, "quantity": 0.00072}, {"price": 63364.25, "quantity": 1.03672}, {"price": 63364.24, "quantity": 1.5741}, {"price": 63364.0, "quantity": 0.09718}, {"price": 63363.99, "quantity": 0.01583}, {"price": 63363.98, "quantity": 0.17979}, {"price": 63310.32, "quantity": 0.0}], "asks": [{"price": 63365.26, "quantity": 19.21309}, {"price": 63365.27, "quantity": 0.00206}, {"price": 63365.28, "quantity": 0.00064}, {"price": 63365.89, "quantity": 0.00036}, {"price": 63365.93, "quantity": 0.00072}, {"price": 63365.94, "quantity": 0.28594}, {"price": 63365.97, "quantity": 0.00032}, {"price": 63366.01, "quantity": 0.00084}, {"price": 63366.06, "quantity": 0.00032}, {"price": 63366.07, "quantity": 0.00032}, {"price": 63366.4, "quantity": 0.00032}, {"price": 63367.34, "quantity": 0.00072}, {"price": 63367.35, "quantity": 0.1617}, {"price": 63367.5, "quantity": 0.00072}, {"price": 63367.51, "quantity": 0.24787}, {"price": 63367.72, "quantity": 0.00032}, {"price": 63367.86, "quantity": 0.016}, {"price": 63367.99, "quantity": 0.00072}, {"price": 63368.0, "quantity": 0.28888}, {"price": 63368.37, "quantity": 0.00128}, {"price": 63369.89, "quantity": 0.0}, {"price": 63369.9, "quantity": 0.0}, {"price": 63369.91, "quantity": 0.0}, {"price": 63369.94, "quantity": 0.0}, {"price": 63369.95, "quantity": 0.0}, {"price": 63369.99, "quantity": 0.0}, {"price": 63370.0, "quantity": 0.0}, {"price": 63371.04, "quantity": 0.0}, {"price": 63371.54, "quantity": 0.0}, {"price": 63371.55, "quantity": 0.0}, {"price": 63371.62, "quantity": 0.0}, {"price": 63371.65, "quantity": 0.0}, {"price": 63371.87, "quantity": 0.0}, {"price": 63371.93, "quantity": 0.0}, {"price": 63371.98, "quantity": 0.0}, {"price": 63371.99, "quantity": 0.0}, {"price": 63372.0, "quantity": 0.0}, {"price": 63372.15, "quantity": 0.0}, {"price": 63372.27, "quantity": 0.0}, {"price": 63372.63, "quantity": 0.0}, {"price": 63373.67, "quantity": 0.0}, {"price": 64003.58, "quantity": 0.00031}]}}
{"type": "delta", "data": {"event_type": "depth_update", "exchange": "binance", "symbol": "BTCUSDT", "event_time": 1786680252039, "received_time": 1786680252235, "first_update_id": 4673824, "final_update_id": 4673825, "bids": [{"price": 63338.2, "quantity": 0.00315}], "asks": [{"price": 63401.57, "quantity": 0.00315}]}}
{"type": "delta", "data": {"event_type": "depth_update", "exchange": "binance", "symbol": "BTCUSDT", "event_time": 1786680255005, "received_time": 1786680255238, "first_update_id": 4673826, "final_update_id": 4673826, "bids": [], "asks": [{"price": 63682.1, "quantity": 0.004}]}}
{"type": "delta", "data": {"event_type": "depth_update", "exchange": "binance", "symbol": "BTCUSDT", "event_time": 1786680257008, "received_time": 1786680258848, "first_update_id": 4673827, "final_update_id": 4673829, "bids": [{"price": 63363.93, "quantity": 0.001}], "asks": [{"price": 63365.78, "quantity": 0.001}, {"price": 63370.41, "quantity": 0.0}]}}
{"type": "delta", "data": {"event_type": "depth_update", "exchange": "binance", "symbol": "BTCUSDT", "event_time": 1786680258006, "received_time": 1786680259028, "first_update_id": 4673830, "final_update_id": 4673830, "bids": [{"price": 63365.25, "quantity": 10.30347}], "asks": []}}
{"type": "delta", "data": {"event_type": "depth_update", "exchange": "binance", "symbol": "BTCUSDT", "event_time": 1786680260044, "received_time": 1786680260240, "first_update_id": 4673831, "final_update_id": 4673833, "bids": [{"price": 63365.25, "quantity": 10.30269}], "asks": [{"price": 63365.26, "quantity": 19.21286}, {"price": 66449.1, "quantity": 0.0}]}}
{"type": "delta", "data": {"event_type": "depth_update", "exchange": "binance", "symbol": "BTCUSDT", "event_time": 1786680263050, "received_time": 1786680263251, "first_update_id": 4673834, "final_update_id": 4673887, "bids": [{"price": 63365.25, "quantity": 10.29969}], "asks": [{"price": 63382.54, "quantity": 0.0}, {"price": 63382.55, "quantity": 0.00011}, {"price": 66533.6, "quantity": 0.002}]}}
{"type": "delta", "data": {"event_type": "depth_update", "exchange": "binance", "symbol": "BTCUSDT", "event_time": 1786680264004, "received_time": 1786680264199, "first_update_id": 4673888, "final_update_id": 4673889, "bids": [{"price": 63365.25, "quantity": 10.29769}], "asks": []}}
{"type": "delta", "data": {"event_type": "depth_update", "exchange": "binance", "symbol": "BTCUSDT", "event_time": 1786680265007, "received_time": 1786680265205, "first_update_id": 4673890, "final_update_id": 4673891, "bids": [], "asks": [{"price": 63365.26, "quantity": 19.21259}, {"price": 66508.6, "quantity": 0.0}]}}
{"type": "delta", "data": {"event_type": "depth_update", "exchange": "binance", "symbol": "BTCUSDT", "event_time": 1786680267007, "received_time": 1786680267203, "first_update_id": 4673892, "final_update_id": 4673893, "bids": [{"price": 63365.25, "quantity": 10.2967}], "asks": [{"price": 63365.26, "quantity": 19.2122}]}}
{"type": "delta", "data": {"event_type": "depth_update", "exchange": "binance", "symbol": "BTCUSDT", "event_time": 1786680268009, "received_time": 1786680268206, "first_update_id": 4673894, "final_update_id": 4673936, "bids": [{"price": 63369.88, "quantity": 37.93403}, {"price": 63369.87, "quantity": 4.22855}, {"price": 63369.86, "quantity": 0.00111}, {"price": 63369.83, "quantity": 0.03144}, {"price": 63369.6, "quantity": 0.00064}, {"price": 63369.59, "quantity": 0.00032}, {"price": 63369.45, "quantity": 0.016}, {"price": 63369.08, "quantity": 0.00036}, {"price": 63368.78, "quantity": 0.00072}, {"price": 63368.77, "quantity": 0.37968}, {"price": 63368.62, "quantity": 0.00032}, {"price": 63368.61, "quantity": 0.18012}, {"price": 63368.44, "quantity": 0.00068}, {"price": 63368.43, "quantity": 0.00032}, {"price": 63368.42, "quantity": 0.00032}, {"price": 63368.39, "quantity": 0.00032}, {"price": 63368.38, "quantity": 0.00032}, {"price": 63368.37, "quantity": 0.00032}, {"price": 63368.01, "quantity": 0.00072}, {"price": 63368.0, "quantity": 4.70408}, {"price": 63365.25, "quantity": 0.0}, {"price": 63365.24, "quantity": 0.0}, {"price": 63365.23, "quantity": 0.0}, {"price": 63365.2, "quantity": 0.0}, {"price": 63365.16, "quantity": 0.0}, {"price": 63365.14, "quantity": 0.0}, {"price": 63365.13, "quantity": 0.0}, {"price": 63364.81, "quantity": 0.0}, {"price": 63364.79, "quantity": 0.0}, {"price": 63364.78, "quantity": 0.0}, {"price": 63364.73, "quantity": 0.0}, {"price": 63364.69, "quantity": 0.0}, {"price": 63364.68, "quantity": 0.0}, {"price": 63364.53, "quantity": 0.0}, {"price": 63364.26, "quantity": 0.0}, {"price": 63364.25, "quantity": 0.0}, {"price": 63364.24, "quantity": 0.0}, {"price": 63364.0, "quantity": 0.0}, {"price": 63363.99, "quantity": 0.0}, {"price": 63363.98, "quantity": 0.0}, {"price": 63363.93, "quantity": 0.001}], "asks": [{"price": 63365.26, "quantity": 0.0}, {"price": 63365.27, "quantity": 0.0}, {"price": 63365.28, "quantity": 0.0}, {"price": 63365.78, "quantity": 0.0}, {"price": 63365.89, "quantity": 0.0}, {"price": 63365.93, "quantity": 0.0}, {"price": 63365.94, "quantity": 0.0}, {"price": 63365.97, "quantity": 0.0}, {"price": 63366.01, "quantity": 0.0}, {"price": 63366.06, "quantity": 0.0}, {"price": 63366.07, "quantity": 0.0}, {"price": 63366.4, "quantity": 0.0}, {"price": 63367.34, "quantity": 0.0}, {"price": 63367.35, "quantity": 0.0}, {"price": 63367.5, "quantity": 0.0}, {"price": 63367.51, "quantity": 0.0}, {"price": 63367.72, "quantity": 0.0}, {"price": 63367.86, "quantity": 0.0}, {"price": 63367.99, "quantity": 0.0}, {"price": 63368.0, "quantity": 0.0}, {"price": 63368.37, "quantity": 0.0}, {"price": 63369.89, "quantity": 2.30948}, {"price": 63369.9, "quantity": 0.00206}, {"price": 63369.91, "quantity": 0.00064}, {"price": 63369.99, "quantity": 0.00072}, {"price": 63370.0, "quantity": 0.138}, {"price": 63371.04, "quantity": 0.00036}, {"price": 63371.6, "quantity": 0.00032}, {"price": 63371.99, "quantity": 0.00103}, {"price": 63372.0, "quantity": 0.08799}, {"price": 63372.14, "quantity": 0.00072}, {"price": 63372.15, "quantity": 0.24784}, {"price": 63372.41, "quantity": 0.00072}, {"price": 63372.42, "quantity": 0.0852}, {"price": 63372.51, "quantity": 0.00944}, {"price": 63372.8, "quantity": 0.00068}, {"price": 63373.0, "quantity": 0.00036}, {"price": 63373.01, "quantity": 0.06994}, {"price": 63373.14, "quantity": 0.00032}, {"price": 63373.16, "quantity": 0.00032}, {"price": 63373.24, "quantity": 0.00128}]}}
{"type": "delta", "data": {"event_type": "depth_update", "exchange": "binance", "symbol": "BTCUSDT", "event_time": 1786680270011, "received_time": 1786680270206, "first_update_id": 4673937, "final_update_id": 4673937, "bids": [], "asks": [{"price": 63682.1, "quantity": 0.0}]}}
{"type": "delta", "data": {"event_type": "depth_update", "exchange": "binance", "symbol": "BTCUSDT", "event_time": 1786680272003, "received_time": 1786680272198, "first_update_id": 4673938, "final_update_id": 4673952, "bids": [{"price": 63369.88, "quantity": 37.93325}], "asks": [{"price": 63382.54, "quantity": 0.0}, {"price": 63382.55, "quantity": 0.00011}]}}
{"type": "delta", "data": {"event_type": "depth_update", "exchange": "binance", "symbol": "BTCUSDT", "event_time": 1786680273008, "received_time": 1786680273204, "first_update_id": 4673953, "final_update_id": 4673988, "bids": [], "asks": [{"price": 63382.54, "quantity": 0.0}, {"price": 63382.55, "quantity": 0.00011}]}}
{"type": "delta", "data": {"event_type": "depth_update", "exchange": "binance", "symbol": "BTCUSDT", "event_time": 1786680276003, "received_time": 1786680276200, "first_update_id": 4673989, "final_update_id": 4673992, "bids": [{"price": 63369.88, "quantity": 37.93286}, {"price": 62096.95, "quantity": 0.0}, {"price": 60829.66, "quantity": 0.0}, {"price": 59562.38, "quantity": 0.0}], "asks": []}}
{"type": "delta", "data": {"event_type": "depth_update", "exchange": "binance", "symbol": "BTCUSDT", "event_time": 1786680277014, "received_time": 1786680277210, "first_update_id": 4673993, "final_update_id": 4673997, "bids": [{"price": 63369.88, "quantity": 37.93186}, {"price": 58295.09, "quantity": 0.0}, {"price": 57027.81, "quantity": 0.0}], "asks": [{"price": 64631.51, "quantity": 0.0}, {"price": 65898.8, "quantity": 0.0}]}}
{"type": "delta", "data": {"event_type": "depth_update", "exchange": "binance", "symbol": "BTCUSDT", "event_time": 1786680278031, "received_time": 1786680278244, "first_update_id": 4673998, "final_update_id": 4674002, "bids": [{"price": 63369.88, "quantity": 37.92986}], "asks": [{"price": 67166.08, "quantity": 0.0}, {"price": 68433.37, "quantity": 0.0}, {"price": 69700.65, "quantity": 0.0}]}}
{"type": "delta", "data": {"event_type": "depth_update", "exchange": "binance", "symbol": "BTCUSDT", "event_time": 1786680279008, "received_time": 1786680279205, "first_update_id": 4674003, "final_update_id": 4674008, "bids": [{"price": 63369.88, "quantity": 37.92886}, {"price": 63368.56, "quantity": 0.001}, {"price": 63363.93, "quantity": 0.0}, {"price": 62102.48, "quantity": 0.02853}, {"price": 60835.08, "quantity": 0.02913}], "asks": [{"price": 63370.41, "quantity": 0.001}]}}
{"type": "delta", "data": {"event_type": "depth_update", "exchange": "binance", "symbol": "BTCUSDT", "event_time": 1786680280015, "received_time": 1786680280212, "first_update_id": 4674009, "final_update_id": 4674012, "bids": [{"price": 63369.88, "quantity": 37.92786}, {"price": 59567.69, "quantity": 0.02975}, {"price": 58300.29, "quantity": 0.0304}, {"price": 57032.89, "quantity": 0.03107}], "asks": []}}
{"type": "delta", "data": {"event_type": "depth_update", "exchange": "binance", "symbol": "BTCUSDT", "event_time": 1786680281005, "received_time": 1786680281200, "first_update_id": 4674013, "final_update_id": 4674066, "bids": [], "asks": [{"price": 63382.54, "quantity": 0.0}, {"price": 63382.55, "quantity": 0.00011}, {"price": 64637.28, "quantity": 0.17539}, {"price": 65904.68, "quantity": 0.17539}, {"price": 67172.07, "quantity": 0.17539}, {"price": 68439.47, "quantity": 0.17539}]}}
{"type": "delta", "data": {"event_type": "depth_update", "exchange": "binance", "symbol": "BTCUSDT", "event_time": 1786680282010, "received_time": 1786680282209, "first_update_id": 4674067, "final_update_id": 4674067, "bids": [], "asks": [{"price": 69706.87, "quantity": 0.17539}]}}
{"type": "delta", "data": {"event_type": "depth_update", "exchange": "binance", "symbol": "BTCUSDT", "event_time": 1786680283008, "received_time": 1786680283228, "first_update_id": 4674068, "final_update_id": 4674068, "bids": [{"price": 63369.88, "quantity": 37.91996}], "asks": []}}
{"type": "delta", "data": {"event_type": "depth_update", "exchange": "binance", "symbol": "BTCUSDT", "event_time": 1786680284012, "received_time": 1786680284210, "first_update_id": 4674069, "final_update_id": 4674105, "bids": [{"price": 63372.41, "quantity": 39.09522}, {"price": 63372.4, "quantity": 0.20272}, {"price": 63372.39, "quantity": 0.00064}, {"price": 63372.36, "quantity": 0.02998}, {"price": 63372.35, "quantity": 0.20102}, {"price": 63372.15, "quantity": 0.0091}, {"price": 63372.03, "quantity": 0.11272}, {"price": 63372.02, "quantity": 0.00036}, {"price": 63372.01, "quantity": 1.88168}, {"price": 63372.0, "quantity": 0.3163}, {"price": 63371.99, "quantity": 6.01796}, {"price": 63371.98, "quantity": 10.16783}, {"price": 63371.97, "quantity": 0.11984}, {"price": 63371.61, "quantity": 0.00032}, {"price": 63371.6, "quantity": 0.29998}, {"price": 63371.59, "quantity": 1.99815}, {"price": 63371.53, "quantity": 0.16431}, {"price": 63371.19, "quantity": 0.30031}, {"price": 63371.04, "quantity": 0.01754}, {"price": 63369.88, "quantity": 0.0}, {"price": 63369.87, "quantity": 0.0}, {"price": 63369.86, "quantity": 0.0}, {"price": 63369.83, "quantity": 0.0}, {"price": 63369.6, "quantity": 0.0}, {"price": 63369.59, "quantity": 0.0}, {"price": 63369.45, "quantity": 0.0}, {"price": 63369.08, "quantity": 0.0}, {"price": 63368.78, "quantity": 0.0}, {"price": 63368.77, "quantity": 0.0}, {"price": 63368.62, "quantity": 0.0}, {"price": 63368.61, "quantity": 0.0}, {"price": 63368.44, "quantity": 0.0}, {"price": 63368.43, "quantity": 0.0}, {"price": 63368.42, "quantity": 0.0}, {"price": 63368.39, "quantity": 0.0}, {"price": 63368.38, "quantity": 0.0}, {"price": 63368.37, "quantity": 0.0}, {"price": 63368.01, "quantity": 0.0}, {"price": 63368.0, "quantity": 0.0}], "asks": [{"price": 63369.89, "quantity": 0.0}, {"price": 63369.9, "quantity": 0.0}, {"price": 63369.91, "quantity": 0.0}, {"price": 63369.99, "quantity": 0.0}, {"price": 63370.0, "quantity": 0.0}, {"price": 63370.41, "quantity": 0.0}, {"price": 63371.04, "quantity": 0.0}, {"price": 63371.6, "quantity": 0.0}, {"price": 63371.99, "quantity": 0.0}, {"price": 63372.0, "quantity": 0.0}, {"price": 63372.14, "quantity": 0.0}, {"price": 63372.15, "quantity": 0.0}, {"price": 63372.41, "quantity": 0.0}, {"price": 63372.42, "quantity": 0.75832}, {"price": 63372.43, "quantity": 0.00206}, {"price": 63372.44, "quantity": 0.00064}, {"price": 63372.87, "quantity": 0.00036}, {"price": 63373.0, "quantity": 0.0}, {"price": 63373.01, "quantity": 0.0}, {"price": 63373.14, "quantity": 0.0}, {"price": 63373.16, "quantity": 0.0}, {"price": 63373.99, "quantity": 0.00072}, {"price": 63374.0, "quantity": 0.08799}, {"price": 63374.22, "quantity": 0.00036}, {"price": 63374.25, "quantity": 0.00032}, {"price": 63374.67, "quantity": 0.00072}, {"price": 63374.68, "quantity": 0.24784}, {"price": 63375.1, "quantity": 0.00072}, {"price": 63375.11, "quantity": 0.06994}, {"price": 63375.93, "quantity": 0.00032}, {"price": 63375.96, "quantity": 0.00036}, {"price": 63375.99, "quantity": 0.00072}, {"price": 63376.0, "quantity": 0.08831}, {"price": 63376.37, "quantity": 0.00036}]}}
{"type": "delta", "data": {"event_type": "depth_update", "exchange": "binance", "symbol": "BTCUSDT", "event_time": 1786680285016, "received_time": 1786680285211, "first_update_id": 4674106, "final_update_id": 4674109, "bids": [{"price": 62674.81, "quantity": 0.00175}], "asks": [{"price": 63686.8, "quantity": 0.0}, {"price": 63689.3, "quantity": 0.001}]}}
{"type": "delta", "data": {"event_type": "depth_update", "exchange": "binance", "symbol": "BTCUSDT", "event_time": 1786680286020, "received_time": 1786680286216, "first_update_id": 4674110, "final_update_id": 4674110, "bids": [{"price": 63372.41, "quantity": 39.08735}], "asks": []}}
{"type": "delta", "data": {"event_type": "depth_update", "exchange": "binance", "symbol": "BTCUSDT", "event_time": 1786680288011, "received_time": 1786680288283, "first_update_id": 4674111, "final_update_id": 4674111, "bids": [], "asks": [{"price": 63448.07, "quantity": 0.0}]}}
{"type": "delta", "data": {"event_type": "depth_update", "exchange": "binance", "symbol": "BTCUSDT", "event_time": 1786680289004, "received_time": 1786680289199, "first_update_id": 4674112, "final_update_id": 4674112, "bids": [], "asks": [{"price": 63453.13, "quantity": 0.00078}]}}
{"type": "delta", "data": {"event_type": "depth_update", "exchange": "binance", "symbol": "BTCUSDT", "event_time": 1786680290016, "received_time": 1786680290221, "first_update_id": 4674113, "final_update_id": 4674116, "bids": [{"price": 63372.41, "quantity": 39.07948}, {"price": 63371.09, "quantity": 0.001}, {"price": 63368.56, "quantity": 0.0}], "asks": [{"price": 63372.94, "quantity": 0.001}]}}
{"type": "delta", "data": {"event_type": "depth_update", "exchange": "binance", "symbol": "BTCUSDT", "event_time": 1786680293004, "received_time": 1786680293201, "first_update_id": 4674117, "final_update_id": 4674170, "bids": [], "asks": [{"price": 63372.42, "quantity": 0.75532}, {"price": 63382.54, "quantity": 0.0}, {"price": 63382.55, "quantity": 0.00011}, {"price": 66541.1, "quantity": 0.002}]}}
{"type": "delta", "data": {"event_type": "depth_update", "exchange": "binance", "symbol": "BTCUSDT", "event_time": 1786680294008, "received_time": 1786680294206, "first_update_id": 4674171, "final_update_id": 4674172, "bids": [], "asks": [{"price": 63372.42, "quantity": 0.75332}]}}
{"type": "delta", "data": {"event_type": "depth_update", "exchange": "binance", "symbol": "BTCUSDT", "event_time": 1786680295015, "received_time": 1786680295216, "first_update_id": 4674173, "final_update_id": 4674173, "bids": [{"price": 63372.41, "quantity": 39.07161}], "asks": []}}
